Workbook

Sheet 2023
A1: note: I added to the providing sector the IVC-speciifc market price, so I should skip columns b-H here and only do the sector allocation for the receiving sectors
A2: EU production | J2: Receiving sector
A3: ADVANCED biofuels | B3: Produced 2023 [Mtoe] | C3: Conversion factor [t/toe] | D3: Produced 2023 [t] | E3: Share per IVC | F3: Market prices 2025 (averaged over 24 months) [€/t] | G3: Market value of amount produced [€] | I3: In Million Eur | J3: Road | K3: Aviation | L3: Maritime | M3: Sum
A4: Biodiesel | B4: =SUM(B5:B7) -> 1.3116089 | D4: =SUM(D5:D7) -> 1455038.6 | F4: 1450 | G4: =D4*F4 -> 2.109806e+09 | I4: =G4/1000000 -> 2109.806 | J4: ='[3]GAP analysis Sc. 1'!$D$3+'[3]GAP analysis Sc. 1'!$D$4+'[3]GAP analysis Sc. 1'!$D$16/2 -> 1.2192443 | K4: ='[3]GAP analysis Sc. 1'!$E$16 -> 0.014211331 | L4: ='[3]GAP analysis Sc. 1'!$F$3+'[3]GAP analysis Sc. 1'!$F$16 -> 0.075420846 | M4: =SUM(J4:L4) -> 1.3088765
A5: of which IVC 1 | B5: ='[3]GAP analysis Sc. 1'!$G$3 -> 1.1404758 | C5: ='[4]Conversion factors selected IV '!$O$4 -> 1.1315676 | D5: =B5*C5*1000000 -> 1290525.4 | E5: =D5/D4 -> 0.88693549 | F5: 1450 | G5: =D5*F5 -> 1.8712618e+09 | H5: =SUM(G5:G7) -> 2.15916e+09 | I5: =H5/1000000 -> 2159.16 | J5: =J4/M4 -> 0.93151976 | K5: =K4/M4 -> 0.010857656 | L5: =L4/M4 -> 0.057622586 | N5: Share of how much each transpor sector receives
A6: of which IVC 2 | B6: ='[3]GAP analysis Sc. 1'!$G$4 -> 0.13661985 | C6: ='[4]Conversion factors selected IV '!$O$7 -> 0.95154545 | D6: =B6*C6*1000000 -> 130000 | E6: =D6/D4 -> 0.089344706 | F6: 1750 | G6: =D6*F6 -> 2.275e+08 | J6: =J5*I4 -> 1965.326 | K6: =K5*I4 -> 22.907549 | L6: =L5*I4 -> 121.57248 | M6: =SUM(J6:L6) -> 2109.806 | N6: Translated into monetary values
A7: of which IVC 13a | B7: ='[3]GAP analysis Sc. 1'!$D$16/2+'[3]GAP analysis Sc. 1'!$E$16+'[3]GAP analysis Sc. 1'!$F$16 -> 0.034513232 | C7: ='[4]Conversion factors selected IV '!$O$98 -> 1 | D7: =B7*C7*1000000 -> 34513.232 | E7: =D7/D4 -> 0.023719805 | F7: 1750 | G7: =D7*F7 -> 60398156
A8: Biogasoline (ethanol) | B8: =SUM(B9:B10) -> 0.13609057 | D8: =SUM(D9:D10) -> 207677.24 | F8: 1000 | G8: =D8*F8 -> 2.0767724e+08 | I8: =G8/1000000 -> 207.67724 | J8: ='[3]GAP analysis Sc. 1'!$D$7+'[3]GAP analysis Sc. 1'!$D$16/2+'[3]GAP analysis Sc. 1'!$D$6 -> 0.13506735 | K8: - | L8: -
A9: of which IVC 5 | B9: 0.13 | C9: ='[4]Conversion factors selected IV '!$O$18 -> 1.5506667 | D9: =B9*C9*1000000 -> 201586.67 | J9: 1
A10: of which IVC 13a | B10: ='[3]GAP analysis Sc. 1'!$D$16/2 -> 0.0060905704 | C10: ='[4]Conversion factors selected IV '!$O$89 -> 1 | D10: =B10*C10*1000000 -> 6090.5704 | J10: =I8*J9 -> 207.67724
A11: Biogas - available to the transport sector | B11: ='[3]GAP analysis Sc. 1'!$G$9 -> 0.32 | D11: =SUM(D12) -> 267741.01 | F11: 1275 | G11: =D11*F11 -> 3.4136978e+08 | I11: =G11/1000000 -> 341.36978 | J11: ='[3]GAP analysis Sc. 1'!$D$9 -> 0.32
A12: of which IVC 7 | B12: 0.32 | C12: ='[4]Conversion factors selected IV '!$O$29 -> 0.83669065 | D12: =B12*C12*1000000 -> 267741.01 | J12: 1
J13: =I11*J12 -> 341.36978
A14: TOTAL | B14: =B4+B8+B11 -> 1.7676994 | D14: =D4+D8+D11 -> 1930456.9 | G14: =G4+G8+G11 -> 2.658853e+09 | I14: =I5+I8+I11 -> 2708.207
A15: CONVENTIONAL biofuels | B15: Produced 2023 [Mtot] | C15: Conversion factor | D15: Produced 2023 [t] | F15: Market price [€/t] | G15: Market value of amount produced [€] | I15: In Million Eur | J15: Road | K15: Aviation | L15: Maritime
A16: Biodiesel (including Annex IX Part B feedstocks) | B16: =SUM(B17:B18) -> 12.943059 | C16: 1.1627907 | D16: =SUM(D17:D18) -> 13700000 | F16: 1165.6261 | G16: =D16*F16 -> 1.5969078e+10 | I16: =G16/1000000 -> 15969.078 | J16: ='[3]GAP analysis Sc. 1'!$D$18+'[3]GAP analysis Sc. 1'!$D$19+'[3]GAP analysis Sc. 1'!$D$23 -> 12.78929 | K16: =0 -> 0 | L16: ='[3]GAP analysis Sc. 1'!$F$23+'[3]GAP analysis Sc. 1'!$F$18 -> 0.15376899 | M16: =SUM(J16:L16) -> 12.943059
A17: of which IVC 1 | B17: ='[3]GAP analysis Sc. 1'!$G$18+'[3]GAP analysis Sc. 1'!$G$23 -> 7.6884494 | C17: ='[4]Conversion factors selected IV '!$O$4 -> 1.1315676 | D17: =B17*C17*1000000 -> 8700000 | J17: =J16/M16 -> 0.98811958 | K17: =K16/M16 -> 0 | L17: =L16/M16 -> 0.011880421 | M17: =SUM(J17:L17) -> 1
A18: of which IVC 2 | B18: ='[3]GAP analysis Sc. 1'!$G$19 -> 5.2546097 | C18: ='[4]Conversion factors selected IV '!$O$7 -> 0.95154545 | D18: =B18*C18*1000000 -> 5000000 | J18: =J17*I16 -> 15779.359 | K18: =K17*I16 -> 0 | L18: =L17*I16 -> 189.71937 | M18: =SUM(J18:L18) -> 15969.078
A19: Biogasoline (ethanol) | B19: =B20 -> 3.1599312 | C19: 1.5625 | D19: =D20 -> 4900000 | F19: 1018.9696 | G19: =D19*F19 -> 4.992951e+09 | I19: =G19/1000000 -> 4992.951 | J19: ='[3]GAP analysis Sc. 1'!$D$20 -> 3.1599312
A20: of which IVC 5 | B20: ='[3]GAP analysis Sc. 1'!$G$20 -> 3.1599312 | C20: ='[4]Conversion factors selected IV '!$O$17 -> 1.5506667 | D20: =B20*C20*1000000 -> 4900000 | J20: 1
A21: Biogas | B21: none (everything is advanced) | J21: =I19*J20 -> 4992.951
A22: Total | B22: =B16+B19 -> 16.10299 | D22: =D16+D19 -> 18600000 | G22: =G16+G19 -> 2.0962029e+10 | I22: =I16+I19 -> 20962.029
A24: ALL biofuels together | B24: =B14+B22 -> 17.87069 | D24: =D14+D22 -> 20530457 | G24: =G14+G22 -> 2.3620882e+10 | I24: =I14+I22 -> 23670.236
A26: IMPORTS of finished fuels to the EU
A27: ADVANCED biofuels
A28: check still
A32: CONVENTIONAL biofuels | B32: Imported 2023 [Million litres] | C32: Imported 2023 [1000l] | D32: Product price [USD/ 1000 litres] | E32: Conversion factor | F32: Imported 2023 [t] | G32: Market price [€/t] | I32: Market value of amount imported [USD | J32: EUR/USD | K32: Market value of amount imported [€] | L32: In Million Eur
A33: Based on GAIN report
A34: Biodiesel | B34: 2870 | K34: 3200000000 | L34: =K34/1000000 -> 3200
A35: Biogasoline | B35: 1242 | C35: =B35*1000 -> 1242000 | D35: 800 | I35: =C35*D35 -> 993600000 | J35: 0.92 | K35: =I35*J35 -> 914112000 | L35: =K35/1000000 -> 914.112
A36: Biogas
A37: Bio-kerosene
A38: Bio-HFO | M38: 3213.4163
A39: Based on Eurostat
A40: Biodiesel | F40: =24861548.23/10 -> 2486154.8 | G40: =K41/F40 -> 202.15573 | K40: 3213416319 | L40: =K40/1000000 -> 3213.4163 | M40: also in line with CETO report
A41: Biogasoline | B41: not sure whether this is only bio or also fossil-derived | F41: =6070534.21/10 -> 607053.42 | G41: =K41/F41 -> 827.91798 | K41: 502590444 | L41: =K41/1000000 -> 502.59044 | M41: also in line with CETO report
A42: ETBE | B42: not sure how to treat this | F42: =2018050.77/2 -> 1009025.4 | G42: =K42/F42 -> 220.91506 | K42: 222908907 | L42: =K42/1000000 -> 222.90891
A44: Exports of finished fuels from the EU
A45: CONVENTIONAL biofuels | B45: Exports 2023 [Million litres]
A46: Based on Eurostat
...

Sheet Tabelle1
A1: IVC No. | B1: Resulting Product | C1: Sector Destination | D1: Recommended EI (final) | E1: Feedstock-specific pathway
A2: 1 | B2: FAME | C2: Road-bio | D2: {=IFERROR(SUMPRODUCT(($A$36:$A$137=$A2)*($B$36:$B$137=#REF!)*($C$36:$C$137=$D2)*($D$36:$D$137=$E2)*(--ISNUMBER(SEARCH("UCO",$F$36:$F$137)))*$K$36:$K$137*$M$36:$M$137)/SUMPRODUCT(($A$36:$A$137=$A2)*($B$36:$B$137=#REF!)*($C$36:$C$137=$D2)*($D$36:$D$137=$E2)*(--ISNUMBER(SEARCH("UCO",$F$36:$F$137)))*$K$36:$K$137),0)} -> 12.15 | E2: UCO / animal fat
A3: 1 | B3: FAME | C3: Road-bio | D3: 15.39 | E3: POME
A4: 2 | B4: HVO | C4: Road-bio | D4: {=IFERROR(SUMPRODUCT(($A$36:$A$137=$A4)*($B$36:$B$137=$B2)*($C$36:$C$137=$D4)*($D$36:$D$137=$E4)*(--ISNUMBER(SEARCH("UCO",$F$36:$F$137)))*$K$36:$K$137*$M$36:$M$137)/SUMPRODUCT(($A$36:$A$137=$A4)*($B$36:$B$137=$B2)*($C$36:$C$137=$D4)*($D$36:$D$137=$E4)*(--ISNUMBER(SEARCH("UCO",$F$36:$F$137)))*$K$36:$K$137),0)} -> 13.775 | E4: UCO / animal fat
A5: 2 | B5: HVO | C5: Road-bio | D5: {=IFERROR(SUMPRODUCT(($A$36:$A$137=$A5)*($B$36:$B$137=$B4)*($C$36:$C$137=$D5)*($D$36:$D$137=$E5)*(--((ISNUMBER(SEARCH("Tall oil",$F$36:$F$137))+ISNUMBER(SEARCH("POME",$F$36:$F$137)))>0))*$K$36:$K$137*$M$36:$M$137)/SUMPRODUCT(($A$36:$A$137=$A5)*($B$36:$B$137=$B4)*($C$36:$C$137=$D5)*($D$36:$D$137=$E5)*(--((ISNUMBER(SEARCH("Tall oil",$F$36:$F$137))+ISNUMBER(SEARCH("POME",$F$36:$F$137)))>0))*$K$36:$K$137),0)} -> 10.8 | E5: POME / tall-oil proxy
A6: 2 | B6: HVO | C6: Road-bio | D6: {=IFERROR(SUMPRODUCT(($A$36:$A$137=$A6)*($B$36:$B$137=$B5)*($C$36:$C$137=$D6)*($D$36:$D$137=$E6)*(--((ISNUMBER(SEARCH("FPBO",$F$36:$F$137))+ISNUMBER(SEARCH("biocrude",$F$36:$F$137)))>0))*$K$36:$K$137*$M$36:$M$137)/SUMPRODUCT(($A$36:$A$137=$A6)*($B$36:$B$137=$B5)*($C$36:$C$137=$D6)*($D$36:$D$137=$E6)*(--((ISNUMBER(SEARCH("FPBO",$F$36:$F$137))+ISNUMBER(SEARCH("biocrude",$F$36:$F$137)))>0))*$K$36:$K$137),0)} -> 13.775 | E6: FPBO + biocrude
A7: 2 | B7: HEFA / SAF | C7: Aviation-bio | D7: {=IFERROR(SUMPRODUCT(($A$36:$A$137=$A7)*($B$36:$B$137=$B6)*($C$36:$C$137=$D7)*($D$36:$D$137=$E7)*(--ISNUMBER(SEARCH("Oil crops",$F$36:$F$137)))*$K$36:$K$137*$M$36:$M$137)/SUMPRODUCT(($A$36:$A$137=$A7)*($B$36:$B$137=$B6)*($C$36:$C$137=$D7)*($D$36:$D$137=$E7)*(--ISNUMBER(SEARCH("Oil crops",$F$36:$F$137)))*$K$36:$K$137),0)} -> 26.05 | E7: Oil crops
A8: 2 | B8: HEFA / SAF | C8: Aviation-bio | D8: {=IFERROR(SUMPRODUCT(($A$36:$A$137=$A8)*($B$36:$B$137=$B7)*($C$36:$C$137=$D8)*($D$36:$D$137=$E8)*(--ISNUMBER(SEARCH("UCO",$F$36:$F$137)))*$K$36:$K$137*$M$36:$M$137)/SUMPRODUCT(($A$36:$A$137=$A8)*($B$36:$B$137=$B7)*($C$36:$C$137=$D8)*($D$36:$D$137=$E8)*(--ISNUMBER(SEARCH("UCO",$F$36:$F$137)))*$K$36:$K$137),0)} -> 21.4 | E8: UCO / animal fat
A9: 2 | B9: HEFA / SAF | C9: Aviation-bio | D9: {=IFERROR(SUMPRODUCT(($A$36:$A$137=$A9)*($B$36:$B$137=$B8)*($C$36:$C$137=$D9)*($D$36:$D$137=$E9)*(--((ISNUMBER(SEARCH("Tall oil",$F$36:$F$137))+ISNUMBER(SEARCH("POME",$F$36:$F$137)))>0))*$K$36:$K$137*$M$36:$M$137)/SUMPRODUCT(($A$36:$A$137=$A9)*($B$36:$B$137=$B8)*($C$36:$C$137=$D9)*($D$36:$D$137=$E9)*(--((ISNUMBER(SEARCH("Tall oil",$F$36:$F$137))+ISNUMBER(SEARCH("POME",$F$36:$F$137)))>0))*$K$36:$K$137),0)} -> 17.5 | E9: POME / tall-oil proxy
A10: 2 | B10: HEFA / SAF | C10: Aviation-bio | D10: {=IFERROR(SUMPRODUCT(($A$36:$A$137=$A10)*($B$36:$B$137=$B9)*($C$36:$C$137=$D10)*($D$36:$D$137=$E10)*(--((ISNUMBER(SEARCH("FPBO",$F$36:$F$137))+ISNUMBER(SEARCH("biocrude",$F$36:$F$137)))>0))*$K$36:$K$137*$M$36:$M$137)/SUMPRODUCT(($A$36:$A$137=$A10)*($B$36:$B$137=$B9)*($C$36:$C$137=$D10)*($D$36:$D$137=$E10)*(--((ISNUMBER(SEARCH("FPBO",$F$36:$F$137))+ISNUMBER(SEARCH("biocrude",$F$36:$F$137)))>0))*$K$36:$K$137),0)} -> 21.4 | E10: FPBO + biocrude
A11: 3 | B11: Renewable diesel | C11: Road-bio | D11: {=IFERROR(SUMPRODUCT(($A$36:$A$137=$A11)*($B$36:$B$137=$B10)*($C$36:$C$137=$D11)*($D$36:$D$137=$E11)*$K$36:$K$137*$M$36:$M$137)/SUMIFS($K$36:$K$137,$A$36:$A$137,$A11,$B$36:$B$137,$B10,$C$36:$C$137,$D11,$D$36:$D$137,$E11),0)} -> 55.5
A12: 5 | B12: Advanced ethanol | C12: Road-bio | D12: {=IFERROR(SUMPRODUCT(($A$36:$A$137=$A12)*($B$36:$B$137=$B11)*($C$36:$C$137=$D12)*($D$36:$D$137=$E12)*$K$36:$K$137*$M$36:$M$137)/SUMIFS($K$36:$K$137,$A$36:$A$137,$A12,$B$36:$B$137,$B11,$C$36:$C$137,$D12,$D$36:$D$137,$E12),0)} -> 24.4
A13: 5 | B13: ATJ-SPK | C13: Aviation-bio 2040/2050 | D13: {=IFERROR(SUMPRODUCT(($A$36:$A$137=$A13)*($B$36:$B$137=$B12)*($C$36:$C$137=$D13)*($D$36:$D$137=$E13)*$K$36:$K$137*$M$36:$M$137)/SUMIFS($K$36:$K$137,$A$36:$A$137,$A13,$B$36:$B$137,$B12,$C$36:$C$137,$D13,$D$36:$D$137,$E13),0)} -> 24.4
A14: 6 | B14: ATJ-SPK | C14: Aviation-bio | D14: 13.1
A15: 7 | B15: Biomethane | C15: Road-bio 2030 | D15: {=IFERROR(SUMPRODUCT(($A$36:$A$137=$A15)*($B$36:$B$137=$B14)*($C$36:$C$137=$D15)*($D$36:$D$137=$E15)*$K$36:$K$137*$M$36:$M$137)/SUMIFS($K$36:$K$137,$A$36:$A$137,$A15,$B$36:$B$137,$B14,$C$36:$C$137,$D15,$D$36:$D$137,$E15),0)} -> -62.308737
A16: 8a | B16: Methanol | C16: Maritime-bio | D16: {=IFERROR(SUMPRODUCT(($A$36:$A$137=$A16)*($B$36:$B$137=$B15)*($C$36:$C$137=$D16)*($D$36:$D$137=$E16)*$K$36:$K$137*$M$36:$M$137)/SUMIFS($K$36:$K$137,$A$36:$A$137,$A16,$B$36:$B$137,$B15,$C$36:$C$137,$D16,$D$36:$D$137,$E16),0)} -> 12.5
A17: 8b | B17: Methanol | C17: Maritime-bio | D17: {=IFERROR(SUMPRODUCT(($A$36:$A$137=$A17)*($B$36:$B$137=$B16)*($C$36:$C$137=$D17)*($D$36:$D$137=$E17)*$K$36:$K$137*$M$36:$M$137)/SUMIFS($K$36:$K$137,$A$36:$A$137,$A17,$B$36:$B$137,$B16,$C$36:$C$137,$D17,$D$36:$D$137,$E17),0)} -> 12
A18: 8c | B18: e-Methanol (RFNBO) | C18: Maritime-e | D18: {=IFERROR(SUMPRODUCT(($A$36:$A$137=$A18)*($B$36:$B$137=$B17)*($C$36:$C$137=$D18)*($D$36:$D$137=$E18)*$K$36:$K$137*$M$36:$M$137)/SUMIFS($K$36:$K$137,$A$36:$A$137,$A18,$B$36:$B$137,$B17,$C$36:$C$137,$D18,$D$36:$D$137,$E18),0)} -> 1.8
A19: 8d | B19: Pathway output | C19: Other / multi-sector | D19: {=IFERROR(SUMPRODUCT(($A$36:$A$137=$A19)*($B$36:$B$137=$B18)*($C$36:$C$137=$D19)*($D$36:$D$137=$E19)*$K$36:$K$137*$M$36:$M$137)/SUMIFS($K$36:$K$137,$A$36:$A$137,$A19,$B$36:$B$137,$B18,$C$36:$C$137,$D19,$D$36:$D$137,$E19),0)} -> 0
A20: 9a | B20: Methane | C20: Maritime -bio | D20: {=IFERROR(SUMPRODUCT(($A$36:$A$137=$A20)*($B$36:$B$137=$B19)*($C$36:$C$137=$D20)*($D$36:$D$137=$E20)*$K$36:$K$137*$M$36:$M$137)/SUMIFS($K$36:$K$137,$A$36:$A$137,$A20,$B$36:$B$137,$B19,$C$36:$C$137,$D20,$D$36:$D$137,$E20),0)} -> 21.754917
A21: 9b | B21: e-Methane (RFNBO) | C21: Maritime-e 2040/ 2050 | D21: {=IFERROR(SUMPRODUCT(($A$36:$A$137=$A21)*($B$36:$B$137=$B20)*($C$36:$C$137=$D21)*($D$36:$D$137=$E21)*$K$36:$K$137*$M$36:$M$137)/SUMIFS($K$36:$K$137,$A$36:$A$137,$A21,$B$36:$B$137,$B20,$C$36:$C$137,$D21,$D$36:$D$137,$E21),0)} -> 2.4
A22: 11a | B22: Biodiesel | C22: Road-bio | D22: {=IFERROR(SUMPRODUCT(($A$36:$A$137=$A22)*($B$36:$B$137=$B21)*($C$36:$C$137=$D22)*($D$36:$D$137=$E22)*$K$36:$K$137*$M$36:$M$137)/SUMIFS($K$36:$K$137,$A$36:$A$137,$A22,$B$36:$B$137,$B21,$C$36:$C$137,$D22,$D$36:$D$137,$E22),0)} -> 8.6991543
A23: 11a | B23: FT-SPK | C23: Aviation-bio | D23: {=IFERROR(SUMPRODUCT(($A$36:$A$137=$A23)*($B$36:$B$137=$B22)*($C$36:$C$137=$D23)*($D$36:$D$137=$E23)*$K$36:$K$137*$M$36:$M$137)/SUMIFS($K$36:$K$137,$A$36:$A$137,$A23,$B$36:$B$137,$B22,$C$36:$C$137,$D23,$D$36:$D$137,$E23),0)} -> 8.6991543
A24: 12 | B24: Pathway output | C24: Road | D24: {=IFERROR(SUMPRODUCT(($A$36:$A$137=$A24)*($B$36:$B$137=$B23)*($C$36:$C$137=$D24)*($D$36:$D$137=$E24)*$K$36:$K$137*$M$36:$M$137)/SUMIFS($K$36:$K$137,$A$36:$A$137,$A24,$B$36:$B$137,$B23,$C$36:$C$137,$D24,$D$36:$D$137,$E24),0)} -> 29.4
A25: 13a | B25: Gasoline+Diesel | C25: Road, aviation., maritim | D25: {=IFERROR(SUMPRODUCT(($A$36:$A$137=$A25)*($B$36:$B$137=$B24)*($C$36:$C$137=$D25)*($D$36:$D$137=$E25)*$K$36:$K$137*$M$36:$M$137)/SUMIFS($K$36:$K$137,$A$36:$A$137,$A25,$B$36:$B$137,$B24,$C$36:$C$137,$D25,$D$36:$D$137,$E25),0)} -> 55.5
A26: 13b | B26: Biogasoline | C26: Road-bio | D26: {=IFERROR(SUMPRODUCT(($A$36:$A$137=$A26)*($B$36:$B$137=$B25)*($C$36:$C$137=$D26)*($D$36:$D$137=$E26)*$K$36:$K$137*$M$36:$M$137)/SUMIFS($K$36:$K$137,$A$36:$A$137,$A26,$B$36:$B$137,$B25,$C$36:$C$137,$D26,$D$36:$D$137,$E26),0)} -> 26.8
A27: 13b | B27: Bio-heavy fuel oil | C27: Maritime-bio 2040/2050 | D27: {=IFERROR(SUMPRODUCT(($A$36:$A$137=$A27)*($B$36:$B$137=$B26)*($C$36:$C$137=$D27)*($D$36:$D$137=$E27)*$K$36:$K$137*$M$36:$M$137)/SUMIFS($K$36:$K$137,$A$36:$A$137,$A27,$B$36:$B$137,$B26,$C$36:$C$137,$D27,$D$36:$D$137,$E27),0)} -> 26.8
A29: transesterification of food/feed crops | B29: diesel | C29: Food/feed crops | D29: 27.7
A30: hydrotreatment of food/feed crops | B30: diesel | C30: Food/feed crops | D30: 30.1
A31: ethanol fermentation of food/feed crops | B31: Gasoline | C31: Food/feed crops | D31: 29.1
A32: transesterification of cover crops from marginal lands | B32: diesel | C32: Cover crops from marginal lands | D32: 27.7
A33: hydrotreatment of cover crops from marginal lands (non-aviation part) | B33: diesel | C33: Cover crops from marginal lands | D33: 25.6
A34: transesterification of UCO and AF | B34: diesel | C34: UCO and animal fats | D34: 17
A35: hydrotreatment of UCO and AF | B35: diesel | C35: UCO and animal fats | D35: 17.4

Sheet Import Emissions
A1: Emissions attributable to EU imports of finished renewable fuels | J1: ='2030 Sc 1'!B3 -> 7.9193948
A2: EI = simple average of all matching IVC rows in Tabelle1 (gCO2eq/MJ) | J2: ='2023'!F40 -> 2486154.8
J3: ='2023'!C17 -> 1.1315676
A4: Energy conversion
A5: MJ per toe | B5: 41868
F6: EI inputs taken from Tabelle1 column D (displayed values; source formulas are circular)
A7: Import category | B7: Matched Tabelle1 rows | C7: EI [gCO2eq/MJ] | F7: Tabelle1 ref | G7: Pathway | H7: EI [gCO2eq/MJ] | I7: Weight
A8: Advanced biodiesel (FAME / HVO) | B8: IVC 1, 2 (rows 2-6) | C8: =AVERAGE($H$8:$H$12) -> 13.178 | F8: Tabelle1!D2 | G8: IVC 1 - FAME, UCO / animal fat | H8: 12.15
A9: Advanced biogasoline (ethanol) | B9: IVC 5, 12, 13b (rows 12, 24, 26) | C9: =AVERAGE($H$15:$H$16,$H$31) -> 26.866667 | F9: Tabelle1!D3 | G9: IVC 1 - FAME, POME | H9: 15.39
A10: Advanced biogas / biomethane | B10: IVC 7, 9a (rows 15, 20) | C10: =AVERAGE($H$17:$H$18) -> -20.27691 | F10: Tabelle1!D4 | G10: IVC 2 - HVO, UCO / animal fat | H10: 13.775
A11: Advanced bio-kerosene (HEFA / ATJ / FT-SPK) | B11: IVC 2 50% / IVC 6 25% / IVC 11a 25% (weights in I19:I25) | C11: =SUMPRODUCT($H$19:$H$25,$I$19:$I$25) -> 16.243539 | F11: Tabelle1!D5 | G11: IVC 2 - HVO, POME / tall oil | H11: 10.8
A12: Advanced bio-HFO | B12: IVC 8a 45% / IVC 8b 45% / IVC 13b 10% (weights in I26:I28) | C12: =SUMPRODUCT($H$26:$H$28,$I$26:$I$28) -> 13.705 | F12: Tabelle1!D6 | G12: IVC 2 - HVO, FPBO + biocrude | H12: 13.775
A13: Conventional biodiesel (food/feed crops) | B13: Food/feed transesterif. + hydrotreatment (rows 29-30) | C13: =AVERAGE(Tabelle1!D29:D30) -> 28.9 | F13: Tabelle1!D11 | G13: IVC 3 - Renewable diesel (excluded) | H13: 55.5
A14: Conventional biogasoline (food/feed crops) | B14: Ethanol fermentation food/feed (row 31) | C14: =Tabelle1!D31 -> 29.1 | F14: Tabelle1!D22 | G14: IVC 11a - Biodiesel (excluded) | H14: 8.6991543
A15: RFNBO e-methanol (IVC 8c) | B15: IVC 8c (row 18) | C15: =$H$29 -> 1.8 | F15: Tabelle1!D12 | G15: IVC 5 - Advanced ethanol | H15: 24.4
A16: RFNBO e-methane (IVC 9b) | B16: IVC 9b (row 21) | C16: =$H$30 -> 2.4 | F16: Tabelle1!D26 | G16: IVC 13b - Biogasoline | H16: 26.8
F17: Tabelle1!D15 | G17: IVC 7 - Biomethane | H17: -62.308737
F18: Tabelle1!D20 | G18: IVC 9a - Methane | H18: 21.754917
F19: Tabelle1!D7 | G19: IVC 2 - HEFA/SAF, oil crops | H19: 26.05 | I19: 0.125
F20: Tabelle1!D8 | G20: IVC 2 - HEFA/SAF, UCO / animal fat | H20: 21.4 | I20: 0.125
F21: Tabelle1!D9 | G21: IVC 2 - HEFA/SAF, POME / tall oil | H21: 17.5 | I21: 0.125
F22: Tabelle1!D10 | G22: IVC 2 - HEFA/SAF, FPBO + biocrude | H22: 21.4 | I22: 0.125
F23: Tabelle1!D13 | G23: IVC 5 - ATJ-SPK (excluded) | H23: 24.4 | I23: 0
F24: Tabelle1!D14 | G24: IVC 6 - ATJ-SPK | H24: 13.1 | I24: 0.25
F25: Tabelle1!D23 | G25: IVC 11a - FT-SPK | H25: 8.6991543 | I25: 0.25
F26: Tabelle1!D16 | G26: IVC 8a - Methanol | H26: 12.5 | I26: 0.45
F27: Tabelle1!D17 | G27: IVC 8b - Methanol | H27: 12 | I27: 0.45
F28: Tabelle1!D27 | G28: IVC 13b - Bio-heavy fuel oil | H28: 26.8 | I28: 0.1
F29: Tabelle1!D18 | G29: IVC 8c - e-Methanol (RFNBO) | H29: 1.8
F30: Tabelle1!D21 | G30: IVC 9b - e-Methane (RFNBO) | H30: 2.4
F31: Tabelle1!D24 | G31: IVC 12 - Pathway output (road) | H31: 29.4
G32: Weight check (bio-kerosene) = 100% | I32: =SUM($I$19:$I$25) -> 1
A33: Imported volumes [Mtoe] | G33: Weight check (bio-HFO) = 100% | I33: =SUM($I$26:$I$28) -> 1
A34: Import category | B34: 2023 | C34: 2030 Sc 1 | D34: 2030 Sc 2 | E34: 2030 Sc 3 | F34: 2035 Sc 1 | G34: 2035 Sc 2 | H34: 2035 Sc 3 | I34: 2040 Sc 1 | J34: 2040 Sc 2 | K34: 2040 Sc 3
A35: =$A$8 -> Advanced biodiesel (FAME / HVO) | B35: 0 | C35: ='2030 Sc 1'!B3 -> 7.9193948 | D35: ='2030 Sc 2'!B4 -> 0 | E35: 0 | F35: ='2035 Sc 1'!B4 -> 11.471013 | G35: ='2035 Sc 2'!B3 -> 0 | H35: ='2035 Sc 3'!B3 -> 0 | I35: ='2040 Sc 1'!B3 -> 11.167026 | J35: ='2040 Sc 2'!B3 -> 0 | K35: ='2040 Sc 3'!B3 -> 0
A36: =$A$9 -> Advanced biogasoline (ethanol) | B36: 0 | C36: ='2030 Sc 1'!B4 -> 3.6551267 | D36: ='2030 Sc 2'!B5 -> 0 | E36: 0 | F36: ='2035 Sc 1'!B5 -> 2.0844603 | G36: ='2035 Sc 2'!B4 -> 0 | H36: ='2035 Sc 3'!B4 -> 0 | I36: ='2040 Sc 1'!B4 -> 0.74936264 | J36: ='2040 Sc 2'!B4 -> 0 | K36: ='2040 Sc 3'!B4 -> 0
A37: =$A$10 -> Advanced biogas / biomethane | B37: 0 | C37: ='2030 Sc 1'!B5 -> 0 | D37: ='2030 Sc 2'!B6 -> 0 | E37: 0 | F37: ='2035 Sc 1'!B6 -> 0 | G37: ='2035 Sc 2'!B5 -> 0 | H37: ='2035 Sc 3'!B5 -> 0 | I37: ='2040 Sc 1'!B5 -> 0 | J37: ='2040 Sc 2'!B5 -> 0 | K37: ='2040 Sc 3'!B5 -> 0
A38: =$A$11 -> Advanced bio-kerosene (HEFA / ATJ / FT-SPK) | B38: 0 | C38: ='2030 Sc 1'!B6 -> 0.79777401 | D38: ='2030 Sc 2'!B7 -> 0 | E38: 0 | F38: ='2035 Sc 1'!B7 -> 3.5163409 | G38: ='2035 Sc 2'!B6 -> 0 | H38: ='2035 Sc 3'!B6 -> 0 | I38: ='2040 Sc 1'!B6 -> 4.7218354 | J38: ='2040 Sc 2'!B6 -> 0 | K38: ='2040 Sc 3'!B6 -> 0
A39: =$A$12 -> Advanced bio-HFO | B39: 0 | C39: ='2030 Sc 1'!B7 -> 0.9897683 | D39: ='2030 Sc 2'!B8 -> 0 | E39: 0 | F39: ='2035 Sc 1'!B8 -> 0.36429701 | G39: ='2035 Sc 2'!B7 -> 0 | H39: ='2035 Sc 3'!B7 -> 0 | I39: ='2040 Sc 1'!B7 -> 5.6543291 | J39: ='2040 Sc 2'!B7 -> 0 | K39: ='2040 Sc 3'!B7 -> 0
A40: =$A$13 -> Conventional biodiesel (food/feed crops) | B40: ='2023'!F40/'2023'!C17/1000000 -> 2.1970891 | C40: ='2030 Sc 1'!B10 -> 0.7241411 | D40: ='2030 Sc 2'!B11 -> 6.2189821 | E40: 0 | F40: 0 | G40: ='2035 Sc 2'!B10 -> 0 | H40: ='2035 Sc 3'!B10 -> 0 | I40: ='2040 Sc 1'!B10 -> 0 | J40: ='2040 Sc 2'!B10 -> 0 | K40: ='2040 Sc 3'!B10 -> 0
...

Sheet 2030 Sc 1
A1: IMPORTS of finished fuels to the EU
A2: ADVANCED biofuels | B2: Imported 2030 [Mtoe] | C2: Conversion factor [t/toe] | D2: Imported 2030 [t] | E2: Trade price | F2: Market value of amount imported [€] | G2: In Million Eur
A3: Biodiesel | B3: ='[3]GAP analysis Sc. 1'!$I$36 -> 7.9193948 | C3: =('[2]2030 costs Sc 1'!$E$9+'[2]2030 costs Sc 1'!$E$16+'[2]2030 costs Sc 1'!$E$23)/3 -> 1.0277043 | D3: =B3*C3*1000000 -> 8138796.4 | E3: =(1450+1750)/2 -> 1600 | F3: =D3*E3 -> 1.3022074e+10 | G3: =F3/1000000 -> 13022.074
A4: Biogasoline | B4: ='[3]GAP analysis Sc. 1'!$G$39 -> 3.6551267 | C4: =('[2]2035 costs Sc 1'!$E$43+'[2]2035 costs Sc 1'!$E$57)/2 -> 1.2753333 | D4: =B4*C4*1000000 -> 4661505 | E4: 1000 | F4: =D4*E4 -> 4.661505e+09 | G4: =F4/1000000 -> 4661.505
A5: Biogas | B5: 0 | C5: =('[2]2035 costs Sc 1'!$E$85) -> 0.83669065 | D5: =B5*C5*1000000 -> 0 | E5: 1275 | F5: =D5*E5 -> 0 | G5: =F5/1000000 -> 0
A6: Bio-kerosene | B6: ='[3]GAP analysis Sc. 1'!$G$59 -> 0.79777401 | C6: =('[2]2035 costs Sc 1'!$E$119+'[2]2035 costs Sc 1'!$E$126+'[2]2035 costs Sc 1'!$E$138)/3 -> 0.98244961 | D6: =B6*C6*1000000 -> 783772.76 | E6: 2380 | F6: =D6*E6 -> 1.8653792e+09 | G6: =F6/1000000 -> 1865.3792
A7: Bio-HFO | B7: ='[3]GAP analysis Sc. 1'!$G$48 -> 0.9897683 | C7: 2 | D7: =B7*C7*1000000 -> 1979536.6 | E7: 935 | F7: =D7*E7 -> 1.8508667e+09 | G7: =F7/1000000 -> 1850.8667
A8: Summe | B8: =SUM(B3:B7) -> 13.362064 | D8: =SUM(D3:D7) -> 15563611 | E8: =SUM(E3:E7) -> 7190 | F8: =SUM(F3:F7) -> 2.1399825e+10 | G8: =SUM(G3:G7) -> 21399.825
A9: CONVENTIONAL biofuels | B9: Imported 2030 [Mtoe] | D9: Imported 2030 [t] | E9: Trade price | F9: Market value of amount imported [€] | G9: In Million Eur
A10: Biodiesel | B10: ='[3]GAP analysis Sc. 1'!$I$37 -> 0.7241411 | C10: =('[2]2035 costs Sc 1'!$E$203+'[2]2035 costs Sc 1'!$E$211+'[2]2035 costs Sc 1'!$E$218+'[2]2035 costs Sc 1'!$E$226)/4 -> 1.0415565 | D10: =B10*C10*1000000 -> 754233.88 | E10: 1165.6261 | F10: =D10*E10 -> 8.7915472e+08 | G10: =SUM(G5:G9) -> 25116.071
A11: RFNBOs
A12: from IVC 8c | B12: 0
A13: from IVC 9b | B13: ='[3]GAP analysis Sc. 1'!$G$66 -> 0.33661569 | C13: ='[2]2040 Sc 1'!$E$171 -> 0.83669065 | D13: =B13*C13*1000000 -> 281643.2 | E13: 1275 | F13: =D13*E13 -> 3.5909508e+08

Sheet 2030 Sc 2
A2: IMPORTS of finished fuels to the EU
A3: ADVANCED biofuels | B3: Imported 2030 [Mtoe] | C3: Conversion factor | D3: Imported 2030 [t] | E3: Trade price | F3: Market value of amount imported [€] | G3: In Million Eur
A4: Biodiesel | B4: ='[2]2030 costs Sc 2'!$D$275 -> 0 | D4: ='[2]2030 costs Sc 2'!$F$275 -> 0 | E4: =(1450+1750)/2 -> 1600 | F4: =D4*E4 -> 0 | G4: =F4/1000000 -> 0
A5: Biogasoline | B5: 0 | E5: 1000
A6: Biogas | B6: 0
A7: Bio-kerosene | B7: 0
A8: Bio-HFO | B8: 0
A9: Sum imported advanced | B9: =SUM(B4:B8) -> 0 | G9: =SUM(G4:G8) -> 0
A10: CONVENTIONAL biofuels | B10: Imported 2030 [Mtoe] | D10: Imported 2030 [t] | E10: Trade price | F10: Market value of amount imported [€] | G10: In Million Eur
A11: Biodiesel | B11: ='[3]GAP analysis Sc. 2'!$G$37 -> 6.2189821 | C11: =('[2]2035 costs Sc 1'!$E$203+'[2]2035 costs Sc 1'!$E$211+'[2]2035 costs Sc 1'!$E$218+'[2]2035 costs Sc 1'!$E$226)/4 -> 1.0415565 | D11: =B11*C11*1000000 -> 6477421.3 | E11: 1165.6261 | F11: =D11*E11 -> 7.5502515e+09 | G11: =F11/1000000 -> 7550.2515

Sheet 2030 Sc 3
A1: EXPORTS of finished fuels to the EU | B1: in Mtoe | C1: Conversion factor | D1: Exported in tons | E1: Market price | F1: Market value of exports
A2: Gap between production and demand
A3: Demand
A4: Advanced biodiesel | B4: ='[1]Scenario 3 2030'!$I$4 -> 0.98610231 | C4: =('[2]2030 costs Sc 1'!$E$9+'[2]2030 costs Sc 1'!$E$16+'[2]2030 costs Sc 1'!$E$23)/3 -> 1.0277043 | D4: =B4*C4*1000000 -> 1013421.6 | E4: =(1450+1750)/2 -> 1600 | F4: =D4*E4 -> 1.6214746e+09
A5: Advanced biogasoline | B5: ='[1]Scenario 3 2030'!$I$8 -> 30.513235 | C5: =('[2]2035 costs Sc 1'!$E$43+'[2]2035 costs Sc 1'!$E$57)/2 -> 1.2753333 | D5: =B5*C5*1000000 -> 38914546 | E5: 1000 | F5: =D5*E5 -> 3.8914546e+10
A6: Advanced biogas | B6: ='[1]Scenario 3 2030'!$I$14 -> 24.295003 | C6: =('[2]2035 costs Sc 1'!$E$85) -> 0.83669065 | D6: =B6*C6*1000000 -> 20327402 | E6: 1275 | F6: =D6*E6 -> 2.5917437e+10
A7: Advanced bio-kerosene | B7: ='[1]Scenario 3 2030'!$I$28 -> 7.0505844 | C7: 0.97 | D7: =B7*C7*1000000 -> 6839066.9 | E7: 2380 | F7: =D7*E7 -> 1.6276979e+10
A8: Advanced bio-HFO | B8: ='[1]Scenario 3 2030'!$I$20 -> 22.789276 | C8: 2 | D8: =B8*C8*1000000 -> 45578552 | E8: 935 | F8: =D8*E8 -> 4.2615946e+10
A9: SUM exports | B9: =SUM(B4:B8) -> 85.634201 | F9: =SUM(F4:F8) -> 1.2534638e+11
A11: RFNBOs 8c | B11: ='[1]Scenario 3 2030'!$G$26 -> 5.1463701 | C11: ='[2]2030 costs Sc 3'!$E$202 -> 2.0934 | D11: =B11*C11*1000000 -> 10773411 | E11: 935 | F11: =D11*E11 -> 1.0073139e+10
A12: RFNBO 9b | B12: ='[1]Scenario 3 2030'!$G$17 -> 6.5401862 | C12: ='[2]2030 costs Sc 3'!$E$209 -> 0.83669065 | D12: =B12*C12*1000000 -> 5472112.6 | E12: 1275 | F12: =D12*E12 -> 6.9769436e+09
B13: =B9+B11+B12 -> 97.320757 | F13: =F11+F12 -> 1.7050083e+10
A14: IMPORTS of finished fuels to the EU | C14: NONE
A15: ADVANCED biofuels | B15: Imported 2030 [Mtoe] | C15: Imported 2030 [t] | D15: Trade price | E15: Market value of amount imported [€] | F15: In Million Eur
A16: Biodiesel | D16: =(1450+1750)/2 -> 1600
A17: Biogasoline | D17: 1000
A18: Biogas | D18: 1275
A19: Bio-kerosene | D19: 2380
A20: Bio-HFO | D20: 935
A22: CONVENTIONAL biofuels | B22: Imported 2030 [Mtoe] | C22: Imported 2030 [t] | D22: Trade price | E22: Market value of amount imported [€] | F22: In Million Eur
A23: Biodiesel | C23: =B23*1*1000000 -> 0 | E23: =C23*D23 -> 0

Sheet 2035 Sc 1
A1: IMPORTS of finished fuels to the EU
B2: Imported [Mtoe] | C2: Conversion factor | D2: Imported [t] | E2: Trade price | F2: Market value of amount imported [€] | G2: In Million Eur
A3: ADVANCED biofuels
A4: Biodiesel | B4: ='[3]GAP analysis Sc. 1'!$G$73 -> 11.471013 | C4: 1.0277043 | D4: =B4*C4*1000000 -> 11788810 | E4: =(1450+1750)/2 -> 1600 | F4: =D4*E4 -> 1.8862096e+10
A5: Biogasoline | B5: ='[3]GAP analysis Sc. 1'!$G$77 -> 2.0844603 | C5: 1.2753333 | D5: =B5*C5*1000000 -> 2658381.7 | E5: 1000 | F5: =D5*E5 -> 2.6583817e+09
A6: Biogas | B6: 0 | C6: 0.83669065 | D6: =B6*C6*1000000 -> 0 | E6: 0 | F6: =D6*E6 -> 0
A7: Bio-kerosene | B7: ='[3]GAP analysis Sc. 1'!$G$95 -> 3.5163409 | C7: 0.98244961 | D7: =B7*C7*1000000 -> 3454627.8 | E7: 2380 | F7: =D7*E7 -> 8.2220141e+09
A8: Bio-HFO | B8: ='[3]GAP analysis Sc. 1'!$G$86 -> 0.36429701 | C8: 2 | D8: =B8*C8*1000000 -> 728594.03 | E8: 1000 | F8: =D8*E8 -> 7.2859403e+08
A9: Sum Imports Advanced | B9: =SUM(B4:B8) -> 17.436111 | C9: =SUM(C4:C8) -> 6.1221779
A10: CONVENTIONAL biofuels | E10: Trade price | F10: Market value of amount imported [€] | G10: In Million Eur
A11: Biodiesel
A12: Sum ALL Imports
A13: RFNBOs
A14: IVC8c | B14: ='[3]GAP analysis Sc. 1'!$E$106+'[3]GAP analysis Sc. 1'!$E$107 -> 3.6400411 | C14: ='[2]2040 Sc 1'!$E$164 -> 2.0934 | D14: =B14*C14*1000000 -> 7620062.1 | E14: 935 | F14: =D14*E14 -> 7.124758e+09
A15: IVC9b | B15: ='[3]GAP analysis Sc. 1'!$E$105 -> 10.008769 | C15: ='[2]2040 Sc 1'!$E$171 -> 0.83669065 | D15: =B15*C15*1000000 -> 8374243.7 | E15: 1275 | F15: =D15*E15 -> 1.0677161e+10
A16: Sum | F16: =SUM(F14:F15) -> 1.7801919e+10

Sheet 2035 Sc 2
A1: IMPORTS of finished fuels to the EU
A2: ADVANCED biofuels | B2: Imported 2035 [Mtoe] | C2: Conversion factor | E2: Trade price | F2: Market value of amount imported [€] | G2: In Million Eur
A3: Biodiesel | B3: 0 | C3: 1.0277043 | D3: =B3*C3*1000000 -> 0 | E3: =(1450+1750)/2 -> 1600 | F3: =D3*E3 -> 0
A4: Biogasoline | B4: 0 | C4: 1.2753333 | D4: =B4*C4*1000000 -> 0 | E4: 1000 | F4: =D4*E4 -> 0
A5: Biogas | B5: 0 | C5: 0.83669065 | D5: =B5*C5*1000000 -> 0 | E5: 1275 | F5: =D5*E5 -> 0
A6: Bio-kerosene | B6: 0 | C6: 0.98244961 | D6: =B6*C6*1000000 -> 0 | E6: 2380 | F6: =D6*E6 -> 0
A7: Bio-HFO | B7: 0 | C7: 2.0934 | D7: =B7*C7*1000000 -> 0 | E7: 935 | F7: =D7*E7 -> 0
A8: Sum Imports Advanced | B8: 0 | C8: =SUM(C3:C7) -> 6.2155779
A9: CONVENTIONAL biofuels | B9: Imported 2035 [Mtoe] | C9: Conversion factor | E9: Trade price | F9: Market value of amount imported [€] | G9: In Million Eur
A10: Biodiesel | B10: 0 | C10: =B10*1000000 -> 0
A11: Sum ALL Imports | B11: 0
A12: RFNBOs | B12: Imported 2035 [Mtoe] | C12: Conversion factor | D12: Imported in [t] | E12: Trade price | F12: Market value of amount imported [€]
A13: from 8c | B13: ='[3]GAP analysis Sc. 2'!$G$98+'[3]GAP analysis Sc. 2'!$G$99 -> 1.9665946 | C13: ='[2]2030 costs Sc 3'!$E$202 -> 2.0934 | D13: =B13*C13*1000000 -> 4116869.1 | E13: 935 | F13: =D13*E13 -> 3.8492727e+09
A14: from 9b | B14: ='[3]GAP analysis Sc. 2'!$G$97 -> 1.5341825 | C14: ='[2]2030 costs Sc 3'!$E$209 -> 0.83669065 | D14: =B14*C14*1000000 -> 1283636.2 | E14: 1275 | F14: =D14*E14 -> 1.6366361e+09
F15: =F13+F14 -> 5.4859088e+09

Sheet 2035 Sc 3
A1: IMPORTS of finished fuels to the EU
A2: ADVANCED biofuels | B2: Imported 2030 [Mtoe] | C2: Conversion factor | D2: Imported 2030 [t] | E2: Trade price | F2: Market value of amount imported [€] | G2: In Million Eur
A3: Biodiesel | B3: 0 | E3: =(1450+1750)/2 -> 1600
A4: Biogasoline | B4: 0 | E4: 1000
A5: Biogas | B5: 0 | E5: 1275
A6: Bio-kerosene | B6: 0 | E6: 2380
A7: Bio-HFO | B7: 0 | E7: 935
A9: CONVENTIONAL biofuels | B9: Imported 2030 [Mtoe] | D9: Imported 2030 [t] | E9: Trade price | F9: Market value of amount imported [€] | G9: In Million Eur
A10: Biodiesel | B10: 0 | D10: =B10*1*1000000 -> 0 | E10: 1165.6261 | F10: =D10*E10 -> 0
A11: RFNBOs
A12: from 9b | B12: ='[1]Scenario 3 2035'!$N$38 -> 1.5341825 | C12: ='[2]2030 costs Sc 3'!$E$209 -> 0.83669065 | D12: =B12*C12*1000000 -> 1283636.2 | E12: 1275 | F12: =D12*E12 -> 1.6366361e+09
A13: EXPORTS of finished fuels to the EU | B13: in Mtoe | C13: Conversion factor | D13: Exported in tons | E13: Market price | F13: Market value of exports
A14: Demand
A15: Advanced biodiesel | B15: =0 -> 0 | C15: 0 | D15: =B15*C15*1000000 -> 0 | E15: =(1450+1750)/2 -> 1600 | F15: =D15*E15 -> 0
A16: Advanced biogasoline | B16: ='[1]Scenario 3 2035'!$M$7 -> 35.084061 | C16: =('[2]2035 costs Sc 1'!$E$43+'[2]2035 costs Sc 1'!$E$57)/2 -> 1.2753333 | D16: =B16*C16*1000000 -> 44743872 | E16: 1000 | F16: =D16*E16 -> 4.4743872e+10
A17: Advanced biogas | B17: ='[1]Scenario 3 2035'!$M$12 -> 24.668074 | C17: =('[2]2035 costs Sc 1'!$E$85) -> 0.83669065 | D17: =B17*C17*1000000 -> 20639547 | E17: 1275 | F17: =D17*E17 -> 2.6315422e+10
A18: Advanced bio-kerosene | B18: ='[1]Scenario 3 2035'!$M$26 -> 6.6375865 | C18: =('[2]2035 costs Sc 1'!$E$119+'[2]2035 costs Sc 1'!$E$126+'[2]2035 costs Sc 1'!$E$138)/3 -> 0.98244961 | D18: =B18*C18*1000000 -> 6521094.3 | E18: 2380 | F18: =D18*E18 -> 1.5520204e+10
A19: Advanced bio-HFO | B19: ='[1]Scenario 3 2035'!$M$16 -> 21.162482 | C19: 2 | D19: =B19*C19*1000000 -> 42324965 | E19: 935 | F19: =D19*E19 -> 3.9573842e+10
A20: SUM exports | B20: =SUM(B15:B19) -> 87.552204 | F20: =SUM(F15:F19) -> 1.2615334e+11
A22: RFNBOs 8c | B22: ='[1]Scenario 3 2035'!$K$36+'[1]Scenario 3 2035'!$K$37 -> 2.4888585 | C22: ='[2]2030 costs Sc 3'!$E$202 -> 2.0934 | D22: =B22*C22*1000000 -> 5210176.4 | E22: 935 | F22: =D22*E22 -> 4.871515e+09
A23: RFNBO 9b | B23: 0 | C23: ='[2]2030 costs Sc 3'!$E$209 -> 0.83669065 | D23: =B23*C23*1000000 -> 0 | E23: 1275 | F23: =D23*E23 -> 0
F24: =F22+F23 -> 4.871515e+09

Sheet 2040  Sc 1
A1: IMPORTS of finished fuels to the EU
A2: ADVANCED biofuels | B2: Imported 2035 [Mtoe] | C2: Conversion factor | D2: Imported 2035 [t] | E2: Trade price | F2: Market value of amount imported [€] | G2: In Million Eur
A3: Biodiesel | B3: ='[3]GAP analysis Sc. 1'!$G$112 -> 11.167026 | C3: 1.0277043 | D3: =B3*C3*1000000 -> 11476401 | E3: =(1450+1750)/2 -> 1600 | F3: =D3*E3 -> 1.8362242e+10
A4: Biogasoline | B4: ='[3]GAP analysis Sc. 1'!$G$116 -> 0.74936264 | C4: 1.2753333 | D4: =B4*C4*1000000 -> 955687.15 | E4: 1000 | F4: =D4*E4 -> 9.5568715e+08
A5: Biogas | B5: =0 -> 0 | C5: 0.83669065 | D5: =B5*C5*1000000 -> 0 | E5: 1275 | F5: =D5*E5 -> 0
A6: Bio-kerosene | B6: ='[3]GAP analysis Sc. 1'!$G$134 -> 4.7218354 | C6: 0.98244961 | D6: =B6*C6*1000000 -> 4638965.4 | E6: 2380 | F6: =D6*E6 -> 1.1040738e+10
A7: Bio-HFO | B7: ='[3]GAP analysis Sc. 1'!$G$125 -> 5.6543291 | C7: 2 | D7: =B7*C7*1000000 -> 11308658 | E7: 935 | F7: =D7*E7 -> 1.0573595e+10
A8: Sum Imports Advanced | B8: =SUM(B3:B7) -> 22.292553 | C8: =SUM(C3:C7) -> 6.1221779 | D8: =SUM(D3:D7) -> 28379712
A9: CONVENTIONAL biofuels | B9: Imported 2035 [Mtoe] | D9: Imported 2035 [t] | E9: Trade price | F9: Market value of amount imported [€] | G9: In Million Eur
A10: Biodiesel | B10: 0
A11: Sum ALL Imports | B11: =B8 -> 22.292553 | D11: =D8 -> 28379712
A12: RFNBOs
A13: from 8c | B13: ='[3]GAP analysis Sc. 1'!$G$146+'[3]GAP analysis Sc. 1'!$G$147 -> 6.7588959 | C13: ='[2]2040 Sc 1'!$E$164 -> 2.0934 | D13: =B13*C13*1000000 -> 14149073 | E13: 935 | F13: =D13*E13 -> 1.3229383e+10
A14: from 9b | B14: ='[3]GAP analysis Sc. 1'!$G$145 -> 14.96838 | C14: ='[2]2040 Sc 1'!$E$171 -> 0.83669065 | D14: =B14*C14*1000000 -> 12523903 | E14: 1275 | F14: =D14*E14 -> 1.5967977e+10
F15: =SUM(F13:F14) -> 2.919736e+10

Sheet 2040 Sc 2
A1: IMPORTS of finished fuels to the EU
A2: ADVANCED biofuels | B2: Imported 2030 [Mtoe] | C2: Conversion factor | D2: Imported 2030 [t] | E2: Trade price | F2: Market value of amount imported [€] | G2: In Million Eur
A3: Biodiesel | B3: 0 | E3: =(1450+1750)/2 -> 1600
A4: Biogasoline | B4: 0 | E4: 1000
A5: Biogas | B5: 0 | E5: 1275
A6: Bio-kerosene | B6: 0 | E6: 2380
A7: Bio-HFO | B7: 0 | E7: 935
A9: CONVENTIONAL biofuels | B9: Imported 2030 [Mtoe] | D9: Imported 2030 [t] | E9: Trade price | F9: Market value of amount imported [€] | G9: In Million Eur
A10: Biodiesel | B10: 0 | D10: =B10*1*1000000 -> 0 | E10: 1165.6261 | F10: =D10*E10 -> 0
A11: RFNBOs | B11: Imported 2030 [Mtoe] | D11: Imported 2030 [t] | E11: Trade price | F11: Market value of amount imported [€] | G11: In Million Eur
A12: from 8c | B12: ='[3]GAP analysis Sc. 2'!$H$125+'[3]GAP analysis Sc. 2'!$H$133 -> 3.6311851 | C12: ='[2]2030 costs Sc 3'!$E$202 -> 2.0934 | D12: =B12*C12*1000000 -> 7601522.8 | E12: 935 | F12: =D12*E12 -> 7.1074238e+09
A13: from 9b | B13: ='[3]GAP analysis Sc. 2'!$H$115 -> 5.8619293 | C13: ='[2]2030 costs Sc 3'!$E$209 -> 0.83669065 | D13: =B13*C13*1000000 -> 4904621.4 | E13: 1275 | F13: =D13*E13 -> 6.2533923e+09 | G13: =B12+B13 -> 9.4931143 | H13: =F12+F13 -> 1.3360816e+10
A14: EXPORTS of finished fuels to the EU | B14: in Mtoe | C14: Conversion factor | D14: Exported in tons | E14: Market price | F14: Market value of exports | G14: NONE
A15: Demand
A16: Advanced biodiesel | B16: 0 | C16: 0 | D16: =B16*C16*1000000 -> 0 | E16: =(1450+1750)/2 -> 1600 | F16: =D16*E16 -> 0
A17: Advanced biogasoline | B17: 0 | C17: =('[2]2035 costs Sc 1'!$E$43+'[2]2035 costs Sc 1'!$E$57)/2 -> 1.2753333 | D17: =B17*C17*1000000 -> 0 | E17: 1000 | F17: =D17*E17 -> 0
A18: Advanced biogas | B18: 0 | C18: =('[2]2035 costs Sc 1'!$E$85) -> 0.83669065 | D18: =B18*C18*1000000 -> 0 | E18: 1275 | F18: =D18*E18 -> 0
A19: Advanced bio-kerosene | B19: 0 | C19: =('[2]2035 costs Sc 1'!$E$119+'[2]2035 costs Sc 1'!$E$126+'[2]2035 costs Sc 1'!$E$138)/3 -> 0.98244961 | D19: =B19*C19*1000000 -> 0 | E19: 2380 | F19: =D19*E19 -> 0
A20: Advanced bio-HFO | B20: 0 | C20: =('[2]2035 costs Sc 1'!$E$152+'[2]2035 costs Sc 1'!$E$163)/2 -> 2.0934 | D20: =B20*C20*1000000 -> 0 | E20: 935 | F20: =D20*E20 -> 0
A21: SUM exports | B21: 0 | F21: =SUM(F16:F20) -> 0
A23: RFNBOs 8c | B23: 0 | C23: ='[2]2030 costs Sc 3'!$E$202 -> 2.0934 | D23: =B23*C23*1000000 -> 0 | E23: 935 | F23: =D23*E23 -> 0
A24: RFNBO 9b | B24: 0 | C24: ='[2]2030 costs Sc 3'!$E$209 -> 0.83669065 | D24: =B24*C24*1000000 -> 0 | E24: 1275 | F24: =D24*E24 -> 0
F25: =F23+F24 -> 0

Sheet 2040 Sc 3
A1: IMPORTS of finished fuels to the EU | C1: Conversion factor | D1: Exported in tons | E1: Market price | F1: Market value of exports
A2: ADVANCED biofuels | B2: Imported 2030 [Mtoe] | D2: Imported 2030 [t] | E2: Trade price | F2: Market value of amount imported [€] | G2: In Million Eur
A3: Biodiesel | B3: 0 | E3: =(1450+1750)/2 -> 1600
A4: Biogasoline | B4: 0 | E4: 1000
A5: Biogas | B5: 0 | E5: 1275
A6: Bio-kerosene | B6: 0 | E6: 2380
A7: Bio-HFO | B7: 0 | E7: 935
A9: CONVENTIONAL biofuels | B9: Imported 2030 [Mtoe] | C9: Conversion factor | D9: Imported 2030 [t] | E9: Trade price | F9: Market value of amount imported [€] | G9: In Million Eur
A10: Biodiesel | B10: 0 | D10: =B10*1*1000000 -> 0 | E10: 1165.6261 | F10: =D10*E10 -> 0
A11: RFNBOs
A12: from 8c
A13: from 9b
A14: RFNBOs | B14: Imported 2030 [Mtoe] | C14: Conversion factor | D14: Imported 2030 [t] | E14: Trade price | F14: Market value of amount imported [€] | G14: In Million Eur
A15: from 9b | B15: ='[1]Scenaior 3 2040'!$K$15 -> 4.8960079 | C15: ='[2]2030 costs Sc 3'!$E$209 -> 0.83669065 | D15: =B15*C15*1000000 -> 4096444 | E15: 1275 | F15: =D15*E15 -> 5.2229662e+09
A18: EXPORTS of finished fuels to the EU | B18: in Mtoe | C18: Conversion factor | D18: in tons | E18: Market price | F18: Market value of exports
A19: Advanced biodiesel | B19: 0 | C19: 0 | D19: =B19*C19*1000000 -> 0 | E19: =(1450+1750)/2 -> 1600 | F19: =D19*E19 -> 0
A20: Advanced biogasoline | B20: ='[1]Scenaior 3 2040'!$I$7 -> 38.324085 | C20: =('[2]2035 costs Sc 1'!$E$43+'[2]2035 costs Sc 1'!$E$57)/2 -> 1.2753333 | D20: =B20*C20*1000000 -> 48875983 | E20: 1000 | F20: =D20*E20 -> 4.8875983e+10
A21: Advanced biogas | B21: ='[1]Scenaior 3 2040'!$I$12 -> 24.727863 | C21: =('[2]2035 costs Sc 1'!$E$85) -> 0.83669065 | D21: =B21*C21*1000000 -> 20689572 | E21: 1275 | F21: =D21*E21 -> 2.6379204e+10
A22: Advanced bio-kerosene | B22: ='[1]Scenaior 3 2040'!$I$30 -> 5.1093755 | C22: =('[2]2035 costs Sc 1'!$E$119+'[2]2035 costs Sc 1'!$E$126+'[2]2035 costs Sc 1'!$E$138)/3 -> 0.98244961 | D22: =B22*C22*1000000 -> 5019704 | E22: 2380 | F22: =D22*E22 -> 1.1946895e+10 | G22: 4.9092007e+09
A23: Advanced bio-HFO | B23: ='[1]Scenaior 3 2040'!$I$18 -> 19.119384 | C23: 2 | D23: =B23*C23*1000000 -> 38238768 | E23: 935 | F23: =D23*E23 -> 3.5753248e+10
A24: SUM exports | B24: =SUM(B19:B23) -> 87.280708 | F24: =SUM(F19:F23) -> 1.2295533e+11
A26: RFNBOs 8c | B26: ='[1]Scenaior 3 2040'!$I$27+'[1]Scenaior 3 2040'!$I$36 -> 0.48506464 | C26: ='[2]2030 costs Sc 3'!$E$202 -> 2.0934 | D26: =B26*C26*1000000 -> 1015434.3 | E26: 935 | F26: =D26*E26 -> 9.4943108e+08
A27: RFNBO 9b | B27: 0 | C27: ='[2]2030 costs Sc 3'!$E$209 -> 0.83669065 | D27: =B27*C27*1000000 -> 0 | E27: 1275 | F27: =D27*E27 -> 0
F28: =F26+F27 -> 9.4943108e+08
