Workbook
Name _ftnref1: TRL!#REF!

Sheet conversion factors
D1: calculated from JEC_WTT_v5 | I1: estimation based on tender 1 values | M1: Background data RED (2009) | Q1: JEC_WTT_v5
A2: Nr. | B2: Value Chain | C2: Fuel | D2: product yield [t product / t feedstock] | E2: toe/t | F2: combined factor [toe product / t feedstock] | G2: (product in Mtoe) = (feedstock in Mt) * (t product / t feedstock) * (toe/t) | I2: effiency [MJ/MJ] | J2: product yield [t/t] | M2: Fuel | N2: toe/t | O2: LHV [MJ/kg] | Q2: IVC | R2: Pathway | S2: Yield | T2: Unit
A3: 1 | B3: Transesterification | C3: FAME | D3: 0.965 | E3: 0.88372982 | F3: =D3*E3 -> 0.85279927 | G3: LHV of feedstock and product quite similar | I3: 1 | J3: =I3 -> 1 | M3: Ethanol | N3: 0.64488392 | O3: 27 | Q3: 1 | R3: WOFA | S3: 0.965 | T3: MJ product/MJ oil
A4: 2 | B4: Hydrotreatment of Lipids | C4: HVO | D4: =1.039/2 -> 0.5195 | E4: 1.0509219 | F4: =D4*E4 -> 0.54595395 | G4: LHV of feedstock and product quite similar; 50% HVO, 50% HEFA | I4: 1 | J4: =I4 -> 1 | M4: ETBE | N4: 0.85984523 | O4: 36 | Q4: 2 | R4: WOHY1e | S4: 1.039 | T4: MJ product/MJ oil
C5: HEFA | D5: =1.039/2 -> 0.5195 | E5: 1.0270374 | F5: =D5*E5 -> 0.53354591 | G5: 50% HVO, 50% HEFA | M5: Methanol | N5: 0.47769179 | O5: 20 | Q5: 4 | R5: SBET | S5: 0.0777 | T5: kg ethanol/kg sugar beet
A6: 3 | B6: Lignin Boost of Fatty Acids and Co-processing in Refinery | C6: Renewable diesel | D6: 2 | E6: 1.0509219 | F6: =D6*E6 -> 2.1018439 | G6: 1 t fatty acid + 1 t lignin = 2 t product | M6: MTBE | N6: 0.83596064 | O6: 35 | R6: SBET | S6: 0.058 | T6: kg pulp/kg sugar beet
A7: 4 | B7: Sugar and Starch Fermentation to Ethanol | C7: Ethanol | D7: =1000/5500 -> 0.18181818 | E7: 0.64488392 | F7: =D7*E7 -> 0.11725162 | G7: St1 Etanolix 5,500 t of bakery waste --> 1,000 t of ethanol | M7: DME | N7: 0.66876851 | O7: 28 | R7: SBET | S7: =S5/S6 -> 1.3396552 | T7: kg ethanol/kg pulp
C8: ATJ-SPK | D8: =D11*D7 -> 0.10909091 | E8: 0.64488392 | F8: =D8*E8 -> 0.070350973 | M8: TAEE | N8: 0.90761441 | O8: 38 | Q8: 5 | R8: STET1 | S8: 0.283 | T8: MJ ethanol/MJ straw
A9: 5 | B9: Fermentation of Lignocellulosic Materials to Ethanol | C9: Advanced ethanol | D9: 0.182 | E9: 0.64488392 | F9: =D9*E9 -> 0.11736887 | I9: 0.41 | J9: =I9/O3*O27 -> 0.26118519 | M9: Butanol | N9: 0.78819146 | O9: 33 | R9: STET1 | S9: =S8/26.8*17.2 -> 0.18162687 | T9: t ethanol/t straw
C10: ATJ-SPK | D10: =D11*D9 -> 0.1092 | E10: 0.64488392 | F10: =D10*E10 -> 0.070421324 | I10: =I9*0.4 -> 0.164 | M10: Otto | N10: 1.0270374 | O10: 43 | Q10: 7 | R10: OWGC21 | S10: 0.462 | T10: MJ raw gas/MJ manure
A11: 6 | B11: ATJ / MTJ | C11: ATJ-SPK | D11: 0.6 | E11: 1.0270374 | F11: =D11*E11 -> 0.61622241 | G11: several sources, see Doris notes | I11: 0.4 | J11: =I11/O19*O3 -> 0.25116279 | M11: Biodiesel | N11: 0.88372982 | O11: 37 | R11: OWGC21 | S11: 0.97 | T11: MJ biomethane/MJ raw gas
A12: 7 | B12: Biomethane from Anaerobic Digestion | C12: Biomethane | D12: 0.28 | E12: 1.1951849 | F12: =D12*E12 -> 0.33465176 | G12: using a combination of straw and manure as feedstock according to availability | I12: 1 | J12: =I12/O16*O30 -> 0.36 | M12: FT-Diesel | N12: 1.0509219 | O12: 44 | R12: OWGC21 | S12: =S10*S11/46.1*12 -> 0.11665249 | T12: t biomethane/t manure
C13: Biomethane | D13: =D12 -> 0.28 | E13: 1.1951849 | F13: =D13*E13 -> 0.33465176 | M13: HVO | N13: 1.0509219 | O13: 44 | Q13: 7 | R13: OWCG5 | S13: 1.3978 | T13: MJ raw gas/MJ crop
A14: 8a | B14: Gasification and Methanolysis | C14: Methanol | D14: 0.48693467 | E14: 0.47769179 | F14: =D14*E14 -> 0.2326047 | I14: 0.58 | J14: =I14/O5*O29 -> 0.551 | M14: PPO | N14: 0.88372982 | O14: 37 | R14: OWCG5 | S14: 0.97 | T14: MJ biomethane/MJ raw gas
A15: 8b | B15: Methane reforming and Methanolysis | C15: Methanol | D15: 1.6886231 | E15: 0.47769179 | F15: =D15*E15 -> 0.8066414 | M15: Diesel | N15: 1.0270374 | O15: 43 | R15: OWCG5 | S15: =S13*S14/46.1*18 -> 0.52940538 | T15: t biomethane/t crop
A16: 8c | B16: Methanolysis from CO2 and H2 | C16: e-Methanol | D16: 0.67451351 | E16: 0.47769179 | F16: =D16*E16 -> 0.32220957 | M16: Biomethane | N16: 1.1951849 | O16: 50 | Q16: 7 | R16: combined | S16: =(67*S15+102*S12)/(67+102) -> 0.28028825 | T16: t biomethane/t combined feedstock
A17: 8d | B17: Methanol from pulping | C17: Methanol | D17: 0.01 | E17: 0.47769179 | F17: =D17*E17 -> 0.0047769179 | G17: 10 kg of methanol per 1 t of pulp | M17: Natural Gas / CNG | N17: 1.1951849 | O17: 50 | Q17: 8a | R17: WMD | S17: 0.51 | T17: efficiency, assumed it is MJ methanol/MJ wood
A18: 9a | B18: Gasification and Methanation | C18: Methane | D18: 0.27366594 | E18: 1.1951849 | F18: =D18*E18 -> 0.32708139 | I18: 0.71 | J18: =I18/O16*O29 -> 0.2698 | M18: Natural Gas / LNG | O18: 50 | R18: WMD | S18: 19.9 | T18: LHV methanol MJ/kg
C19: Methane | D19: 0.27366594 | E19: 1.1951849 | F19: =D19*E19 -> 0.32708139 | M19: ATJ | N19: 1.0270374 | O19: 43 | R19: WMD | S19: 19 | T19: LHV wood MJ/kg
A20: 9b | B20: Methanation from CO2 and H2 | C20: e-Methane | D20: 0.36363636 | E20: 1.1951849 | F20: =D20*E20 -> 0.43461268 | M20: FT-SPK | O20: 43 | R20: WMD | S20: =S17/S18*S19 -> 0.48693467 | T20: t methanol/t wood
C21: e-Methane | D21: 0.36363636 | E21: 1.1951849 | F21: =D21*E21 -> 0.43461268 | M21: HTL biocrude | N21: 0.83596064 | O21: 35 | Q21: 8b | R21: GRME | S21: 0.683 | T21: efficiency, assumed it is MJ methanol/MJ methane
A22: 10 | B22: Gasification to Hydrogen | C22: Hydrogen | D22: 0.26 | E22: 2.8661508 | F22: =D22*E22 -> 0.7451992 | M22: pyrolysis oil | N22: 0.40603802 | O22: 17 | R22: GRME | S22: 19.9 | T22: LHV methanol MJ/kg
A23: 11a | B23: Gasification and FT-Synthesis | C23: FT-diesel | D23: 0.19475 | E23: 1.0509219 | F23: =D23*E23 -> 0.20466705 | I23: 0.4 | J23: =I23/O12*O29 -> 0.17272727 | R23: GRME | S23: 49.2 | T23: LHV methane MJ/kg
C24: FT-SPK | D24: =D23/2 -> 0.097375 | E24: 1.0270374 | F24: =D24*E24 -> 0.10000776 | G24: 50% share of FT-diesel amount assumed | M24: hydrogen | N24: =120/41.868 -> 2.8661508 | R24: GRME | S24: =S21/S22*S23 -> 1.6886231 | T24: t methanol/t methane
A25: 11b | B25: FT-Synthesis from CO2 and H2 | C25: e-FT-diesel | D25: 0.18 | E25: 1.0509219 | F25: =D25*E25 -> 0.18916595 | G25: average of 3 different sources (0,32 / 0,15 / 0,07) | Q25: 8c | R25: REME1 | S25: 0.0745 | T25: kg CO2/MJ methanol
C26: e-FT-SPK | D26: =D25/2 -> 0.09 | E26: 1.0270374 | F26: =D26*E26 -> 0.092433362 | G26: 50% share of FT-diesel amount assumed | M26: Feedstock | O26: LHV [MJ/kg] | R26: REME1 | S26: =1/S25/19.9 -> 0.67451351 | T26: t methanol/t CO2
A27: 12 | B27: Gas Fermentation to Ethanol | C27: Ethanol | D27: =1/2.12 -> 0.47169811 | E27: 0.64488392 | F27: =D27*E27 -> 0.30419053 | G27: Lanzatech figures | M27: Straw | O27: 17.2 | Q27: 9a | R27: WWCG2 | S27: 0.664 | T27: efficiency, assumed it is MJ methane/MJ wood
C28: ATJ-SPK | D28: =D11*D27 -> 0.28301887 | E28: 0.64488392 | F28: =D28*E28 -> 0.18251432 | M28: Manure | O28: 12 | R28: WWCG2 | S28: 46.1 | T28: LHV methane MJ/kg
A29: 13a | B29: Pyrolysis and Co-processing in Refinery | C29: Gasoline+Diesel | D29: 0.27123986 | E29: 1 | F29: =D29*E29 -> 0.27123986 | G29: the efficiency is already for diesel | I29: 0.65 | J29: =I29/O15*O27 -> 0.26 | M29: Wood | O29: 19 | R29: WWCG2 | S29: 19 | T29: LHV wood MJ/kg
C30: Bio-kerosene | D30: =D29/3 -> 0.090413287 | E30: 1 | F30: =D30*E30 -> 0.090413287 | G30: 33% share of overall amount assumed | M30: Crop (wheat, barley) | O30: 18 | R30: WWCG2 | S30: =S27/S28*S29 -> 0.27366594 | T30: t methane/t wood
A31: 13b | B31: Pyrolysis (and Thermo-Catalytic Reforming) and Upgrading (HDO) | C31: Gasoline+Diesel | D31: 0.27123986 | E31: 1 | F31: =D31*E31 -> 0.27123986 | G31: the efficiency is already for diesel | I31: 0.54 | Q31: 9b | R31: RECG1 | S31: 0.055 | T31: kg CO2/MJ methane
C32: Bio-heavy fuel oil | D32: =D31/3 -> 0.090413287 | E32: 1 | F32: =D32*E32 -> 0.090413287 | G32: 33% share of overall amount assumed | R32: RECG1 | S32: 50 | T32: LHV methane MJ/kg
A33: 14 | B33: Hydrothermal Liquefaction and Upgrading in Refinery (FCC or HDO) | C33: Diesel | D33: 0.36986079 | E33: 1 | F33: =D33*E33 -> 0.36986079 | G33: the efficiency is already for diesel | I33: 0.7 | J33: =I33/O21*O27 -> 0.344 | R33: RECG1 | S33: =1/S31/S32 -> 0.36363636 | T33: t methane/t CO2
C34: Bio-kerosene | D34: =D33/3 -> 0.12328693 | E34: 1.0270374 | F34: =D34*E34 -> 0.12662028 | G34: 33% kerosene, 67% HFO | M34: possible error in JEC_WTT_v5 | Q34: 11a | R34: WSD1 | S34: 0.451 | T34: efficiency, assumed it is MJ diesel/MJ wood | U34: based on König et al 2015: https://www.sciencedirect.com/science/article/abs/pii/S0360544215011767?via%3Dihub
C35: Bio-heavy fuel oil | D35: =D33/3*2 -> 0.24657386 | E35: 1 | F35: =D35*E35 -> 0.24657386 | G35: 33% kerosene, 67% HFO | L35: 11b | M35: RESD2 | N35: 0.3408 | O35: ass: kg CO2/MJ diesel | R35: WSD1 | S35: 44 | T35: LHV diesel MJ/kg
M36: RESD2 | N36: 44 | O36: LHV diesel MJ/kg | R36: WSD1 | S36: 19 | T36: LHV wood MJ/kg
M37: RESD2 | R37: WSD1 | S37: =S34/S35*S36 -> 0.19475 | T37: t diesel/t wood
M38: RESD2 | N38: =1/N35/N36 -> 0.066688007 | O38: t diesel/t CO2 | Q38: 11b | R38: RESD2 | S38: 0.3408 | T38: MJ CO2/MJ diesel
R39: RESD2 | S39: 44 | T39: LHV diesel MJ/kg
R40: RESD2 | T40: LHV CO2 MJ/kg
...

Sheet Conversion factors selected IV 
G1: Conversion factors | I1: LHV feedstock | J1: LHV fuel
A2: Value chain | B2: VC description | C2: Feedstock | D2: Feedstock | E2: Pathway | F2: comments/ questions | G2: product yield [t product / t feedstock] | H2: MJfuel/ MJfeedstock | I2: [MJ/kg] | J2: [MJ/kg] | K2: toe/t | L2: combined factor = yield [toe product / t feedstock] | M2: Correction | O2: t/toe
A3: 1 | C3: FAME
D4: Oil crops abandoned, degraded, intercropping | F4: assumed to be the same as UCO | G4: =H4/J4*I4 -> 0.994 | H4: =([1]ROFA!$E$111+[1]SOFA!$E$107+[1]SYFA!$E$133)/3 -> 0.99937297 | I4: =[2]Props!$C$47 -> 37 | J4: =[2]Props!$C$48 -> 37.2 | K4: 0.88372982 | L4: =G4*K4 -> 0.87842744 | O4: =1/K4 -> 1.1315676
D5: UCO, brown grease, animal fat | E5: WOFA in Biodiesels | G5: =H5/J5*I5 -> 0.95978351 | H5: ='[2]Bio-processes'!$E$915 -> 0.96497153 | I5: =[2]Props!$C$47 -> 37 | J5: =[2]Props!$C$48 -> 37.2 | K5: 0.88372982 | L5: =G5*K5 -> 0.84818931 | O5: =1/K5 -> 1.1315676
A6: 2 | C6: HVO
D7: Oil crops abandoned, degraded, intercropping | E7: HVO in Biodiesels | G7: =H7/J7*I7/2 -> 0.42350471 | H7: =([1]HVO!$E$94+[1]HVO!$E$103+[1]HVO!$E$109+[1]HVO!$E$118)/4 -> 1.0072545 | I7: =[2]Props!$C$47 -> 37 | J7: =[2]Props!$C$50 -> 44 | K7: ='conversion factors'!$E$4 -> 1.0509219 | L7: =G7*K7 -> 0.4450704 | O7: =1/K7 -> 0.95154545
D8: UCO, brown grease, animal fat | E8: HVO in Biodiesels | F8: =G8*2 -> 0.87367178 | G8: =H8/J8*I8/2 -> 0.43683589 | H8: ='[2]Bio-processes'!E$888 -> 1.038961 | I8: =[2]Props!$C$47 -> 37 | J8: =[2]Props!$C$50 -> 44 | K8: ='conversion factors'!$E$4 -> 1.0509219 | L8: =G8*K8 -> 0.45908042 | O8: =1/K8 -> 0.95154545
D9: Tall oil | K9: ='conversion factors'!$E$4 -> 1.0509219 | L9: 0.69 | M9: (taken from new excel file from Dina: "additial conversion factors") | O9: =1/K9 -> 0.95154545
D10: Intermediate Bioenergy carriers (biocrude, FPBO) | G10: =H10/J10*I10/2 -> 0.15387273 | H10: 0.78 | I10: 17.36 | J10: =[2]Props!$C$50 -> 44 | K10: ='conversion factors'!$E$4 -> 1.0509219 | L10: =G10*K10 -> 0.16170823 | O10: =1/K10 -> 0.95154545
C11: HEFA
D12: Oil crops abandoned, degraded, intercropping | G12: =H12/J12*I12/2 -> 0.42350471 | H12: =([1]HVO!$E$94+[1]HVO!$E$103+[1]HVO!$E$109+[1]HVO!$E$118)/4 -> 1.0072545 | I12: =[2]Props!$C$47 -> 37 | J12: =[2]Props!$C$50 -> 44 | K12: ='conversion factors'!$E$5 -> 1.0270374 | L12: =G12*K12 -> 0.43495516 | O12: =1/K12 -> 0.97367442
D13: UCO, brown grease, animal fat | G13: =H13/J13*I13/2 -> 0.43683589 | H13: ='[2]Bio-processes'!E$888 -> 1.038961 | I13: =[2]Props!$C$47 -> 37 | J13: =[2]Props!$C$50 -> 44 | K13: ='conversion factors'!$E$5 -> 1.0270374 | L13: =G13*K13 -> 0.44864678 | O13: =1/K13 -> 0.97367442
D14: Tall oil | J14: =[2]Props!$C$50 -> 44 | K14: ='conversion factors'!$E$5 -> 1.0270374 | L14: 0.68 | M14: (taken from new excel file from Dina: "additial conversion factors") | O14: =1/K14 -> 0.97367442
D15: Intermediate Bioenergy carriers (biocrude, FPBO) | G15: =H15/J15*I15/2 -> 0.15387273 | H15: 0.78 | I15: 17.36 | J15: =[2]Props!$C$50 -> 44 | K15: ='conversion factors'!$E$5 -> 1.0270374 | L15: =G15*K15 -> 0.15803304 | O15: =1/K15 -> 0.97367442
A16: 5 | B16: Fermentation of Lignocellulosic Materials to Ethanol | C16: Advanced ethanol
D17: Straw | G17: =H17/J17*I17 -> 0.18050496 | H17: ='[2]Bio-processes'!$E$567 -> 0.28335081 | I17: =[2]Props!$C$75 -> 17.2 | J17: 27 | K17: 0.64488392 | L17: =G17*K17 -> 0.11640475 | O17: =1/K17 -> 1.5506667
D18: Lignocrops abandoned degraded | G18: =H18/J18*I18 -> 0.18050496 | H18: ='[2]Bio-processes'!$E$567 -> 0.28335081 | I18: =[2]Props!$C$75 -> 17.2 | J18: 27 | K18: 0.64488392 | L18: =G18*K18 -> 0.11640475 | O18: =1/K18 -> 1.5506667
D19: Lignocrops inter & cover cropping | G19: =H19/J19*I19 -> 0.18050496 | H19: ='[2]Bio-processes'!$E$567 -> 0.28335081 | I19: =[2]Props!$C$75 -> 17.2 | J19: 27 | K19: 0.64488392 | L19: =G19*K19 -> 0.11640475 | O19: =1/K19 -> 1.5506667
D20: Secondary forest residues | G20: =H20/J20*I20 -> 0.23616906 | H20: ='[2]Bio-processes'!$E$541 -> 0.33560866 | I20: =[2]Props!$C$64 -> 19 | J20: 27 | K20: 0.64488392 | L20: =G20*K20 -> 0.15230163 | O20: =1/K20 -> 1.5506667
A21: 5 | B21: Fermentation of Lignocellulosic Materials to Ethanol | C21: ATJ-SPK
D22: Straw | E22: STET1 in Ethanol | F22: Corrected; see Mail Dina 28.07. | G22: =H22/J22*I22*0.47 -> 0.053146356 | H22: ='[2]Bio-processes'!$E$567 -> 0.28335081 | I22: =[2]Props!$C$75 -> 17.2 | J22: 43.1 | K22: 0.64488392 | L22: =G22*K22 -> 0.03427323 | O22: =1/K22 -> 1.5506667
D23: Lignocrops abandoned degraded | E23: STET1 in Ethanol | F23: Advanced ethanol value * D11 from original conversion factor sheet (IVC 6 value) | G23: =H23/J23*I23*0.47 -> 0.053146356 | H23: ='[2]Bio-processes'!$E$567 -> 0.28335081 | I23: =[2]Props!$C$75 -> 17.2 | J23: 43.1 | K23: 0.64488392 | L23: =G23*K23 -> 0.03427323 | O23: =1/K23 -> 1.5506667
D24: Lignocrops inter & cover cropping | E24: STET1 in Ethanol | F24: Advanced ethanol value * D11 from original conversion factor sheet (IVC 6 value) | G24: =H24/J24*I24*0.47 -> 0.053146356 | H24: ='[2]Bio-processes'!$E$567 -> 0.28335081 | I24: =[2]Props!$C$75 -> 17.2 | J24: 43.1 | K24: 0.64488392 | L24: =G24*K24 -> 0.03427323 | O24: =1/K24 -> 1.5506667
D25: Secondary forest residues | E25: WW WFET1 in Ethanol | G25: =H25/J25*I25*0.47 -> 0.069535623 | H25: ='[2]Bio-processes'!$E$541 -> 0.33560866 | I25: =[2]Props!$C$64 -> 19 | J25: 43.1 | K25: 0.64488392 | L25: =G25*K25 -> 0.044842405 | O25: =1/K25 -> 1.5506667
A26: 6 | C26: ATJ-SPK
D27: Intermediate Bioenergy carrier (ethanol, methanol) | F27: directly taken from original "conversion factor" sheet | G27: 0.47 | J27: 43.1 | K27: ='conversion factors'!E11 -> 1.0270374 | L27: ='conversion factors'!F11 -> 0.61622241 | O27: =1/K27 -> 0.97367442
A28: 7 | B28: Biomethane from Anaerobic Digestion | C28: Biomethane (road) | P28: for maritime/ aviation:
D29: Prunings & damaged crops (olive stones excluded) | E29: assumed to be the same as straw | F29: for all of these: unit: MJ/MJ(crops)*MJ/MJ/(Raw gas) | G29: =H29/J29*I29 -> 0.50565326 | H29: =[3]OWCG5!$E$57*[3]OWCG5!$E$61 -> 1.3558848 | I29: =[2]Props!$C$75 -> 17.2 | J29: =[2]Props!$C$16 -> 46.12097 | K29: ='conversion factors'!$E$12 -> 1.1951849 | L29: =G29*K29 -> 0.60434912 | O29: =1/K29 -> 0.83669065
D30: Lignocrops abandoned degraded | E30: assumed to be the same as straw | G30: =H30/J30*I30 -> 0.50565326 | H30: =[3]OWCG5!$E$57*[3]OWCG5!$E$61 -> 1.3558848 | I30: =[2]Props!$C$75 -> 17.2 | J30: =[2]Props!$C$16 -> 46.12097 | K30: ='conversion factors'!$E$12 -> 1.1951849 | L30: =G30*K30 -> 0.60434912 | O30: =1/K30 -> 0.83669065
D31: Lignocrops inter & cover cropping | E31: assumed to be the same as straw | G31: =H31/J31*I31 -> 0.50565326 | H31: =[3]OWCG5!$E$57*[3]OWCG5!$E$61 -> 1.3558848 | I31: =[2]Props!$C$75 -> 17.2 | J31: =[2]Props!$C$16 -> 46.12097 | K31: ='conversion factors'!$E$12 -> 1.1951849 | L31: =G31*K31 -> 0.60434912 | O31: =1/K31 -> 0.83669065
D32: Agroprocessing residues | E32: assumed to be the same as straw | G32: =H32/J32*I32 -> 0.50565326 | H32: =[3]OWCG5!$E$57*[3]OWCG5!$E$61 -> 1.3558848 | I32: =[2]Props!$C$75 -> 17.2 | J32: =[2]Props!$C$16 -> 46.12097 | K32: ='conversion factors'!$E$12 -> 1.1951849 | L32: =G32*K32 -> 0.60434912 | O32: =1/K32 -> 0.83669065
D33: Straw | E33: OVCG5 | G33: =H33/J33*I33 -> 0.50565326 | H33: =[3]OWCG5!$E$57*[3]OWCG5!$E$61 -> 1.3558848 | I33: =[2]Props!$C$75 -> 17.2 | J33: =[2]Props!$C$16 -> 46.12097 | K33: ='conversion factors'!$E$12 -> 1.1951849 | L33: =G33*K33 -> 0.60434912 | O33: =1/K33 -> 0.83669065
D34: Manure | E34: OWGC21 | G34: =H34/J34*I34 -> 0.11659946 | H34: =[3]OWCG2!$E$56*[3]OWCG2!$E$70 -> 0.44814 | I34: =[2]Props!$C$89 -> 12 | J34: =[2]Props!$C$16 -> 46.12097 | K34: ='conversion factors'!$E$12 -> 1.1951849 | L34: =G34*K34 -> 0.1393579 | O34: =1/K34 -> 0.83669065
D35: Sewage sludge | E35: OWLCG3 | G35: =H35/J35*I35 -> 0.11659946 | H35: =[3]OWCG3!$E$52*[3]OWCG3!$E$60 -> 0.44814 | I35: 12 | J35: =[2]Props!$C$16 -> 46.12097 | K35: ='conversion factors'!$E$12 -> 1.1951849 | L35: =G35*K35 -> 0.1393579 | O35: =1/K35 -> 0.83669065
D36: Biowastes (post consumer woods excluded) | E36: OWCG1 | G36: =H36/J36*I36 -> 0.18593291 | H36: =[3]OWCG1!$E$52*[3]OWCG1!$E$62 -> 0.6860325 | I36: 12.5 | J36: =[2]Props!$C$16 -> 46.12097 | K36: ='conversion factors'!$E$12 -> 1.1951849 | L36: =G36*K36 -> 0.2222242 | O36: =1/K36 -> 0.83669065
D37: Intermediate Bioenergy carrier (crude glycerine) | L37: 0.275
A38: 8a | B38: Gasification and Methanol Synthesis | C38: Methanol
D39: Straw | G39: =H39/J39*I39 -> 0.44129562 | H39: =[4]Wxxx!$E$180 -> 0.51056877 | I39: =[2]Props!$C$75 -> 17.2 | J39: 19.9 | K39: 0.47769179 | L39: =G39*K39 -> 0.2108033 | O39: =1/K39 -> 2.0934
D40: Prunnings & damaged crops | E40: ??? | G40: =H40/J40*I40 -> 0.44129562 | H40: =[4]Wxxx!$E$180 -> 0.51056877 | I40: =[2]Props!$C$75 -> 17.2 | J40: 19.9 | K40: 0.47769179 | L40: =G40*K40 -> 0.2108033 | O40: =1/K40 -> 2.0934
...

Sheet IVC Emission Allocation
A1: EU IVC Emission Intensity Allocation by Product and Transport Sector
A2: Weights use EU feedstock availability in columns N, Q and X multiplied by feedstock share in AE. Column H is the final recommended emission intensity. IVC 1 and IVC 2 are separated by actual feedstock pathway; FPBO and biocrude are combined, while HVO and HEFA remain sector-specific.
A4: Region | B4: IVC No. | C4: IVC Name | D4: Resulting Product | E4: Sector Destination | F4: N-weighted EI | G4: Q-weighted EI | H4: Recommended EI (final) | I4: X-weighted EI | J4: N x AE Total | K4: Q x AE Total | L4: X x AE Total | M4: Combined Weight | N4: Basis
A5: EU | B5: 1 | C5: Transesterification | D5: FAME | E5: Road-bio | F5: {=IFERROR(SUMPRODUCT(($A$34:$A$135=$A5)*($B$34:$B$135=$B5)*($C$34:$C$135=$D5)*($D$34:$D$135=$E5)*(--ISNUMBER(SEARCH("UCO",$F$34:$F$135)))*$H$34:$H$135*$M$34:$M$135)/SUMPRODUCT(($A$34:$A$135=$A5)*($B$34:$B$135=$B5)*($C$34:$C$135=$D5)*($D$34:$D$135=$E5)*(--ISNUMBER(SEARCH("UCO",$F$34:$F$135)))*$H$34:$H$135),0)} -> 12.15 | G5: {=IFERROR(SUMPRODUCT(($A$34:$A$135=$A5)*($B$34:$B$135=$B5)*($C$34:$C$135=$D5)*($D$34:$D$135=$E5)*(--ISNUMBER(SEARCH("UCO",$F$34:$F$135)))*$I$34:$I$135*$M$34:$M$135)/SUMPRODUCT(($A$34:$A$135=$A5)*($B$34:$B$135=$B5)*($C$34:$C$135=$D5)*($D$34:$D$135=$E5)*(--ISNUMBER(SEARCH("UCO",$F$34:$F$135)))*$I$34:$I$135),0)} -> 12.15 | H5: {=IFERROR(SUMPRODUCT(($A$34:$A$135=$A5)*($B$34:$B$135=$B5)*($C$34:$C$135=$D5)*($D$34:$D$135=$E5)*(--ISNUMBER(SEARCH("UCO",$F$34:$F$135)))*$K$34:$K$135*$M$34:$M$135)/SUMPRODUCT(($A$34:$A$135=$A5)*($B$34:$B$135=$B5)*($C$34:$C$135=$D5)*($D$34:$D$135=$E5)*(--ISNUMBER(SEARCH("UCO",$F$34:$F$135)))*$K$34:$K$135),0)} -> 12.15 | I5: {=IFERROR(SUMPRODUCT(($A$34:$A$135=$A5)*($B$34:$B$135=$B5)*($C$34:$C$135=$D5)*($D$34:$D$135=$E5)*(--ISNUMBER(SEARCH("UCO",$F$34:$F$135)))*$J$34:$J$135*$M$34:$M$135)/SUMPRODUCT(($A$34:$A$135=$A5)*($B$34:$B$135=$B5)*($C$34:$C$135=$D5)*($D$34:$D$135=$E5)*(--ISNUMBER(SEARCH("UCO",$F$34:$F$135)))*$J$34:$J$135),0)} -> 12.15 | J5: {=SUMPRODUCT(($A$34:$A$135=$A5)*($B$34:$B$135=$B5)*($C$34:$C$135=$D5)*($D$34:$D$135=$E5)*(--ISNUMBER(SEARCH("UCO",$F$34:$F$135)))*$H$34:$H$135)} -> 1.741836 | K5: {=SUMPRODUCT(($A$34:$A$135=$A5)*($B$34:$B$135=$B5)*($C$34:$C$135=$D5)*($D$34:$D$135=$E5)*(--ISNUMBER(SEARCH("UCO",$F$34:$F$135)))*$I$34:$I$135)} -> 3.0212618 | L5: {=SUMPRODUCT(($A$34:$A$135=$A5)*($B$34:$B$135=$B5)*($C$34:$C$135=$D5)*($D$34:$D$135=$E5)*(--ISNUMBER(SEARCH("UCO",$F$34:$F$135)))*$J$34:$J$135)} -> 4.8006866 | M5: {=SUMPRODUCT(($A$34:$A$135=$A5)*($B$34:$B$135=$B5)*($C$34:$C$135=$D5)*($D$34:$D$135=$E5)*(--ISNUMBER(SEARCH("UCO",$F$34:$F$135)))*$K$34:$K$135)} -> 9.5637844 | N5: Feedstock-specific pathway: UCO / animal fat
A6: EU | B6: 2 | C6: Hydrotreatment of Lipids | D6: HVO | E6: Road-bio | F6: {=IFERROR(SUMPRODUCT(($A$34:$A$135=$A6)*($B$34:$B$135=$B6)*($C$34:$C$135=$D6)*($D$34:$D$135=$E6)*(--ISNUMBER(SEARCH("UCO",$F$34:$F$135)))*$H$34:$H$135*$M$34:$M$135)/SUMPRODUCT(($A$34:$A$135=$A6)*($B$34:$B$135=$B6)*($C$34:$C$135=$D6)*($D$34:$D$135=$E6)*(--ISNUMBER(SEARCH("UCO",$F$34:$F$135)))*$H$34:$H$135),0)} -> 13.775 | G6: {=IFERROR(SUMPRODUCT(($A$34:$A$135=$A6)*($B$34:$B$135=$B6)*($C$34:$C$135=$D6)*($D$34:$D$135=$E6)*(--ISNUMBER(SEARCH("UCO",$F$34:$F$135)))*$I$34:$I$135*$M$34:$M$135)/SUMPRODUCT(($A$34:$A$135=$A6)*($B$34:$B$135=$B6)*($C$34:$C$135=$D6)*($D$34:$D$135=$E6)*(--ISNUMBER(SEARCH("UCO",$F$34:$F$135)))*$I$34:$I$135),0)} -> 13.775 | H6: {=IFERROR(SUMPRODUCT(($A$34:$A$135=$A6)*($B$34:$B$135=$B6)*($C$34:$C$135=$D6)*($D$34:$D$135=$E6)*(--ISNUMBER(SEARCH("UCO",$F$34:$F$135)))*$K$34:$K$135*$M$34:$M$135)/SUMPRODUCT(($A$34:$A$135=$A6)*($B$34:$B$135=$B6)*($C$34:$C$135=$D6)*($D$34:$D$135=$E6)*(--ISNUMBER(SEARCH("UCO",$F$34:$F$135)))*$K$34:$K$135),0)} -> 13.775 | I6: {=IFERROR(SUMPRODUCT(($A$34:$A$135=$A6)*($B$34:$B$135=$B6)*($C$34:$C$135=$D6)*($D$34:$D$135=$E6)*(--ISNUMBER(SEARCH("UCO",$F$34:$F$135)))*$J$34:$J$135*$M$34:$M$135)/SUMPRODUCT(($A$34:$A$135=$A6)*($B$34:$B$135=$B6)*($C$34:$C$135=$D6)*($D$34:$D$135=$E6)*(--ISNUMBER(SEARCH("UCO",$F$34:$F$135)))*$J$34:$J$135),0)} -> 13.775 | J6: {=SUMPRODUCT(($A$34:$A$135=$A6)*($B$34:$B$135=$B6)*($C$34:$C$135=$D6)*($D$34:$D$135=$E6)*(--ISNUMBER(SEARCH("UCO",$F$34:$F$135)))*$H$34:$H$135)} -> 0.87091801 | K6: {=SUMPRODUCT(($A$34:$A$135=$A6)*($B$34:$B$135=$B6)*($C$34:$C$135=$D6)*($D$34:$D$135=$E6)*(--ISNUMBER(SEARCH("UCO",$F$34:$F$135)))*$I$34:$I$135)} -> 1.5106309 | L6: {=SUMPRODUCT(($A$34:$A$135=$A6)*($B$34:$B$135=$B6)*($C$34:$C$135=$D6)*($D$34:$D$135=$E6)*(--ISNUMBER(SEARCH("UCO",$F$34:$F$135)))*$J$34:$J$135)} -> 2.4003433 | M6: {=SUMPRODUCT(($A$34:$A$135=$A6)*($B$34:$B$135=$B6)*($C$34:$C$135=$D6)*($D$34:$D$135=$E6)*(--ISNUMBER(SEARCH("UCO",$F$34:$F$135)))*$K$34:$K$135)} -> 4.7818922 | N6: Feedstock-specific pathway: UCO / animal fat
A7: EU | B7: 2 | C7: Hydrotreatment of Lipids | D7: HVO | E7: Road-bio | F7: {=IFERROR(SUMPRODUCT(($A$34:$A$135=$A7)*($B$34:$B$135=$B7)*($C$34:$C$135=$D7)*($D$34:$D$135=$E7)*(--((ISNUMBER(SEARCH("Tall oil",$F$34:$F$135))+ISNUMBER(SEARCH("POME",$F$34:$F$135)))>0))*$H$34:$H$135*$M$34:$M$135)/SUMPRODUCT(($A$34:$A$135=$A7)*($B$34:$B$135=$B7)*($C$34:$C$135=$D7)*($D$34:$D$135=$E7)*(--((ISNUMBER(SEARCH("Tall oil",$F$34:$F$135))+ISNUMBER(SEARCH("POME",$F$34:$F$135)))>0))*$H$34:$H$135),0)} -> 10.8 | G7: {=IFERROR(SUMPRODUCT(($A$34:$A$135=$A7)*($B$34:$B$135=$B7)*($C$34:$C$135=$D7)*($D$34:$D$135=$E7)*(--((ISNUMBER(SEARCH("Tall oil",$F$34:$F$135))+ISNUMBER(SEARCH("POME",$F$34:$F$135)))>0))*$I$34:$I$135*$M$34:$M$135)/SUMPRODUCT(($A$34:$A$135=$A7)*($B$34:$B$135=$B7)*($C$34:$C$135=$D7)*($D$34:$D$135=$E7)*(--((ISNUMBER(SEARCH("Tall oil",$F$34:$F$135))+ISNUMBER(SEARCH("POME",$F$34:$F$135)))>0))*$I$34:$I$135),0)} -> 10.8 | H7: {=IFERROR(SUMPRODUCT(($A$34:$A$135=$A7)*($B$34:$B$135=$B7)*($C$34:$C$135=$D7)*($D$34:$D$135=$E7)*(--((ISNUMBER(SEARCH("Tall oil",$F$34:$F$135))+ISNUMBER(SEARCH("POME",$F$34:$F$135)))>0))*$K$34:$K$135*$M$34:$M$135)/SUMPRODUCT(($A$34:$A$135=$A7)*($B$34:$B$135=$B7)*($C$34:$C$135=$D7)*($D$34:$D$135=$E7)*(--((ISNUMBER(SEARCH("Tall oil",$F$34:$F$135))+ISNUMBER(SEARCH("POME",$F$34:$F$135)))>0))*$K$34:$K$135),0)} -> 10.8 | I7: {=IFERROR(SUMPRODUCT(($A$34:$A$135=$A7)*($B$34:$B$135=$B7)*($C$34:$C$135=$D7)*($D$34:$D$135=$E7)*(--((ISNUMBER(SEARCH("Tall oil",$F$34:$F$135))+ISNUMBER(SEARCH("POME",$F$34:$F$135)))>0))*$J$34:$J$135*$M$34:$M$135)/SUMPRODUCT(($A$34:$A$135=$A7)*($B$34:$B$135=$B7)*($C$34:$C$135=$D7)*($D$34:$D$135=$E7)*(--((ISNUMBER(SEARCH("Tall oil",$F$34:$F$135))+ISNUMBER(SEARCH("POME",$F$34:$F$135)))>0))*$J$34:$J$135),0)} -> 10.8 | J7: {=SUMPRODUCT(($A$34:$A$135=$A7)*($B$34:$B$135=$B7)*($C$34:$C$135=$D7)*($D$34:$D$135=$E7)*(--((ISNUMBER(SEARCH("Tall oil",$F$34:$F$135))+ISNUMBER(SEARCH("POME",$F$34:$F$135)))>0))*$H$34:$H$135)} -> 0.2 | K7: {=SUMPRODUCT(($A$34:$A$135=$A7)*($B$34:$B$135=$B7)*($C$34:$C$135=$D7)*($D$34:$D$135=$E7)*(--((ISNUMBER(SEARCH("Tall oil",$F$34:$F$135))+ISNUMBER(SEARCH("POME",$F$34:$F$135)))>0))*$I$34:$I$135)} -> 0.4 | L7: {=SUMPRODUCT(($A$34:$A$135=$A7)*($B$34:$B$135=$B7)*($C$34:$C$135=$D7)*($D$34:$D$135=$E7)*(--((ISNUMBER(SEARCH("Tall oil",$F$34:$F$135))+ISNUMBER(SEARCH("POME",$F$34:$F$135)))>0))*$J$34:$J$135)} -> 0.7 | M7: {=SUMPRODUCT(($A$34:$A$135=$A7)*($B$34:$B$135=$B7)*($C$34:$C$135=$D7)*($D$34:$D$135=$E7)*(--((ISNUMBER(SEARCH("Tall oil",$F$34:$F$135))+ISNUMBER(SEARCH("POME",$F$34:$F$135)))>0))*$K$34:$K$135)} -> 1.3 | N7: Feedstock-specific pathway: POME / tall-oil proxy
A8: EU | B8: 2 | C8: Hydrotreatment of Lipids | D8: HVO | E8: Road-bio | F8: {=IFERROR(SUMPRODUCT(($A$34:$A$135=$A8)*($B$34:$B$135=$B8)*($C$34:$C$135=$D8)*($D$34:$D$135=$E8)*(--((ISNUMBER(SEARCH("FPBO",$F$34:$F$135))+ISNUMBER(SEARCH("biocrude",$F$34:$F$135)))>0))*$H$34:$H$135*$M$34:$M$135)/SUMPRODUCT(($A$34:$A$135=$A8)*($B$34:$B$135=$B8)*($C$34:$C$135=$D8)*($D$34:$D$135=$E8)*(--((ISNUMBER(SEARCH("FPBO",$F$34:$F$135))+ISNUMBER(SEARCH("biocrude",$F$34:$F$135)))>0))*$H$34:$H$135),0)} -> 13.775 | G8: {=IFERROR(SUMPRODUCT(($A$34:$A$135=$A8)*($B$34:$B$135=$B8)*($C$34:$C$135=$D8)*($D$34:$D$135=$E8)*(--((ISNUMBER(SEARCH("FPBO",$F$34:$F$135))+ISNUMBER(SEARCH("biocrude",$F$34:$F$135)))>0))*$I$34:$I$135*$M$34:$M$135)/SUMPRODUCT(($A$34:$A$135=$A8)*($B$34:$B$135=$B8)*($C$34:$C$135=$D8)*($D$34:$D$135=$E8)*(--((ISNUMBER(SEARCH("FPBO",$F$34:$F$135))+ISNUMBER(SEARCH("biocrude",$F$34:$F$135)))>0))*$I$34:$I$135),0)} -> 13.775 | H8: {=IFERROR(SUMPRODUCT(($A$34:$A$135=$A8)*($B$34:$B$135=$B8)*($C$34:$C$135=$D8)*($D$34:$D$135=$E8)*(--((ISNUMBER(SEARCH("FPBO",$F$34:$F$135))+ISNUMBER(SEARCH("biocrude",$F$34:$F$135)))>0))*$K$34:$K$135*$M$34:$M$135)/SUMPRODUCT(($A$34:$A$135=$A8)*($B$34:$B$135=$B8)*($C$34:$C$135=$D8)*($D$34:$D$135=$E8)*(--((ISNUMBER(SEARCH("FPBO",$F$34:$F$135))+ISNUMBER(SEARCH("biocrude",$F$34:$F$135)))>0))*$K$34:$K$135),0)} -> 13.775 | I8: {=IFERROR(SUMPRODUCT(($A$34:$A$135=$A8)*($B$34:$B$135=$B8)*($C$34:$C$135=$D8)*($D$34:$D$135=$E8)*(--((ISNUMBER(SEARCH("FPBO",$F$34:$F$135))+ISNUMBER(SEARCH("biocrude",$F$34:$F$135)))>0))*$J$34:$J$135*$M$34:$M$135)/SUMPRODUCT(($A$34:$A$135=$A8)*($B$34:$B$135=$B8)*($C$34:$C$135=$D8)*($D$34:$D$135=$E8)*(--((ISNUMBER(SEARCH("FPBO",$F$34:$F$135))+ISNUMBER(SEARCH("biocrude",$F$34:$F$135)))>0))*$J$34:$J$135),0)} -> 13.775 | J8: {=SUMPRODUCT(($A$34:$A$135=$A8)*($B$34:$B$135=$B8)*($C$34:$C$135=$D8)*($D$34:$D$135=$E8)*(--((ISNUMBER(SEARCH("FPBO",$F$34:$F$135))+ISNUMBER(SEARCH("biocrude",$F$34:$F$135)))>0))*$H$34:$H$135)} -> 1.0285054 | K8: {=SUMPRODUCT(($A$34:$A$135=$A8)*($B$34:$B$135=$B8)*($C$34:$C$135=$D8)*($D$34:$D$135=$E8)*(--((ISNUMBER(SEARCH("FPBO",$F$34:$F$135))+ISNUMBER(SEARCH("biocrude",$F$34:$F$135)))>0))*$I$34:$I$135)} -> 1.3060866 | L8: {=SUMPRODUCT(($A$34:$A$135=$A8)*($B$34:$B$135=$B8)*($C$34:$C$135=$D8)*($D$34:$D$135=$E8)*(--((ISNUMBER(SEARCH("FPBO",$F$34:$F$135))+ISNUMBER(SEARCH("biocrude",$F$34:$F$135)))>0))*$J$34:$J$135)} -> 3.407654 | M8: {=SUMPRODUCT(($A$34:$A$135=$A8)*($B$34:$B$135=$B8)*($C$34:$C$135=$D8)*($D$34:$D$135=$E8)*(--((ISNUMBER(SEARCH("FPBO",$F$34:$F$135))+ISNUMBER(SEARCH("biocrude",$F$34:$F$135)))>0))*$K$34:$K$135)} -> 5.7422459 | N8: Feedstock-specific pathway: FPBO + biocrude
A9: EU | B9: 2 | C9: Hydrotreatment of Lipids | D9: HEFA / SAF | E9: Aviation-bio | F9: {=IFERROR(SUMPRODUCT(($A$34:$A$135=$A9)*($B$34:$B$135=$B9)*($C$34:$C$135=$D9)*($D$34:$D$135=$E9)*(--ISNUMBER(SEARCH("Oil crops",$F$34:$F$135)))*$H$34:$H$135*$M$34:$M$135)/SUMPRODUCT(($A$34:$A$135=$A9)*($B$34:$B$135=$B9)*($C$34:$C$135=$D9)*($D$34:$D$135=$E9)*(--ISNUMBER(SEARCH("Oil crops",$F$34:$F$135)))*$H$34:$H$135),0)} -> 26.05 | G9: {=IFERROR(SUMPRODUCT(($A$34:$A$135=$A9)*($B$34:$B$135=$B9)*($C$34:$C$135=$D9)*($D$34:$D$135=$E9)*(--ISNUMBER(SEARCH("Oil crops",$F$34:$F$135)))*$I$34:$I$135*$M$34:$M$135)/SUMPRODUCT(($A$34:$A$135=$A9)*($B$34:$B$135=$B9)*($C$34:$C$135=$D9)*($D$34:$D$135=$E9)*(--ISNUMBER(SEARCH("Oil crops",$F$34:$F$135)))*$I$34:$I$135),0)} -> 26.05 | H9: {=IFERROR(SUMPRODUCT(($A$34:$A$135=$A9)*($B$34:$B$135=$B9)*($C$34:$C$135=$D9)*($D$34:$D$135=$E9)*(--ISNUMBER(SEARCH("Oil crops",$F$34:$F$135)))*$K$34:$K$135*$M$34:$M$135)/SUMPRODUCT(($A$34:$A$135=$A9)*($B$34:$B$135=$B9)*($C$34:$C$135=$D9)*($D$34:$D$135=$E9)*(--ISNUMBER(SEARCH("Oil crops",$F$34:$F$135)))*$K$34:$K$135),0)} -> 26.05 | I9: {=IFERROR(SUMPRODUCT(($A$34:$A$135=$A9)*($B$34:$B$135=$B9)*($C$34:$C$135=$D9)*($D$34:$D$135=$E9)*(--ISNUMBER(SEARCH("Oil crops",$F$34:$F$135)))*$J$34:$J$135*$M$34:$M$135)/SUMPRODUCT(($A$34:$A$135=$A9)*($B$34:$B$135=$B9)*($C$34:$C$135=$D9)*($D$34:$D$135=$E9)*(--ISNUMBER(SEARCH("Oil crops",$F$34:$F$135)))*$J$34:$J$135),0)} -> 26.05 | J9: {=SUMPRODUCT(($A$34:$A$135=$A9)*($B$34:$B$135=$B9)*($C$34:$C$135=$D9)*($D$34:$D$135=$E9)*(--ISNUMBER(SEARCH("Oil crops",$F$34:$F$135)))*$H$34:$H$135)} -> 0.49572711 | K9: {=SUMPRODUCT(($A$34:$A$135=$A9)*($B$34:$B$135=$B9)*($C$34:$C$135=$D9)*($D$34:$D$135=$E9)*(--ISNUMBER(SEARCH("Oil crops",$F$34:$F$135)))*$I$34:$I$135)} -> 1.1703177 | L9: {=SUMPRODUCT(($A$34:$A$135=$A9)*($B$34:$B$135=$B9)*($C$34:$C$135=$D9)*($D$34:$D$135=$E9)*(--ISNUMBER(SEARCH("Oil crops",$F$34:$F$135)))*$J$34:$J$135)} -> 4.0986605 | M9: {=SUMPRODUCT(($A$34:$A$135=$A9)*($B$34:$B$135=$B9)*($C$34:$C$135=$D9)*($D$34:$D$135=$E9)*(--ISNUMBER(SEARCH("Oil crops",$F$34:$F$135)))*$K$34:$K$135)} -> 5.7647054 | N9: Feedstock-specific pathway: Oil crops
A10: EU | B10: 2 | C10: Hydrotreatment of Lipids | D10: HEFA / SAF | E10: Aviation-bio | F10: {=IFERROR(SUMPRODUCT(($A$34:$A$135=$A10)*($B$34:$B$135=$B10)*($C$34:$C$135=$D10)*($D$34:$D$135=$E10)*(--ISNUMBER(SEARCH("UCO",$F$34:$F$135)))*$H$34:$H$135*$M$34:$M$135)/SUMPRODUCT(($A$34:$A$135=$A10)*($B$34:$B$135=$B10)*($C$34:$C$135=$D10)*($D$34:$D$135=$E10)*(--ISNUMBER(SEARCH("UCO",$F$34:$F$135)))*$H$34:$H$135),0)} -> 21.4 | G10: {=IFERROR(SUMPRODUCT(($A$34:$A$135=$A10)*($B$34:$B$135=$B10)*($C$34:$C$135=$D10)*($D$34:$D$135=$E10)*(--ISNUMBER(SEARCH("UCO",$F$34:$F$135)))*$I$34:$I$135*$M$34:$M$135)/SUMPRODUCT(($A$34:$A$135=$A10)*($B$34:$B$135=$B10)*($C$34:$C$135=$D10)*($D$34:$D$135=$E10)*(--ISNUMBER(SEARCH("UCO",$F$34:$F$135)))*$I$34:$I$135),0)} -> 21.4 | H10: {=IFERROR(SUMPRODUCT(($A$34:$A$135=$A10)*($B$34:$B$135=$B10)*($C$34:$C$135=$D10)*($D$34:$D$135=$E10)*(--ISNUMBER(SEARCH("UCO",$F$34:$F$135)))*$K$34:$K$135*$M$34:$M$135)/SUMPRODUCT(($A$34:$A$135=$A10)*($B$34:$B$135=$B10)*($C$34:$C$135=$D10)*($D$34:$D$135=$E10)*(--ISNUMBER(SEARCH("UCO",$F$34:$F$135)))*$K$34:$K$135),0)} -> 21.4 | I10: {=IFERROR(SUMPRODUCT(($A$34:$A$135=$A10)*($B$34:$B$135=$B10)*($C$34:$C$135=$D10)*($D$34:$D$135=$E10)*(--ISNUMBER(SEARCH("UCO",$F$34:$F$135)))*$J$34:$J$135*$M$34:$M$135)/SUMPRODUCT(($A$34:$A$135=$A10)*($B$34:$B$135=$B10)*($C$34:$C$135=$D10)*($D$34:$D$135=$E10)*(--ISNUMBER(SEARCH("UCO",$F$34:$F$135)))*$J$34:$J$135),0)} -> 21.4 | J10: {=SUMPRODUCT(($A$34:$A$135=$A10)*($B$34:$B$135=$B10)*($C$34:$C$135=$D10)*($D$34:$D$135=$E10)*(--ISNUMBER(SEARCH("UCO",$F$34:$F$135)))*$H$34:$H$135)} -> 0.87091801 | K10: {=SUMPRODUCT(($A$34:$A$135=$A10)*($B$34:$B$135=$B10)*($C$34:$C$135=$D10)*($D$34:$D$135=$E10)*(--ISNUMBER(SEARCH("UCO",$F$34:$F$135)))*$I$34:$I$135)} -> 1.5106309 | L10: {=SUMPRODUCT(($A$34:$A$135=$A10)*($B$34:$B$135=$B10)*($C$34:$C$135=$D10)*($D$34:$D$135=$E10)*(--ISNUMBER(SEARCH("UCO",$F$34:$F$135)))*$J$34:$J$135)} -> 2.4003433 | M10: {=SUMPRODUCT(($A$34:$A$135=$A10)*($B$34:$B$135=$B10)*($C$34:$C$135=$D10)*($D$34:$D$135=$E10)*(--ISNUMBER(SEARCH("UCO",$F$34:$F$135)))*$K$34:$K$135)} -> 4.7818922 | N10: Feedstock-specific pathway: UCO / animal fat
A11: EU | B11: 2 | C11: Hydrotreatment of Lipids | D11: HEFA / SAF | E11: Aviation-bio | F11: {=IFERROR(SUMPRODUCT(($A$34:$A$135=$A11)*($B$34:$B$135=$B11)*($C$34:$C$135=$D11)*($D$34:$D$135=$E11)*(--((ISNUMBER(SEARCH("Tall oil",$F$34:$F$135))+ISNUMBER(SEARCH("POME",$F$34:$F$135)))>0))*$H$34:$H$135*$M$34:$M$135)/SUMPRODUCT(($A$34:$A$135=$A11)*($B$34:$B$135=$B11)*($C$34:$C$135=$D11)*($D$34:$D$135=$E11)*(--((ISNUMBER(SEARCH("Tall oil",$F$34:$F$135))+ISNUMBER(SEARCH("POME",$F$34:$F$135)))>0))*$H$34:$H$135),0)} -> 17.5 | G11: {=IFERROR(SUMPRODUCT(($A$34:$A$135=$A11)*($B$34:$B$135=$B11)*($C$34:$C$135=$D11)*($D$34:$D$135=$E11)*(--((ISNUMBER(SEARCH("Tall oil",$F$34:$F$135))+ISNUMBER(SEARCH("POME",$F$34:$F$135)))>0))*$I$34:$I$135*$M$34:$M$135)/SUMPRODUCT(($A$34:$A$135=$A11)*($B$34:$B$135=$B11)*($C$34:$C$135=$D11)*($D$34:$D$135=$E11)*(--((ISNUMBER(SEARCH("Tall oil",$F$34:$F$135))+ISNUMBER(SEARCH("POME",$F$34:$F$135)))>0))*$I$34:$I$135),0)} -> 17.5 | H11: {=IFERROR(SUMPRODUCT(($A$34:$A$135=$A11)*($B$34:$B$135=$B11)*($C$34:$C$135=$D11)*($D$34:$D$135=$E11)*(--((ISNUMBER(SEARCH("Tall oil",$F$34:$F$135))+ISNUMBER(SEARCH("POME",$F$34:$F$135)))>0))*$K$34:$K$135*$M$34:$M$135)/SUMPRODUCT(($A$34:$A$135=$A11)*($B$34:$B$135=$B11)*($C$34:$C$135=$D11)*($D$34:$D$135=$E11)*(--((ISNUMBER(SEARCH("Tall oil",$F$34:$F$135))+ISNUMBER(SEARCH("POME",$F$34:$F$135)))>0))*$K$34:$K$135),0)} -> 17.5 | I11: {=IFERROR(SUMPRODUCT(($A$34:$A$135=$A11)*($B$34:$B$135=$B11)*($C$34:$C$135=$D11)*($D$34:$D$135=$E11)*(--((ISNUMBER(SEARCH("Tall oil",$F$34:$F$135))+ISNUMBER(SEARCH("POME",$F$34:$F$135)))>0))*$J$34:$J$135*$M$34:$M$135)/SUMPRODUCT(($A$34:$A$135=$A11)*($B$34:$B$135=$B11)*($C$34:$C$135=$D11)*($D$34:$D$135=$E11)*(--((ISNUMBER(SEARCH("Tall oil",$F$34:$F$135))+ISNUMBER(SEARCH("POME",$F$34:$F$135)))>0))*$J$34:$J$135),0)} -> 17.5 | J11: {=SUMPRODUCT(($A$34:$A$135=$A11)*($B$34:$B$135=$B11)*($C$34:$C$135=$D11)*($D$34:$D$135=$E11)*(--((ISNUMBER(SEARCH("Tall oil",$F$34:$F$135))+ISNUMBER(SEARCH("POME",$F$34:$F$135)))>0))*$H$34:$H$135)} -> 0.2 | K11: {=SUMPRODUCT(($A$34:$A$135=$A11)*($B$34:$B$135=$B11)*($C$34:$C$135=$D11)*($D$34:$D$135=$E11)*(--((ISNUMBER(SEARCH("Tall oil",$F$34:$F$135))+ISNUMBER(SEARCH("POME",$F$34:$F$135)))>0))*$I$34:$I$135)} -> 0.4 | L11: {=SUMPRODUCT(($A$34:$A$135=$A11)*($B$34:$B$135=$B11)*($C$34:$C$135=$D11)*($D$34:$D$135=$E11)*(--((ISNUMBER(SEARCH("Tall oil",$F$34:$F$135))+ISNUMBER(SEARCH("POME",$F$34:$F$135)))>0))*$J$34:$J$135)} -> 0.7 | M11: {=SUMPRODUCT(($A$34:$A$135=$A11)*($B$34:$B$135=$B11)*($C$34:$C$135=$D11)*($D$34:$D$135=$E11)*(--((ISNUMBER(SEARCH("Tall oil",$F$34:$F$135))+ISNUMBER(SEARCH("POME",$F$34:$F$135)))>0))*$K$34:$K$135)} -> 1.3 | N11: Feedstock-specific pathway: POME / tall-oil proxy
A12: EU | B12: 2 | C12: Hydrotreatment of Lipids | D12: HEFA / SAF | E12: Aviation-bio | F12: {=IFERROR(SUMPRODUCT(($A$34:$A$135=$A12)*($B$34:$B$135=$B12)*($C$34:$C$135=$D12)*($D$34:$D$135=$E12)*(--((ISNUMBER(SEARCH("FPBO",$F$34:$F$135))+ISNUMBER(SEARCH("biocrude",$F$34:$F$135)))>0))*$H$34:$H$135*$M$34:$M$135)/SUMPRODUCT(($A$34:$A$135=$A12)*($B$34:$B$135=$B12)*($C$34:$C$135=$D12)*($D$34:$D$135=$E12)*(--((ISNUMBER(SEARCH("FPBO",$F$34:$F$135))+ISNUMBER(SEARCH("biocrude",$F$34:$F$135)))>0))*$H$34:$H$135),0)} -> 21.4 | G12: {=IFERROR(SUMPRODUCT(($A$34:$A$135=$A12)*($B$34:$B$135=$B12)*($C$34:$C$135=$D12)*($D$34:$D$135=$E12)*(--((ISNUMBER(SEARCH("FPBO",$F$34:$F$135))+ISNUMBER(SEARCH("biocrude",$F$34:$F$135)))>0))*$I$34:$I$135*$M$34:$M$135)/SUMPRODUCT(($A$34:$A$135=$A12)*($B$34:$B$135=$B12)*($C$34:$C$135=$D12)*($D$34:$D$135=$E12)*(--((ISNUMBER(SEARCH("FPBO",$F$34:$F$135))+ISNUMBER(SEARCH("biocrude",$F$34:$F$135)))>0))*$I$34:$I$135),0)} -> 21.4 | H12: {=IFERROR(SUMPRODUCT(($A$34:$A$135=$A12)*($B$34:$B$135=$B12)*($C$34:$C$135=$D12)*($D$34:$D$135=$E12)*(--((ISNUMBER(SEARCH("FPBO",$F$34:$F$135))+ISNUMBER(SEARCH("biocrude",$F$34:$F$135)))>0))*$K$34:$K$135*$M$34:$M$135)/SUMPRODUCT(($A$34:$A$135=$A12)*($B$34:$B$135=$B12)*($C$34:$C$135=$D12)*($D$34:$D$135=$E12)*(--((ISNUMBER(SEARCH("FPBO",$F$34:$F$135))+ISNUMBER(SEARCH("biocrude",$F$34:$F$135)))>0))*$K$34:$K$135),0)} -> 21.4 | I12: {=IFERROR(SUMPRODUCT(($A$34:$A$135=$A12)*($B$34:$B$135=$B12)*($C$34:$C$135=$D12)*($D$34:$D$135=$E12)*(--((ISNUMBER(SEARCH("FPBO",$F$34:$F$135))+ISNUMBER(SEARCH("biocrude",$F$34:$F$135)))>0))*$J$34:$J$135*$M$34:$M$135)/SUMPRODUCT(($A$34:$A$135=$A12)*($B$34:$B$135=$B12)*($C$34:$C$135=$D12)*($D$34:$D$135=$E12)*(--((ISNUMBER(SEARCH("FPBO",$F$34:$F$135))+ISNUMBER(SEARCH("biocrude",$F$34:$F$135)))>0))*$J$34:$J$135),0)} -> 21.4 | J12: {=SUMPRODUCT(($A$34:$A$135=$A12)*($B$34:$B$135=$B12)*($C$34:$C$135=$D12)*($D$34:$D$135=$E12)*(--((ISNUMBER(SEARCH("FPBO",$F$34:$F$135))+ISNUMBER(SEARCH("biocrude",$F$34:$F$135)))>0))*$H$34:$H$135)} -> 1.0285054 | K12: {=SUMPRODUCT(($A$34:$A$135=$A12)*($B$34:$B$135=$B12)*($C$34:$C$135=$D12)*($D$34:$D$135=$E12)*(--((ISNUMBER(SEARCH("FPBO",$F$34:$F$135))+ISNUMBER(SEARCH("biocrude",$F$34:$F$135)))>0))*$I$34:$I$135)} -> 1.3060866 | L12: {=SUMPRODUCT(($A$34:$A$135=$A12)*($B$34:$B$135=$B12)*($C$34:$C$135=$D12)*($D$34:$D$135=$E12)*(--((ISNUMBER(SEARCH("FPBO",$F$34:$F$135))+ISNUMBER(SEARCH("biocrude",$F$34:$F$135)))>0))*$J$34:$J$135)} -> 3.407654 | M12: {=SUMPRODUCT(($A$34:$A$135=$A12)*($B$34:$B$135=$B12)*($C$34:$C$135=$D12)*($D$34:$D$135=$E12)*(--((ISNUMBER(SEARCH("FPBO",$F$34:$F$135))+ISNUMBER(SEARCH("biocrude",$F$34:$F$135)))>0))*$K$34:$K$135)} -> 5.7422459 | N12: Feedstock-specific pathway: FPBO + biocrude
A13: EU | B13: 3 | C13: Lignin Boost of Fatty Acids and Co-processing in Refinery | D13: Renewable diesel | E13: Road-bio | F13: {=IFERROR(SUMPRODUCT(($A$34:$A$135=$A13)*($B$34:$B$135=$B13)*($C$34:$C$135=$D13)*($D$34:$D$135=$E13)*$H$34:$H$135*$M$34:$M$135)/SUMIFS($H$34:$H$135,$A$34:$A$135,$A13,$B$34:$B$135,$B13,$C$34:$C$135,$D13,$D$34:$D$135,$E13),0)} -> 55.5 | G13: {=IFERROR(SUMPRODUCT(($A$34:$A$135=$A13)*($B$34:$B$135=$B13)*($C$34:$C$135=$D13)*($D$34:$D$135=$E13)*$I$34:$I$135*$M$34:$M$135)/SUMIFS($I$34:$I$135,$A$34:$A$135,$A13,$B$34:$B$135,$B13,$C$34:$C$135,$D13,$D$34:$D$135,$E13),0)} -> 0 | H13: {=IFERROR(SUMPRODUCT(($A$34:$A$135=$A13)*($B$34:$B$135=$B13)*($C$34:$C$135=$D13)*($D$34:$D$135=$E13)*$K$34:$K$135*$M$34:$M$135)/SUMIFS($K$34:$K$135,$A$34:$A$135,$A13,$B$34:$B$135,$B13,$C$34:$C$135,$D13,$D$34:$D$135,$E13),0)} -> 55.5 | I13: {=IFERROR(SUMPRODUCT(($A$34:$A$135=$A13)*($B$34:$B$135=$B13)*($C$34:$C$135=$D13)*($D$34:$D$135=$E13)*$J$34:$J$135*$M$34:$M$135)/SUMIFS($J$34:$J$135,$A$34:$A$135,$A13,$B$34:$B$135,$B13,$C$34:$C$135,$D13,$D$34:$D$135,$E13),0)} -> 55.5 | J13: =SUMIFS($H$34:$H$135,$A$34:$A$135,$A13,$B$34:$B$135,$B13,$C$34:$C$135,$D13,$D$34:$D$135,$E13) -> 4.4540042 | K13: =SUMIFS($I$34:$I$135,$A$34:$A$135,$A13,$B$34:$B$135,$B13,$C$34:$C$135,$D13,$D$34:$D$135,$E13) -> 0 | L13: =SUMIFS($J$34:$J$135,$A$34:$A$135,$A13,$B$34:$B$135,$B13,$C$34:$C$135,$D13,$D$34:$D$135,$E13) -> 10.5 | M13: =SUMIFS($K$34:$K$135,$A$34:$A$135,$A13,$B$34:$B$135,$B13,$C$34:$C$135,$D13,$D$34:$D$135,$E13) -> 14.954004 | N13: Sector-specific pathway; EU N/Q/X availability × AE feedstock share
A14: EU | B14: 5 | C14: Fermentation of Lignocellulosic Materials to Ethanol | D14: Advanced ethanol | E14: Road-bio | F14: {=IFERROR(SUMPRODUCT(($A$34:$A$135=$A14)*($B$34:$B$135=$B14)*($C$34:$C$135=$D14)*($D$34:$D$135=$E14)*$H$34:$H$135*$M$34:$M$135)/SUMIFS($H$34:$H$135,$A$34:$A$135,$A14,$B$34:$B$135,$B14,$C$34:$C$135,$D14,$D$34:$D$135,$E14),0)} -> 24.4 | G14: {=IFERROR(SUMPRODUCT(($A$34:$A$135=$A14)*($B$34:$B$135=$B14)*($C$34:$C$135=$D14)*($D$34:$D$135=$E14)*$I$34:$I$135*$M$34:$M$135)/SUMIFS($I$34:$I$135,$A$34:$A$135,$A14,$B$34:$B$135,$B14,$C$34:$C$135,$D14,$D$34:$D$135,$E14),0)} -> 24.4 | H14: {=IFERROR(SUMPRODUCT(($A$34:$A$135=$A14)*($B$34:$B$135=$B14)*($C$34:$C$135=$D14)*($D$34:$D$135=$E14)*$K$34:$K$135*$M$34:$M$135)/SUMIFS($K$34:$K$135,$A$34:$A$135,$A14,$B$34:$B$135,$B14,$C$34:$C$135,$D14,$D$34:$D$135,$E14),0)} -> 24.4 | I14: {=IFERROR(SUMPRODUCT(($A$34:$A$135=$A14)*($B$34:$B$135=$B14)*($C$34:$C$135=$D14)*($D$34:$D$135=$E14)*$J$34:$J$135*$M$34:$M$135)/SUMIFS($J$34:$J$135,$A$34:$A$135,$A14,$B$34:$B$135,$B14,$C$34:$C$135,$D14,$D$34:$D$135,$E14),0)} -> 24.4 | J14: =SUMIFS($H$34:$H$135,$A$34:$A$135,$A14,$B$34:$B$135,$B14,$C$34:$C$135,$D14,$D$34:$D$135,$E14) -> 26.310985 | K14: =SUMIFS($I$34:$I$135,$A$34:$A$135,$A14,$B$34:$B$135,$B14,$C$34:$C$135,$D14,$D$34:$D$135,$E14) -> 40.928169 | L14: =SUMIFS($J$34:$J$135,$A$34:$A$135,$A14,$B$34:$B$135,$B14,$C$34:$C$135,$D14,$D$34:$D$135,$E14) -> 51.616756 | M14: =SUMIFS($K$34:$K$135,$A$34:$A$135,$A14,$B$34:$B$135,$B14,$C$34:$C$135,$D14,$D$34:$D$135,$E14) -> 118.85591 | N14: Sector-specific pathway; EU N/Q/X availability × AE feedstock share
A15: EU | B15: 5 | C15: Fermentation of Lignocellulosic Materials to Ethanol | D15: ATJ-SPK | E15: Aviation-bio 2040/2050 | F15: {=IFERROR(SUMPRODUCT(($A$34:$A$135=$A15)*($B$34:$B$135=$B15)*($C$34:$C$135=$D15)*($D$34:$D$135=$E15)*$H$34:$H$135*$M$34:$M$135)/SUMIFS($H$34:$H$135,$A$34:$A$135,$A15,$B$34:$B$135,$B15,$C$34:$C$135,$D15,$D$34:$D$135,$E15),0)} -> 24.4 | G15: {=IFERROR(SUMPRODUCT(($A$34:$A$135=$A15)*($B$34:$B$135=$B15)*($C$34:$C$135=$D15)*($D$34:$D$135=$E15)*$I$34:$I$135*$M$34:$M$135)/SUMIFS($I$34:$I$135,$A$34:$A$135,$A15,$B$34:$B$135,$B15,$C$34:$C$135,$D15,$D$34:$D$135,$E15),0)} -> 24.4 | H15: {=IFERROR(SUMPRODUCT(($A$34:$A$135=$A15)*($B$34:$B$135=$B15)*($C$34:$C$135=$D15)*($D$34:$D$135=$E15)*$K$34:$K$135*$M$34:$M$135)/SUMIFS($K$34:$K$135,$A$34:$A$135,$A15,$B$34:$B$135,$B15,$C$34:$C$135,$D15,$D$34:$D$135,$E15),0)} -> 24.4 | I15: {=IFERROR(SUMPRODUCT(($A$34:$A$135=$A15)*($B$34:$B$135=$B15)*($C$34:$C$135=$D15)*($D$34:$D$135=$E15)*$J$34:$J$135*$M$34:$M$135)/SUMIFS($J$34:$J$135,$A$34:$A$135,$A15,$B$34:$B$135,$B15,$C$34:$C$135,$D15,$D$34:$D$135,$E15),0)} -> 24.4 | J15: =SUMIFS($H$34:$H$135,$A$34:$A$135,$A15,$B$34:$B$135,$B15,$C$34:$C$135,$D15,$D$34:$D$135,$E15) -> 13.155492 | K15: =SUMIFS($I$34:$I$135,$A$34:$A$135,$A15,$B$34:$B$135,$B15,$C$34:$C$135,$D15,$D$34:$D$135,$E15) -> 20.464084 | L15: =SUMIFS($J$34:$J$135,$A$34:$A$135,$A15,$B$34:$B$135,$B15,$C$34:$C$135,$D15,$D$34:$D$135,$E15) -> 25.808378 | M15: =SUMIFS($K$34:$K$135,$A$34:$A$135,$A15,$B$34:$B$135,$B15,$C$34:$C$135,$D15,$D$34:$D$135,$E15) -> 59.427955 | N15: Sector-specific pathway; EU N/Q/X availability × AE feedstock share
A16: EU | B16: 6 | C16: ATJ / MTJ | D16: ATJ-SPK | E16: Aviation-bio | F16: {=IFERROR(SUMPRODUCT(($A$34:$A$135=$A16)*($B$34:$B$135=$B16)*($C$34:$C$135=$D16)*($D$34:$D$135=$E16)*$H$34:$H$135*$M$34:$M$135)/SUMIFS($H$34:$H$135,$A$34:$A$135,$A16,$B$34:$B$135,$B16,$C$34:$C$135,$D16,$D$34:$D$135,$E16),0)} -> 0 | G16: {=IFERROR(SUMPRODUCT(($A$34:$A$135=$A16)*($B$34:$B$135=$B16)*($C$34:$C$135=$D16)*($D$34:$D$135=$E16)*$I$34:$I$135*$M$34:$M$135)/SUMIFS($I$34:$I$135,$A$34:$A$135,$A16,$B$34:$B$135,$B16,$C$34:$C$135,$D16,$D$34:$D$135,$E16),0)} -> 0 | H16: {=IFERROR(SUMPRODUCT(($A$34:$A$135=$A16)*($B$34:$B$135=$B16)*($C$34:$C$135=$D16)*($D$34:$D$135=$E16)*$K$34:$K$135*$M$34:$M$135)/SUMIFS($K$34:$K$135,$A$34:$A$135,$A16,$B$34:$B$135,$B16,$C$34:$C$135,$D16,$D$34:$D$135,$E16),0)} -> 0 | I16: {=IFERROR(SUMPRODUCT(($A$34:$A$135=$A16)*($B$34:$B$135=$B16)*($C$34:$C$135=$D16)*($D$34:$D$135=$E16)*$J$34:$J$135*$M$34:$M$135)/SUMIFS($J$34:$J$135,$A$34:$A$135,$A16,$B$34:$B$135,$B16,$C$34:$C$135,$D16,$D$34:$D$135,$E16),0)} -> 0 | J16: =SUMIFS($H$34:$H$135,$A$34:$A$135,$A16,$B$34:$B$135,$B16,$C$34:$C$135,$D16,$D$34:$D$135,$E16) -> 0 | K16: =SUMIFS($I$34:$I$135,$A$34:$A$135,$A16,$B$34:$B$135,$B16,$C$34:$C$135,$D16,$D$34:$D$135,$E16) -> 0 | L16: =SUMIFS($J$34:$J$135,$A$34:$A$135,$A16,$B$34:$B$135,$B16,$C$34:$C$135,$D16,$D$34:$D$135,$E16) -> 0 | M16: =SUMIFS($K$34:$K$135,$A$34:$A$135,$A16,$B$34:$B$135,$B16,$C$34:$C$135,$D16,$D$34:$D$135,$E16) -> 0 | N16: Sector-specific pathway; EU N/Q/X availability × AE feedstock share
A17: EU | B17: 7 | C17: Biomethane from Anaerobic Digestion | D17: Biomethane | E17: Road-bio 2030 | F17: {=IFERROR(SUMPRODUCT(($A$34:$A$135=$A17)*($B$34:$B$135=$B17)*($C$34:$C$135=$D17)*($D$34:$D$135=$E17)*$H$34:$H$135*$M$34:$M$135)/SUMIFS($H$34:$H$135,$A$34:$A$135,$A17,$B$34:$B$135,$B17,$C$34:$C$135,$D17,$D$34:$D$135,$E17),0)} -> -65.174147 | G17: {=IFERROR(SUMPRODUCT(($A$34:$A$135=$A17)*($B$34:$B$135=$B17)*($C$34:$C$135=$D17)*($D$34:$D$135=$E17)*$I$34:$I$135*$M$34:$M$135)/SUMIFS($I$34:$I$135,$A$34:$A$135,$A17,$B$34:$B$135,$B17,$C$34:$C$135,$D17,$D$34:$D$135,$E17),0)} -> -63.215969 | H17: {=IFERROR(SUMPRODUCT(($A$34:$A$135=$A17)*($B$34:$B$135=$B17)*($C$34:$C$135=$D17)*($D$34:$D$135=$E17)*$K$34:$K$135*$M$34:$M$135)/SUMIFS($K$34:$K$135,$A$34:$A$135,$A17,$B$34:$B$135,$B17,$C$34:$C$135,$D17,$D$34:$D$135,$E17),0)} -> -62.308737 | I17: {=IFERROR(SUMPRODUCT(($A$34:$A$135=$A17)*($B$34:$B$135=$B17)*($C$34:$C$135=$D17)*($D$34:$D$135=$E17)*$J$34:$J$135*$M$34:$M$135)/SUMIFS($J$34:$J$135,$A$34:$A$135,$A17,$B$34:$B$135,$B17,$C$34:$C$135,$D17,$D$34:$D$135,$E17),0)} -> -59.337639 | J17: =SUMIFS($H$34:$H$135,$A$34:$A$135,$A17,$B$34:$B$135,$B17,$C$34:$C$135,$D17,$D$34:$D$135,$E17) -> 145.33173 | K17: =SUMIFS($I$34:$I$135,$A$34:$A$135,$A17,$B$34:$B$135,$B17,$C$34:$C$135,$D17,$D$34:$D$135,$E17) -> 198.99384 | L17: =SUMIFS($J$34:$J$135,$A$34:$A$135,$A17,$B$34:$B$135,$B17,$C$34:$C$135,$D17,$D$34:$D$135,$E17) -> 200.92527 | M17: =SUMIFS($K$34:$K$135,$A$34:$A$135,$A17,$B$34:$B$135,$B17,$C$34:$C$135,$D17,$D$34:$D$135,$E17) -> 545.25084 | N17: Sector-specific pathway; EU N/Q/X availability × AE feedstock share
A18: EU | B18: 8a | C18: Gasification and Methanol Synthesis | D18: Methanol | E18: Maritime-bio | F18: {=IFERROR(SUMPRODUCT(($A$34:$A$135=$A18)*($B$34:$B$135=$B18)*($C$34:$C$135=$D18)*($D$34:$D$135=$E18)*$H$34:$H$135*$M$34:$M$135)/SUMIFS($H$34:$H$135,$A$34:$A$135,$A18,$B$34:$B$135,$B18,$C$34:$C$135,$D18,$D$34:$D$135,$E18),0)} -> 12.5 | G18: {=IFERROR(SUMPRODUCT(($A$34:$A$135=$A18)*($B$34:$B$135=$B18)*($C$34:$C$135=$D18)*($D$34:$D$135=$E18)*$I$34:$I$135*$M$34:$M$135)/SUMIFS($I$34:$I$135,$A$34:$A$135,$A18,$B$34:$B$135,$B18,$C$34:$C$135,$D18,$D$34:$D$135,$E18),0)} -> 12.5 | H18: {=IFERROR(SUMPRODUCT(($A$34:$A$135=$A18)*($B$34:$B$135=$B18)*($C$34:$C$135=$D18)*($D$34:$D$135=$E18)*$K$34:$K$135*$M$34:$M$135)/SUMIFS($K$34:$K$135,$A$34:$A$135,$A18,$B$34:$B$135,$B18,$C$34:$C$135,$D18,$D$34:$D$135,$E18),0)} -> 12.5 | I18: {=IFERROR(SUMPRODUCT(($A$34:$A$135=$A18)*($B$34:$B$135=$B18)*($C$34:$C$135=$D18)*($D$34:$D$135=$E18)*$J$34:$J$135*$M$34:$M$135)/SUMIFS($J$34:$J$135,$A$34:$A$135,$A18,$B$34:$B$135,$B18,$C$34:$C$135,$D18,$D$34:$D$135,$E18),0)} -> 12.5 | J18: =SUMIFS($H$34:$H$135,$A$34:$A$135,$A18,$B$34:$B$135,$B18,$C$34:$C$135,$D18,$D$34:$D$135,$E18) -> 41.755582 | K18: =SUMIFS($I$34:$I$135,$A$34:$A$135,$A18,$B$34:$B$135,$B18,$C$34:$C$135,$D18,$D$34:$D$135,$E18) -> 58.944139 | L18: =SUMIFS($J$34:$J$135,$A$34:$A$135,$A18,$B$34:$B$135,$B18,$C$34:$C$135,$D18,$D$34:$D$135,$E18) -> 70.45409 | M18: =SUMIFS($K$34:$K$135,$A$34:$A$135,$A18,$B$34:$B$135,$B18,$C$34:$C$135,$D18,$D$34:$D$135,$E18) -> 171.15381 | N18: Sector-specific pathway; EU N/Q/X availability × AE feedstock share
A19: EU | B19: 8b | C19: Methane reforming and Methanolysis | D19: Methanol | E19: Maritime-bio | F19: {=IFERROR(SUMPRODUCT(($A$34:$A$135=$A19)*($B$34:$B$135=$B19)*($C$34:$C$135=$D19)*($D$34:$D$135=$E19)*$H$34:$H$135*$M$34:$M$135)/SUMIFS($H$34:$H$135,$A$34:$A$135,$A19,$B$34:$B$135,$B19,$C$34:$C$135,$D19,$D$34:$D$135,$E19),0)} -> 12 | G19: {=IFERROR(SUMPRODUCT(($A$34:$A$135=$A19)*($B$34:$B$135=$B19)*($C$34:$C$135=$D19)*($D$34:$D$135=$E19)*$I$34:$I$135*$M$34:$M$135)/SUMIFS($I$34:$I$135,$A$34:$A$135,$A19,$B$34:$B$135,$B19,$C$34:$C$135,$D19,$D$34:$D$135,$E19),0)} -> 12 | H19: {=IFERROR(SUMPRODUCT(($A$34:$A$135=$A19)*($B$34:$B$135=$B19)*($C$34:$C$135=$D19)*($D$34:$D$135=$E19)*$K$34:$K$135*$M$34:$M$135)/SUMIFS($K$34:$K$135,$A$34:$A$135,$A19,$B$34:$B$135,$B19,$C$34:$C$135,$D19,$D$34:$D$135,$E19),0)} -> 12 | I19: {=IFERROR(SUMPRODUCT(($A$34:$A$135=$A19)*($B$34:$B$135=$B19)*($C$34:$C$135=$D19)*($D$34:$D$135=$E19)*$J$34:$J$135*$M$34:$M$135)/SUMIFS($J$34:$J$135,$A$34:$A$135,$A19,$B$34:$B$135,$B19,$C$34:$C$135,$D19,$D$34:$D$135,$E19),0)} -> 0 | J19: =SUMIFS($H$34:$H$135,$A$34:$A$135,$A19,$B$34:$B$135,$B19,$C$34:$C$135,$D19,$D$34:$D$135,$E19) -> 2.296 | K19: =SUMIFS($I$34:$I$135,$A$34:$A$135,$A19,$B$34:$B$135,$B19,$C$34:$C$135,$D19,$D$34:$D$135,$E19) -> 26.023398 | L19: =SUMIFS($J$34:$J$135,$A$34:$A$135,$A19,$B$34:$B$135,$B19,$C$34:$C$135,$D19,$D$34:$D$135,$E19) -> 0 | M19: =SUMIFS($K$34:$K$135,$A$34:$A$135,$A19,$B$34:$B$135,$B19,$C$34:$C$135,$D19,$D$34:$D$135,$E19) -> 28.319398 | N19: Sector-specific pathway; EU N/Q/X availability × AE feedstock share
A20: EU | B20: 8c | C20: Methanolysis from CO2 and green H2 | D20: e-Methanol (RFNBO) | E20: Maritime-e | F20: {=IFERROR(SUMPRODUCT(($A$34:$A$135=$A20)*($B$34:$B$135=$B20)*($C$34:$C$135=$D20)*($D$34:$D$135=$E20)*$H$34:$H$135*$M$34:$M$135)/SUMIFS($H$34:$H$135,$A$34:$A$135,$A20,$B$34:$B$135,$B20,$C$34:$C$135,$D20,$D$34:$D$135,$E20),0)} -> 1.8 | G20: {=IFERROR(SUMPRODUCT(($A$34:$A$135=$A20)*($B$34:$B$135=$B20)*($C$34:$C$135=$D20)*($D$34:$D$135=$E20)*$I$34:$I$135*$M$34:$M$135)/SUMIFS($I$34:$I$135,$A$34:$A$135,$A20,$B$34:$B$135,$B20,$C$34:$C$135,$D20,$D$34:$D$135,$E20),0)} -> 1.8 | H20: {=IFERROR(SUMPRODUCT(($A$34:$A$135=$A20)*($B$34:$B$135=$B20)*($C$34:$C$135=$D20)*($D$34:$D$135=$E20)*$K$34:$K$135*$M$34:$M$135)/SUMIFS($K$34:$K$135,$A$34:$A$135,$A20,$B$34:$B$135,$B20,$C$34:$C$135,$D20,$D$34:$D$135,$E20),0)} -> 1.8 | I20: {=IFERROR(SUMPRODUCT(($A$34:$A$135=$A20)*($B$34:$B$135=$B20)*($C$34:$C$135=$D20)*($D$34:$D$135=$E20)*$J$34:$J$135*$M$34:$M$135)/SUMIFS($J$34:$J$135,$A$34:$A$135,$A20,$B$34:$B$135,$B20,$C$34:$C$135,$D20,$D$34:$D$135,$E20),0)} -> 1.8 | J20: =SUMIFS($H$34:$H$135,$A$34:$A$135,$A20,$B$34:$B$135,$B20,$C$34:$C$135,$D20,$D$34:$D$135,$E20) -> 16.34 | K20: =SUMIFS($I$34:$I$135,$A$34:$A$135,$A20,$B$34:$B$135,$B20,$C$34:$C$135,$D20,$D$34:$D$135,$E20) -> 16.34 | L20: =SUMIFS($J$34:$J$135,$A$34:$A$135,$A20,$B$34:$B$135,$B20,$C$34:$C$135,$D20,$D$34:$D$135,$E20) -> 32.195 | M20: =SUMIFS($K$34:$K$135,$A$34:$A$135,$A20,$B$34:$B$135,$B20,$C$34:$C$135,$D20,$D$34:$D$135,$E20) -> 64.875 | N20: Sector-specific pathway; EU N/Q/X availability × AE feedstock share
A21: EU | B21: 8d | C21: Methanol from pulping | D21: Pathway output | E21: Other / multi-sector | F21: {=IFERROR(SUMPRODUCT(($A$34:$A$135=$A21)*($B$34:$B$135=$B21)*($C$34:$C$135=$D21)*($D$34:$D$135=$E21)*$H$34:$H$135*$M$34:$M$135)/SUMIFS($H$34:$H$135,$A$34:$A$135,$A21,$B$34:$B$135,$B21,$C$34:$C$135,$D21,$D$34:$D$135,$E21),0)} -> 0 | G21: {=IFERROR(SUMPRODUCT(($A$34:$A$135=$A21)*($B$34:$B$135=$B21)*($C$34:$C$135=$D21)*($D$34:$D$135=$E21)*$I$34:$I$135*$M$34:$M$135)/SUMIFS($I$34:$I$135,$A$34:$A$135,$A21,$B$34:$B$135,$B21,$C$34:$C$135,$D21,$D$34:$D$135,$E21),0)} -> 0 | H21: {=IFERROR(SUMPRODUCT(($A$34:$A$135=$A21)*($B$34:$B$135=$B21)*($C$34:$C$135=$D21)*($D$34:$D$135=$E21)*$K$34:$K$135*$M$34:$M$135)/SUMIFS($K$34:$K$135,$A$34:$A$135,$A21,$B$34:$B$135,$B21,$C$34:$C$135,$D21,$D$34:$D$135,$E21),0)} -> 0 | I21: {=IFERROR(SUMPRODUCT(($A$34:$A$135=$A21)*($B$34:$B$135=$B21)*($C$34:$C$135=$D21)*($D$34:$D$135=$E21)*$J$34:$J$135*$M$34:$M$135)/SUMIFS($J$34:$J$135,$A$34:$A$135,$A21,$B$34:$B$135,$B21,$C$34:$C$135,$D21,$D$34:$D$135,$E21),0)} -> 0 | J21: =SUMIFS($H$34:$H$135,$A$34:$A$135,$A21,$B$34:$B$135,$B21,$C$34:$C$135,$D21,$D$34:$D$135,$E21) -> 0 | K21: =SUMIFS($I$34:$I$135,$A$34:$A$135,$A21,$B$34:$B$135,$B21,$C$34:$C$135,$D21,$D$34:$D$135,$E21) -> 0 | L21: =SUMIFS($J$34:$J$135,$A$34:$A$135,$A21,$B$34:$B$135,$B21,$C$34:$C$135,$D21,$D$34:$D$135,$E21) -> 0 | M21: =SUMIFS($K$34:$K$135,$A$34:$A$135,$A21,$B$34:$B$135,$B21,$C$34:$C$135,$D21,$D$34:$D$135,$E21) -> 0 | N21: Sector-specific pathway; EU N/Q/X availability × AE feedstock share
A22: EU | B22: 9a | C22: Gasification and Methanation | D22: Methane | E22: Maritime -bio | F22: {=IFERROR(SUMPRODUCT(($A$34:$A$135=$A22)*($B$34:$B$135=$B22)*($C$34:$C$135=$D22)*($D$34:$D$135=$E22)*$H$34:$H$135*$M$34:$M$135)/SUMIFS($H$34:$H$135,$A$34:$A$135,$A22,$B$34:$B$135,$B22,$C$34:$C$135,$D22,$D$34:$D$135,$E22),0)} -> 21.696065 | G22: {=IFERROR(SUMPRODUCT(($A$34:$A$135=$A22)*($B$34:$B$135=$B22)*($C$34:$C$135=$D22)*($D$34:$D$135=$E22)*$I$34:$I$135*$M$34:$M$135)/SUMIFS($I$34:$I$135,$A$34:$A$135,$A22,$B$34:$B$135,$B22,$C$34:$C$135,$D22,$D$34:$D$135,$E22),0)} -> 21.554247 | H22: {=IFERROR(SUMPRODUCT(($A$34:$A$135=$A22)*($B$34:$B$135=$B22)*($C$34:$C$135=$D22)*($D$34:$D$135=$E22)*$K$34:$K$135*$M$34:$M$135)/SUMIFS($K$34:$K$135,$A$34:$A$135,$A22,$B$34:$B$135,$B22,$C$34:$C$135,$D22,$D$34:$D$135,$E22),0)} -> 21.754917 | I22: {=IFERROR(SUMPRODUCT(($A$34:$A$135=$A22)*($B$34:$B$135=$B22)*($C$34:$C$135=$D22)*($D$34:$D$135=$E22)*$J$34:$J$135*$M$34:$M$135)/SUMIFS($J$34:$J$135,$A$34:$A$135,$A22,$B$34:$B$135,$B22,$C$34:$C$135,$D22,$D$34:$D$135,$E22),0)} -> 21.957683 | J22: =SUMIFS($H$34:$H$135,$A$34:$A$135,$A22,$B$34:$B$135,$B22,$C$34:$C$135,$D22,$D$34:$D$135,$E22) -> 41.755582 | K22: =SUMIFS($I$34:$I$135,$A$34:$A$135,$A22,$B$34:$B$135,$B22,$C$34:$C$135,$D22,$D$34:$D$135,$E22) -> 58.944139 | L22: =SUMIFS($J$34:$J$135,$A$34:$A$135,$A22,$B$34:$B$135,$B22,$C$34:$C$135,$D22,$D$34:$D$135,$E22) -> 70.45409 | M22: =SUMIFS($K$34:$K$135,$A$34:$A$135,$A22,$B$34:$B$135,$B22,$C$34:$C$135,$D22,$D$34:$D$135,$E22) -> 171.15381 | N22: Sector-specific pathway; EU N/Q/X availability × AE feedstock share
A23: EU | B23: 9b | C23: Methanation from CO2 and green H2 | D23: e-Methane (RFNBO) | E23: Maritime-e 2040/ 2050 | F23: {=IFERROR(SUMPRODUCT(($A$34:$A$135=$A23)*($B$34:$B$135=$B23)*($C$34:$C$135=$D23)*($D$34:$D$135=$E23)*$H$34:$H$135*$M$34:$M$135)/SUMIFS($H$34:$H$135,$A$34:$A$135,$A23,$B$34:$B$135,$B23,$C$34:$C$135,$D23,$D$34:$D$135,$E23),0)} -> 2.4 | G23: {=IFERROR(SUMPRODUCT(($A$34:$A$135=$A23)*($B$34:$B$135=$B23)*($C$34:$C$135=$D23)*($D$34:$D$135=$E23)*$I$34:$I$135*$M$34:$M$135)/SUMIFS($I$34:$I$135,$A$34:$A$135,$A23,$B$34:$B$135,$B23,$C$34:$C$135,$D23,$D$34:$D$135,$E23),0)} -> 2.4 | H23: {=IFERROR(SUMPRODUCT(($A$34:$A$135=$A23)*($B$34:$B$135=$B23)*($C$34:$C$135=$D23)*($D$34:$D$135=$E23)*$K$34:$K$135*$M$34:$M$135)/SUMIFS($K$34:$K$135,$A$34:$A$135,$A23,$B$34:$B$135,$B23,$C$34:$C$135,$D23,$D$34:$D$135,$E23),0)} -> 2.4 | I23: {=IFERROR(SUMPRODUCT(($A$34:$A$135=$A23)*($B$34:$B$135=$B23)*($C$34:$C$135=$D23)*($D$34:$D$135=$E23)*$J$34:$J$135*$M$34:$M$135)/SUMIFS($J$34:$J$135,$A$34:$A$135,$A23,$B$34:$B$135,$B23,$C$34:$C$135,$D23,$D$34:$D$135,$E23),0)} -> 2.4 | J23: =SUMIFS($H$34:$H$135,$A$34:$A$135,$A23,$B$34:$B$135,$B23,$C$34:$C$135,$D23,$D$34:$D$135,$E23) -> 16.34 | K23: =SUMIFS($I$34:$I$135,$A$34:$A$135,$A23,$B$34:$B$135,$B23,$C$34:$C$135,$D23,$D$34:$D$135,$E23) -> 16.34 | L23: =SUMIFS($J$34:$J$135,$A$34:$A$135,$A23,$B$34:$B$135,$B23,$C$34:$C$135,$D23,$D$34:$D$135,$E23) -> 32.195 | M23: =SUMIFS($K$34:$K$135,$A$34:$A$135,$A23,$B$34:$B$135,$B23,$C$34:$C$135,$D23,$D$34:$D$135,$E23) -> 64.875 | N23: Sector-specific pathway; EU N/Q/X availability × AE feedstock share
A24: EU | B24: 11a | C24: Gasification and FT-Synthesis | D24: Biodiesel | E24: Road-bio | F24: {=IFERROR(SUMPRODUCT(($A$34:$A$135=$A24)*($B$34:$B$135=$B24)*($C$34:$C$135=$D24)*($D$34:$D$135=$E24)*$H$34:$H$135*$M$34:$M$135)/SUMIFS($H$34:$H$135,$A$34:$A$135,$A24,$B$34:$B$135,$B24,$C$34:$C$135,$D24,$D$34:$D$135,$E24),0)} -> 8.6212619 | G24: {=IFERROR(SUMPRODUCT(($A$34:$A$135=$A24)*($B$34:$B$135=$B24)*($C$34:$C$135=$D24)*($D$34:$D$135=$E24)*$I$34:$I$135*$M$34:$M$135)/SUMIFS($I$34:$I$135,$A$34:$A$135,$A24,$B$34:$B$135,$B24,$C$34:$C$135,$D24,$D$34:$D$135,$E24),0)} -> 8.433562 | H24: {=IFERROR(SUMPRODUCT(($A$34:$A$135=$A24)*($B$34:$B$135=$B24)*($C$34:$C$135=$D24)*($D$34:$D$135=$E24)*$K$34:$K$135*$M$34:$M$135)/SUMIFS($K$34:$K$135,$A$34:$A$135,$A24,$B$34:$B$135,$B24,$C$34:$C$135,$D24,$D$34:$D$135,$E24),0)} -> 8.6991543 | I24: {=IFERROR(SUMPRODUCT(($A$34:$A$135=$A24)*($B$34:$B$135=$B24)*($C$34:$C$135=$D24)*($D$34:$D$135=$E24)*$J$34:$J$135*$M$34:$M$135)/SUMIFS($J$34:$J$135,$A$34:$A$135,$A24,$B$34:$B$135,$B24,$C$34:$C$135,$D24,$D$34:$D$135,$E24),0)} -> 8.9675213 | J24: =SUMIFS($H$34:$H$135,$A$34:$A$135,$A24,$B$34:$B$135,$B24,$C$34:$C$135,$D24,$D$34:$D$135,$E24) -> 20.877791 | K24: =SUMIFS($I$34:$I$135,$A$34:$A$135,$A24,$B$34:$B$135,$B24,$C$34:$C$135,$D24,$D$34:$D$135,$E24) -> 29.472069 | L24: =SUMIFS($J$34:$J$135,$A$34:$A$135,$A24,$B$34:$B$135,$B24,$C$34:$C$135,$D24,$D$34:$D$135,$E24) -> 35.227045 | M24: =SUMIFS($K$34:$K$135,$A$34:$A$135,$A24,$B$34:$B$135,$B24,$C$34:$C$135,$D24,$D$34:$D$135,$E24) -> 85.576905 | N24: Sector-specific pathway; EU N/Q/X availability × AE feedstock share
A25: EU | B25: 11a | C25: Gasification and FT-Synthesis | D25: FT-SPK | E25: Aviation-bio | F25: {=IFERROR(SUMPRODUCT(($A$34:$A$135=$A25)*($B$34:$B$135=$B25)*($C$34:$C$135=$D25)*($D$34:$D$135=$E25)*$H$34:$H$135*$M$34:$M$135)/SUMIFS($H$34:$H$135,$A$34:$A$135,$A25,$B$34:$B$135,$B25,$C$34:$C$135,$D25,$D$34:$D$135,$E25),0)} -> 8.6212619 | G25: {=IFERROR(SUMPRODUCT(($A$34:$A$135=$A25)*($B$34:$B$135=$B25)*($C$34:$C$135=$D25)*($D$34:$D$135=$E25)*$I$34:$I$135*$M$34:$M$135)/SUMIFS($I$34:$I$135,$A$34:$A$135,$A25,$B$34:$B$135,$B25,$C$34:$C$135,$D25,$D$34:$D$135,$E25),0)} -> 8.433562 | H25: {=IFERROR(SUMPRODUCT(($A$34:$A$135=$A25)*($B$34:$B$135=$B25)*($C$34:$C$135=$D25)*($D$34:$D$135=$E25)*$K$34:$K$135*$M$34:$M$135)/SUMIFS($K$34:$K$135,$A$34:$A$135,$A25,$B$34:$B$135,$B25,$C$34:$C$135,$D25,$D$34:$D$135,$E25),0)} -> 8.6991543 | I25: {=IFERROR(SUMPRODUCT(($A$34:$A$135=$A25)*($B$34:$B$135=$B25)*($C$34:$C$135=$D25)*($D$34:$D$135=$E25)*$J$34:$J$135*$M$34:$M$135)/SUMIFS($J$34:$J$135,$A$34:$A$135,$A25,$B$34:$B$135,$B25,$C$34:$C$135,$D25,$D$34:$D$135,$E25),0)} -> 8.9675213 | J25: =SUMIFS($H$34:$H$135,$A$34:$A$135,$A25,$B$34:$B$135,$B25,$C$34:$C$135,$D25,$D$34:$D$135,$E25) -> 20.877791 | K25: =SUMIFS($I$34:$I$135,$A$34:$A$135,$A25,$B$34:$B$135,$B25,$C$34:$C$135,$D25,$D$34:$D$135,$E25) -> 29.472069 | L25: =SUMIFS($J$34:$J$135,$A$34:$A$135,$A25,$B$34:$B$135,$B25,$C$34:$C$135,$D25,$D$34:$D$135,$E25) -> 35.227045 | M25: =SUMIFS($K$34:$K$135,$A$34:$A$135,$A25,$B$34:$B$135,$B25,$C$34:$C$135,$D25,$D$34:$D$135,$E25) -> 85.576905 | N25: Sector-specific pathway; EU N/Q/X availability × AE feedstock share
