Workbook

Sheet Prices per feedstock & per IVC
A1: This sheet is mostly redundant since the price data is in th "feedstock MIX price per IVC " sheet. But references and Eurostat mapping in here
A2: Prices of feedstocks
B4: Eurostat sector | C4: Share per feedstock of overall feedstock mix (2030 medium) | D4: Share per feedstock of overall feedstock mix (2030 high) | E4: Price estimate [€/t] | F4: Source | G4: Share distribution of feedstocks within IVC 2030 | H4: Share distribution of feedstocks within IVC 2050 | I4: share feedstock costs | J4: CAPEX [€/t] | K4: share CAPEX | L4: OPEX [€/t] | M4: share OPEX | N4: OVERALL costs
A5: IVC 1 | E5: 520 | I5: =E5/N5 -> 0.59770115 | J5: 83 | K5: =J5/N5 -> 0.095402299 | L5: 267 | M5: =L5/N5 -> 0.30689655 | N5: =E5+J5+L5 -> 870
A6: Oil crops abandoned, degraded, intercropping | B6: A01: Products of agriculture, hunting and related services | D6: 1 | E6: 520 €/t | F6: Study 2, p. 124 | G6: 1 | H6: 1
A7: IVC 2 - HVO | C7: =SUM(C8:C10) -> 1 | D7: =SUM(D8:D10) -> 1 | E7: =D8*E8+D10*E10 -> 87.837631 | I7: =E7/N7 -> 0.11529705 | J7: 269 | K7: =J7/N7 -> 0.35309361 | L7: 405 | M7: =L7/N7 -> 0.53160934 | N7: =E7+J7+L7 -> 761.83763
A8: Oil crops abandoned, degraded, intercropping | B8: A01: Products of agriculture, hunting and related services | C8: 0 | D8: 0 | E8: 520 | F8: Study 2, p. 124
A9: Tall Oil | C9: ='[2]Availabilities EU Austria'!$N$13/'[2]Availabilities EU Austria'!$N$10 -> 0.063011547 | D9: ='[2]Availabilities EU Austria'!$Q$13/'[2]Availabilities EU Austria'!$Q$10 -> 0.089199177 | E9: ??
A10: Intermediate Bioenergy carriers (biocrude, FPBO) | B10: C20: Chemicals and chemical products | C10: =('[2]Availabilities EU Austria'!$N$15+'[2]Availabilities EU Austria'!$N$14)/'[2]Availabilities EU Austria'!$N$10 -> 0.93698845 | D10: =('[2]Availabilities EU Austria'!$Q$14+'[2]Availabilities EU Austria'!$Q$15)/'[2]Availabilities EU Austria'!$Q$10 -> 0.91080082 | E10: 96.44 | F10: CHECK
A11: IVC 2 - HEFA | C11: =SUM(C12:C14) -> 1 | D11: =SUM(D12:D14) -> 1 | E11: =D12*E12+D14*E14 -> 137.72093 | I11: =E11/N11 -> 0.12755234 | J11: 376 | K11: =J11/N11 -> 0.34823813 | L11: 566 | M11: =L11/N11 -> 0.52420953 | N11: =E11+J11+L11 -> 1079.7209
A12: Oil crops abandoned, degraded, intercropping | B12: A01: Products of agriculture, hunting and related services | C12: ='[2]Availabilities EU Austria'!$N$21/'[2]Availabilities EU Austria'!$N$16 -> 0.072434801 | D12: ='[2]Availabilities EU Austria'!$Q$21/'[2]Availabilities EU Austria'!$Q$16 -> 0.11542722 | E12: 520 | F12: Study 2, p. 124
A13: Tall oil | C13: ='[2]Availabilities EU Austria'!$N$23/'[2]Availabilities EU Austria'!$N$16 -> 0.058447318 | D13: ='[2]Availabilities EU Austria'!$Q$23/'[2]Availabilities EU Austria'!$Q$16 -> 0.078903164 | E13: ?
A14: Intermediate Bioenergy carriers (biocrude, FPBO) | B14: C20: Chemicals and chemical products | C14: =('[2]Availabilities EU Austria'!$N$24+'[2]Availabilities EU Austria'!$N$25)/'[2]Availabilities EU Austria'!$N$16 -> 0.86911788 | D14: =('[2]Availabilities EU Austria'!$Q$24+'[2]Availabilities EU Austria'!$Q$25)/'[2]Availabilities EU Austria'!$Q$16 -> 0.80566962 | E14: 96.44
A15: IVC 5 | C15: =SUM(C16:C19) -> 1 | D15: =SUM(D16:D19) -> 1 | E15: =D16*E16+D17*E17+D18*E18+D19*E19 -> 60.376239
A16: Straw | B16: A01: Products of agriculture, hunting and related services | C16: ='[2]Availabilities EU Austria'!$N$27/'[2]Availabilities EU Austria'!$N$26 -> 0.73688393 | D16: ='[2]Availabilities EU Austria'!$Q$27/'[2]Availabilities EU Austria'!$Q$26 -> 0.74789495 | E16: 58 | F16: Study 2, p. 97
A17: Lignocrops abandoned degraded | B17: A01: Products of agriculture, hunting and related services | C17: ='[2]Availabilities EU Austria'!$N$28/'[2]Availabilities EU Austria'!$N$26 -> 0.028841348 | D17: ='[2]Availabilities EU Austria'!$Q$28/'[2]Availabilities EU Austria'!$Q$26 -> 0.031508836 | E17: 69 | F17: Study 2, p. 193
A18: Lignocrops inter & cover cropping | B18: A01: Products of agriculture, hunting and related services | C18: ='[2]Availabilities EU Austria'!$N$29/'[2]Availabilities EU Austria'!$N$26 -> 0.013130549 | D18: ='[2]Availabilities EU Austria'!$Q$29/'[2]Availabilities EU Austria'!$Q$26 -> 0.022137974 | E18: 69 | F18: Study 2, p. 193
A19: Secondary forest residues | B19: C17 Paper and paper products (en) | C19: ='[2]Availabilities EU Austria'!$N$30/'[2]Availabilities EU Austria'!$N$26 -> 0.22114418 | D19: ='[2]Availabilities EU Austria'!$Q$30/'[2]Availabilities EU Austria'!$Q$26 -> 0.19845824 | E19: 67
A20: IVC 6 | E20: =D21*E21 -> 96.44
A21: Intermediate Bioenergy carrier (ethanol, methanol) | B21: C20: Chemicals and chemical products | C21: 1 | D21: 1 | E21: 96.44
A22: IVC 7 | C22: =SUM(C23:C31) -> 1 | D22: =SUM(D23:D31) -> 1 | E22: =D23*E23+D24*E24+D25*E25+D26*E26+D27*E27+D28*E28+D29*E29+D30*E30+D31*E31 -> 30.965299
A23: Prunings & damaged crops (olive stones excluded) | B23: A01: Products of agriculture, hunting and related services | C23: ='[2]Availabilities EU Austria'!$N$41/'[2]Availabilities EU Austria'!$N$40 -> 0.030601718 | D23: ='[2]Availabilities EU Austria'!$Q$41/'[2]Availabilities EU Austria'!$Q$40 -> 0.03010511 | E23: 44 | F23: Study 2, p. 111
A24: Lignocrops abandoned degraded | B24: A01: Products of agriculture, hunting and related services | C24: ='[2]Availabilities EU Austria'!$N$42/'[2]Availabilities EU Austria'!$N$40 -> 0.018454385 | D24: ='[2]Availabilities EU Austria'!$Q$42/'[2]Availabilities EU Austria'!$Q$40 -> 0.021462821 | E24: 69 | F24: Study 2, p. 193 | G24: =0.21/2 -> 0.105
A25: Lignocrops inter & cover cropping | B25: A01: Products of agriculture, hunting and related services | C25: ='[2]Availabilities EU Austria'!$N$43/'[2]Availabilities EU Austria'!$N$40 -> 0.0084016949 | D25: ='[2]Availabilities EU Austria'!$Q$43/'[2]Availabilities EU Austria'!$Q$40 -> 0.015079687 | E25: 69 | F25: Study 2, p. 193 | G25: =0.21/2 -> 0.105
A26: Agroprocessing residues | B26: CPA_C10-12 (Food, beverages and tobacco products) | C26: ='[2]Availabilities EU Austria'!$N$44/'[2]Availabilities EU Austria'!$N$40 -> 0.023575445 | D26: ='[2]Availabilities EU Austria'!$Q$44/'[2]Availabilities EU Austria'!$Q$40 -> 0.024015373 | E26: 44 | F26: Study 2, p. 111 | G26: 0.24
A27: Straw | B27: A01: Products of agriculture, hunting and related services (en); A01.1: non-perennial crops | C27: ='[2]Availabilities EU Austria'!$N$45/'[2]Availabilities EU Austria'!$N$40 -> 0.47150152 | D27: ='[2]Availabilities EU Austria'!$Q$45/'[2]Availabilities EU Austria'!$Q$40 -> 0.50944236 | E27: 58
A28: Manure | B28: A01: Products of agriculture, hunting and related services; A01.4: Live animals and animal products | C28: ='[2]Availabilities EU Austria'!$N$46/'[2]Availabilities EU Austria'!$N$40 -> 0.347493 | D28: ='[2]Availabilities EU Austria'!$Q$46/'[2]Availabilities EU Austria'!$Q$40 -> 0.3159246 | E28: 0 | G28: 0.32
A29: Sewage sludge | B29: Sewerage services; sewage sludge; waste collection, treatment and disposal services; materials recovery services; remediation services and other waste management services | C29: ='[2]Availabilities EU Austria'!$N$47/'[2]Availabilities EU Austria'!$N$40 -> 0.031761184 | D29: ='[2]Availabilities EU Austria'!$Q$47/'[2]Availabilities EU Austria'!$Q$40 -> 0.024204717 | E29: 0
A30: Biowastes (post consumer woods excluded) | B30: Sewerage services; sewage sludge; waste collection, treatment and disposal services; materials recovery services; remediation services and other waste management services | C30: ='[2]Availabilities EU Austria'!$N$48/'[2]Availabilities EU Austria'!$N$40 -> 0.065902037 | D30: ='[2]Availabilities EU Austria'!$Q$48/'[2]Availabilities EU Austria'!$Q$40 -> 0.05819089 | E30: =-(55+70)/2 -> -62.5 | F30: Study 2, annex 4, page 40 | H30: wird hier das Minuszeichen richtig in die Formel übernommen?
A31: Intermediate Bioenergy carrier (crude glycerine) | B31: C20: Chemicals and chemical products | C31: ='[2]Availabilities EU Austria'!$N$49/'[2]Availabilities EU Austria'!$N$40 -> 0.0023090105 | D31: ='[2]Availabilities EU Austria'!$Q$49/'[2]Availabilities EU Austria'!$Q$40 -> 0.0015744344 | E31: 96.44 | F31: CETO 2026, p. 29
A32: IVC 8a | C32: =SUM(C33:C42) -> 1 | D32: =SUM(D33:D42) -> 1 | E32: =D33*E33+D34*E34+D35*E35+D36*E36+D37*E37+D38*E38+D39*E39+D40*E40+D41*E41+D42*E42 -> 57.287316
A33: Straw | B33: A01: Products of agriculture, hunting and related services (en); A01.1: non-perennial crops | C33: ='[2]Availabilities EU Austria'!$N$61/'[2]Availabilities EU Austria'!$N$60 -> 0.5178381 | D33: ='[2]Availabilities EU Austria'!$Q$61/'[2]Availabilities EU Austria'!$Q$60 -> 0.56804069 | E33: 58
A34: Prunings & damaged crops | B34: A01: Products of agriculture, hunting and related services | C34: ='[2]Availabilities EU Austria'!$N$62/'[2]Availabilities EU Austria'!$N$60 -> 0.033609087 | D34: ='[2]Availabilities EU Austria'!$Q$62/'[2]Availabilities EU Austria'!$Q$60 -> 0.033570732 | E34: 44
A35: Sewage sludge | B35: E: WATER SUPPLY; SEWERAGE, WASTE MANAGEMENT AND REMEDIATION SERVICES (en); E37: Sewage services, sewage sludge | C35: ='[2]Availabilities EU Austria'!$N$63/'[2]Availabilities EU Austria'!$N$60 -> 0.034882499 | D35: ='[2]Availabilities EU Austria'!$Q$63/'[2]Availabilities EU Austria'!$Q$60 -> 0.026988851 | E35: 0 | F35: CHECK
A36: Agroprocessing residues - maize cobs | B36: CPA_C10-12 (Food, beverages and tobacco products) | C36: ='[2]Availabilities EU Austria'!$N$64/'[2]Availabilities EU Austria'!$N$60 -> 0.013662908 | D36: ='[2]Availabilities EU Austria'!$Q$64/'[2]Availabilities EU Austria'!$Q$60 -> 0.014187521 | E36: 44
A37: Lignocrops abandoned degraded | B37: A01: Products of agriculture, hunting and related services | C37: ='[2]Availabilities EU Austria'!$N$65/'[2]Availabilities EU Austria'!$N$60 -> 0.020267981 | D37: ='[2]Availabilities EU Austria'!$Q$65/'[2]Availabilities EU Austria'!$Q$60 -> 0.02393157 | E37: 69
A38: Lignocrops inter & cover cropping | B38: A01: Products of agriculture, hunting and related services | C38: ='[2]Availabilities EU Austria'!$N$66/'[2]Availabilities EU Austria'!$N$60 -> 0.0092273673 | D38: ='[2]Availabilities EU Austria'!$Q$66/'[2]Availabilities EU Austria'!$Q$60 -> 0.01681422 | E38: 69
A39: Primary forestry residues | B39: A02: Products of forestry, logging and related services (en) | C39: ='[2]Availabilities EU Austria'!$N$67/'[2]Availabilities EU Austria'!$N$60 -> 0.14802813 | D39: ='[2]Availabilities EU Austria'!$Q$67/'[2]Availabilities EU Austria'!$Q$60 -> 0.10247464 | E39: 69 | F39: CHECK
A40: Secondary forest residues | B40: C MANUFACTURED PRODUCTS, C17: Paper and paper products (en) | C40: ='[2]Availabilities EU Austria'!$N$68/'[2]Availabilities EU Austria'!$N$60 -> 0.15540695 | D40: ='[2]Availabilities EU Austria'!$Q$68/'[2]Availabilities EU Austria'!$Q$60 -> 0.15073288 | E40: 69 | F40: CHECK
A41: Biowastes - Post consumer wood | B41: E WATER SUPPLY; SEWERAGE, WASTE MANAGEMENT AND REMEDIATION SERVICES (en) | C41: ='[2]Availabilities EU Austria'!$N$69/'[2]Availabilities EU Austria'!$N$60 -> 0.046552014 | D41: ='[2]Availabilities EU Austria'!$Q$69/'[2]Availabilities EU Austria'!$Q$60 -> 0.042968416 | E41: 0 | F41: CHECK
...

Sheet LCoP CONVENTIONAL
B1: TOTAL absolute costs [€/ t product] | C1: Feedstock share | E1: Absolute feedstock costs [€/t product] | F1: CAPEX share | H1: Absolute CAPEX | I1: OPEX share | K1: Absolute OPEX | L1: Share of feedstock CETO report 2026, p. 27) | M1: Origin | N1: Price of 1t of feedstock [€/t] | O1: Converison factor [t product/ t feedstock] | P1: Feestock cost to produce 1t of fuel | Q1: NEW share of feedstock mix 2030 medium (taking into account the feedstock split in 2030) | R1: money [€] spent on each feedtsock when producing 1t of product (and weighted feedstock mix cost) | S1: NEW share of feedstock mix 2030 high (taking into account the feedstock split in 2030) | T1: money [€] spent on each feedtsock when producing 1t of product (and weighted feedstock mix cost) | U1: NOTES
A2: Conventional biodiesel | H2: for now just any number
A3: transesterification of food/feed crops | C3: 0.75 | D3: money [€] spent on each feedtsock when producing 1t of product | F3: 0.065 | G3: =SUM(G4:G8) -> 1 | H3: 1000000 | I3: 0.185 | J3: =SUM(J4:J9) -> 1 | L3: =SUM(L4:L7) -> 0.48
B4: primarily EU | C4: Rapeseed oil | D4: ='Feedtstocks only CONVENTIONAL'!I4 -> 354.464 | E4: 0.76 | F4: Machinery and equipment | G4: 0.45 | H4: =G4*H$3 -> 450000 | I4: Chemical and chemical products | J4: 0.3 | L4: 0.38 | M4: primarily EU
B5: imported | C5: Soybean oil | D5: ='Feedtstocks only CONVENTIONAL'!I5 -> 74.624 | E5: 0.16 | F5: Architectural and engineering services | G5: 0.3 | H5: =G5*H$3 -> 300000 | I5: Electricity, gas, steam & AC | J5: 0.2 | L5: 0.08 | M5: imported
B6: pirmarily EU | C6: Sunflower oil | D6: ='Feedtstocks only CONVENTIONAL'!I6 -> 18.656 | E6: 0.04 | F6: Constructions and construction works | G6: 0.15 | H6: =G6*H$3 -> 150000 | I6: Legal and accounting services; services of head offices; management consultancy services | J6: 0.25 | L6: 0.02
B7: imported | C7: Palm oil | D7: ='Feedtstocks only CONVENTIONAL'!I7 -> 18.333333 | E7: 0.04 | F7: Fabricated metal products | G7: 0.07 | H7: =G7*H$3 -> 70000 | I7: Repair and installation services | J7: 0.15
F8: Computer, electronic and optical products | G8: 0.03 | H8: =G8*H$3 -> 30000 | I8: Land transport services and transport services via pipelines | J8: 0.1
I9: Waster management services | J9: 0
A10: transesterification of cover crops from marginal lands | C10: 0.7 | F10: 0.07 | G10: =SUM(G11:G15) -> 1 | H10: 1000000 | I10: 0.23 | J10: =SUM(J11:J16) -> 1
F11: Machinery and equipment | G11: 0.48 | H11: =G11*H$10 -> 480000 | I11: Chemical and chemical products | J11: 0.25
F12: Architectural and engineering services | G12: 0.3 | H12: =G12*H$10 -> 300000 | I12: Electricity, gas, steam & AC | J12: 0.15
F13: Constructions and construction works | G13: 0.12 | H13: =G13*H$10 -> 120000 | I13: Legal and accounting services; services of head offices; management consultancy services | J13: 0.2
F14: Fabricated metal products | G14: 0.07 | H14: =G14*H$10 -> 70000 | I14: Repair and installation services | J14: 0.15
F15: Computer, electronic and optical products | G15: 0.03 | H15: =G15*H$10 -> 30000 | I15: Land transport services and transport services via pipelines | J15: 0.25
I16: Waster management services | J16: 0
A17: transesterification of UCO and AF | B17: =E17+H17+K17 -> 1253 | C17: =E17/B17 -> 0.72067039 | E17: 903 | F17: =H17/B17 -> 0.066241022 | G17: =SUM(G18:G22) -> 1 | H17: 83 | I17: =K17/B17 -> 0.21308859 | J17: =SUM(J18:J23) -> 1 | K17: 267
C18: UCO imported | D18: =0.6618*0.6 -> 0.39708 | E18: =D18*E17 -> 358.56324 | F18: Machinery and equipment | G18: 0.5 | H18: =G18*H$17 -> 41.5 | I18: Chemical and chemical products | J18: 0.25 | K18: =J18*K$17 -> 66.75 | N18: 880
C19: UCO domestic | D19: =0.6618*0.4 -> 0.26472 | E19: =D19*E18 -> 94.918861 | F19: Architectural and engineering services | G19: 0.3 | H19: =G19*H$17 -> 24.9 | I19: Electricity, gas, steam & AC | J19: 0.15 | K19: =J19*K$17 -> 40.05
C20: Animal Fat | D20: 0.3382 | E20: =D20*E19 -> 32.101559 | F20: Constructions and construction works | G20: 0.1 | H20: =G20*H$17 -> 8.3 | I20: Legal and accounting services; services of head offices; management consultancy services | J20: 0.2 | K20: =J20*K$17 -> 53.4
F21: Fabricated metal products | G21: 0.07 | H21: =G21*H$17 -> 5.81 | I21: Repair and installation services | J21: 0.2 | K21: =J21*K$17 -> 53.4
F22: Computer, electronic and optical products | G22: 0.03 | H22: =G22*H$17 -> 2.49 | I22: Land transport services and transport services via pipelines | J22: 0.1 | K22: =J22*K$17 -> 26.7
I23: Waster management services | J23: 0.1 | K23: =J23*K$17 -> 26.7
A24: hydrotreatment of food/feed crops | C24: 0.7 | F24: 0.1 | G24: =SUM(G25:G29) -> 1 | I24: 0.2 | J24: =SUM(J25:J30) -> 1
F25: Machinery and equipment | G25: 0.55 | I25: Chemical and chemical products | J25: 0.4
F26: Architectural and engineering services | G26: 0.25 | I26: Electricity, gas, steam & AC | J26: 0.2
F27: Constructions and construction works | G27: 0.1 | I27: Legal and accounting services; services of head offices; management consultancy services | J27: 0.2
F28: Fabricated metal products | G28: 0.07 | I28: Repair and installation services | J28: 0.15
F29: Computer, electronic and optical products | G29: 0.03 | I29: Land transport services and transport services via pipelines | J29: 0.05
I30: Waster management services | J30: 0
A31: hydrotreatment of cover crops from marginal lands (non-aviation part) | C31: 0.64 | F31: 0.14 | G31: =SUM(G32:G36) -> 1 | I31: 0.22 | J31: =SUM(J32:J37) -> 1
F32: Machinery and equipment | G32: 0.58 | I32: Chemical and chemical products | J32: 0.35
F33: Architectural and engineering services | G33: 0.25 | I33: Electricity, gas, steam & AC | J33: 0.15
F34: Constructions and construction works | G34: 0.08 | I34: Legal and accounting services; services of head offices; management consultancy services | J34: 0.18
F35: Fabricated metal products | G35: 0.06 | I35: Repair and installation services | J35: 0.15
F36: Computer, electronic and optical products | G36: 0.03 | I36: Land transport services and transport services via pipelines | J36: 0.17
I37: Waster management services | J37: 0
A38: HVO (road) hydrotreatment of UCO and AF | B38: =E38+H38+K38 -> 2016 | C38: =E38/B38 -> 0.6656746 | E38: 1342 | F38: =H38/B38 -> 0.13343254 | G38: =SUM(G39:G43) -> 1 | H38: 269 | I38: =K38/B38 -> 0.20089286 | J38: =SUM(J39:J44) -> 1 | K38: 405
B39: 60% imported | C39: UCO | F39: Machinery and equipment | G39: 0.6 | H39: =G39*H$38 -> 161.4 | I39: Chemical and chemical products | J39: 0.15 | K39: =J39*K$38 -> 60.75
B40: domestic | C40: Animal fat | F40: Architectural and engineering services | G40: 0.25 | H40: =G40*H$38 -> 67.25 | I40: Electricity, gas, steam & AC | J40: 0.4 | K40: =J40*K$38 -> 162
...

Sheet 2023 costs
B1: marrket price | C1: market value asbolute [€/t] | D1: in Mtoe | E1: Conversion factor [t/toe] | F1: in t | G1: Cost of production [€/t] | H1: Cost spent per IVC | I1: Feedstock share of costs | J1: Eurostat sector | K1: money [€] spent on each feedtsock when producing 1t of product | L1: Absolute feedstock costs [€] | M1: CAPEX share of costs | N1: CAPEX distribution | O1: Absoluet CAPEX [€] | P1: OPEX share of costs | R1: Absolute OPEX [€] | S1: ENTIRE production costs
A2: Advanced biodiesel
A3: TOTAL | C3: =SUM(C4:C18) -> 2.0926449e+09 | D3: =D4+D11+D18 -> 1.3 | F3: =SUM(F4:F18) -> 1443203.4 | H3: =SUM(H4:H18) -> 1.480528e+10 | L3: =L4+L11+L18 -> 1.4236257e+10 | O3: =O4+O11+O18 -> 1.5900413e+08 | R3: =R4+R11+R18 -> 4.1001916e+08
A4: of which IVC 1 | B4: 1450 | C4: =B4*F4 -> 1.8704812e+09 | D4: 1.14 | E4: ='[2]Conversion factors selected IV '!$O$4 -> 1.1315676 | F4: =D4*E4*1000000 -> 1289987 | G4: ='LCoP 2030 MEDIUM'!E24 -> 10350 | H4: =F4*G4 -> 1.3351366e+10 | I4: ='LCoP 2030 MEDIUM'!H24 -> 0.96618357 | L4: =I4*H4 -> 1.289987e+10 | M4: ='LCoP 2030 MEDIUM'!F24 -> 0.0080193237 | O4: =M4*H4 -> 1.0706892e+08 | P4: ='LCoP 2030 MEDIUM'!G24 -> 0.025797101 | R4: =P4*H4 -> 3.4442654e+08 | S4: =L4+O4+R4 -> 1.3351366e+10
H5: imported | I5: POME | J5: Food, beverages and tobacco products | K5: 850 | L5: =K5*F4 -> 1.096489e+09 | M5: Fabricated metal products | N5: 0.05 | O5: =N5*O$4 -> 5353446.2 | P5: Electricity, gas, steam and air conditioning | Q5: 0.35 | R5: =Q5*R$4 -> 1.2054929e+08
M6: Electrical equipment | N6: 0.02 | O6: =N6*O$4 -> 2141378.5 | P6: Chemicals and chemical products | Q6: 0.25 | R6: =Q6*R$4 -> 86106634
M7: Machinery and equipment n.e.c. | N7: 0.45 | O7: =N7*O$4 -> 48181015 | P7: Legal and accounting services; services of head offices; management consultancy services | Q7: 0.2 | R7: =Q7*R$4 -> 68885307
M8: Constructions and construction works | N8: 0.15 | O8: =N8*O$4 -> 16060338 | P8: Repair and installation services of machinery and equipment | Q8: 0.15 | R8: =Q8*R$4 -> 51663980
M9: Architectural and engineering services; technical testing and analysis services | N9: 0.3 | O9: =N9*O$4 -> 32120677 | P9: Land transport services and transport services via pipelines | Q9: 0.05 | R9: =Q9*R$4 -> 17221327
M10: Computer, electronic and optical products | N10: 0.03 | O10: =N10*O$4 -> 3212067.7 | Q10: =SUM(Q5:Q9) -> 1 | R10: =SUM(R5:R9) -> 3.4442654e+08
A11: of which IVC 2 | B11: 1450 | C11: =B11*F11 -> 1.9316373e+08 | D11: 0.14 | E11: ='[2]Conversion factors selected IV '!$O$7 -> 0.95154545 | F11: =D11*E11*1000000 -> 133216.36 | G11: ='LCoP 2030 MEDIUM'!E25 -> 10674 | H11: =F11*G11 -> 1.4219515e+09 | I11: ='LCoP 2030 MEDIUM'!H25 -> 0.93685591 | L11: =I11*H11 -> 1.3321636e+09 | M11: ='LCoP 2030 MEDIUM'!F25 -> 0.025201424 | N11: =SUM(N12:N17) -> 1 | O11: =M11*H11 -> 35835202 | P11: ='LCoP 2030 MEDIUM'!G25 -> 0.037942664 | R11: =P11*H11 -> 53952627 | S11: =L11+O11+R11 -> 1.4219515e+09
H12: imported | I12: POME | J12: Food, beverages and tobacco products | K12: 850 | L12: =K12*F11 -> 1.1323391e+08 | M12: Fabricated metal products | N12: 0.05 | O12: =N12*O$11 -> 1791760.1 | P12: Electricity, gas, steam and air conditioning | Q12: 0.35 | R12: =Q12*R$11 -> 18883420
M13: Electrical equipment | N13: 0.02 | O13: =N13*O$11 -> 716704.04 | P13: Chemicals and chemical products | Q13: 0.25 | R13: =Q13*R$11 -> 13488157
M14: Machinery and equipment n.e.c. | N14: 0.45 | O14: =N14*O$11 -> 16125841 | P14: Legal and accounting services; services of head offices; management consultancy services | Q14: 0.2 | R14: =Q14*R$11 -> 10790525
M15: Constructions and construction works | N15: 0.15 | O15: =N15*O$11 -> 5375280.3 | P15: Repair and installation services of machinery and equipment | Q15: 0.15 | R15: =Q15*R$11 -> 8092894.1
M16: Architectural and engineering services; technical testing and analysis services | N16: 0.3 | O16: =N16*O$11 -> 10750561 | P16: Land transport services and transport services via pipelines | Q16: 0.05 | R16: =Q16*R$11 -> 2697631.4
M17: Computer, electronic and optical products | N17: 0.03 | O17: =N17*O$11 -> 1075056.1 | Q17: =SUM(Q12:Q16) -> 1 | R17: =SUM(R12:R16) -> 53952627
A18: of which IVC 13a | B18: 1450 | C18: =B18*F18 -> 29000000 | D18: 0.02 | E18: ='[2]Conversion factors selected IV '!$O$98 -> 1 | F18: =D18*E18*1000000 -> 20000 | G18: ='LCoP 2030 MEDIUM'!E20 -> 1598.1345 | H18: =F18*G18 -> 31962689 | I18: ='LCoP 2030 MEDIUM'!H20 -> 0.13211308 | L18: =SUM(L19:L26) -> 4222689.2 | M18: ='LCoP 2030 MEDIUM'!F20 -> 0.50371231 | O18: =M18*H18 -> 16100000 | P18: ='LCoP 2030 MEDIUM'!G20 -> 0.36417461 | R18: =P18*H18 -> 11640000 | S18: =L18+O18+R18 -> 31962689
A19: I am assuming the feedstock split to be as in 2030 medium | G19: of which | H19: domestic | I19: Straw | J19: Products of agriculture, hunting and related services | K19: ='Feedstock MIX per IVC'!G89 -> 104.52294 | L19: =K19*F$18 -> 2090458.8 | M19: Fabricated metal products | N19: 0.15 | O19: =N19*O$18 -> 2415000 | P19: Electricity, gas, steam and air conditioning | Q19: 0.15 | R19: =Q19*R$18 -> 1746000
H20: domestic | I20: Prunings & damaged crops | J20: Products of agriculture, hunting and related services | K20: ='Feedstock MIX per IVC'!G90 -> 6.0040708 | L20: =K20*F$18 -> 120081.42 | M20: Electrical equipment | N20: 0.02 | O20: =N20*O$18 -> 322000 | P20: Chemicals and chemical products | Q20: 0.25 | R20: =Q20*R$18 -> 2910000
H21: domestic | I21: Agroprocessing residues - maize cobs | J21: Food, beverages and tobacco products | K21: ='Feedstock MIX per IVC'!G91 -> 2.9289602 | L21: =K21*F$18 -> 58579.204 | M21: Machinery and equipment n.e.c. | N21: 0.45 | O21: =N21*O$18 -> 7245000 | P21: Legal and accounting services; services of head offices; management consultancy services | Q21: 0.2 | R21: =Q21*R$18 -> 2328000
H22: domestic | I22: Lignocrops abandoned degraded | J22: Products of agriculture, hunting and related services | K22: ='Feedstock MIX per IVC'!G92 -> 4.8668638 | L22: =K22*F$18 -> 97337.275 | M22: Constructions and construction works | N22: 0.1 | O22: =N22*O$18 -> 1610000 | P22: Repair and installation services of machinery and equipment | Q22: 0.3 | R22: =Q22*R$18 -> 3492000
H23: domestic | I23: Lignocrops inter & cover cropping | J23: Products of agriculture, hunting and related services | K23: ='Feedstock MIX per IVC'!G93 -> 2.2157284 | L23: =K23*F$18 -> 44314.568 | M23: Architectural and engineering services; technical testing and analysis services | N23: 0.25 | O23: =N23*O$18 -> 4025000 | P23: Land transport services and transport services via pipelines | Q23: 0.1 | R23: =Q23*R$18 -> 1164000
H24: domestic | I24: Primary forestry residues | J24: Products of forestry, logging and related services | K24: ='Feedstock MIX per IVC'!G94 -> 48.32109 | L24: =K24*F$18 -> 966421.8 | M24: Computer, electronic and optical products | N24: 0.03 | O24: =N24*O$18 -> 483000 | Q24: =SUM(Q19:Q23) -> 1 | R24: =SUM(R19:R23) -> 11640000
H25: domestic | I25: Secondary forest residues | J25: Paper and paper products | K25: ='Feedstock MIX per IVC'!G95 -> 42.274808 | L25: =K25*F$18 -> 845496.15
H26: domestic | I26: Biowastes - Post consumer wood | J26: Sewerage services; sewage sludge; waste collection, treatment and disposal services; materials recovery services; remediation services and other waste management services | K26: ='Feedstock MIX per IVC'!G96 -> 0 | L26: =K26*F$18 -> 0 | M26: =K26*F$18 -> 0
J28: TOTALS domestic | L28: =SUM(L29:L34) -> 4222689.2 | M28: TOTALS | O28: =SUM(O29:O34) -> 1.5900413e+08 | R28: =SUM(R29:R33) -> 4.1001916e+08 | S28: =S4+S11+S18 -> 1.480528e+10
J29: Products of agriculture, hunting and related services | L29: =L19+L20+L22+L23 -> 2352192.1 | M29: Fabricated metal products | O29: =O5+O12+O19 -> 9560206.3 | P29: Electricity, gas, steam and air conditioning | R29: =R5+R12+R19 -> 1.4117871e+08
J30: Paper and paper products | L30: =L25 -> 845496.15 | M30: Electrical equipment | O30: =O6+O13+O20 -> 3180082.5 | P30: Chemicals and chemical products | R30: =R6+R13+R20 -> 1.0250479e+08
G31: or does that rather come from a biofuels sector directly? | J31: Chemicals and chemical products | L31: =L13 -> 0 | M31: Machinery and equipment n.e.c. | O31: =O7+O14+O21 -> 71551856 | P31: Legal and accounting services; services of head offices; management consultancy services | R31: =R7+R14+R21 -> 82003833
J32: Food, beverages and tobacco products | L32: =L21 -> 58579.204 | M32: Constructions and construction works | O32: =O8+O15+O22 -> 23045619 | P32: Repair and installation services of machinery and equipment | R32: =R8+R15+R22 -> 63248875
J33: Sewerage services; sewage sludge; waste collection, treatment and disposal services; materials recovery services; remediation services and other waste management services | L33: =L26 -> 0 | M33: Architectural and engineering services; technical testing and analysis services | O33: =O9+O16+O23 -> 46896238 | P33: Land transport services and transport services via pipelines | R33: =R9+R16+R23 -> 21082958
J34: Products of forestry, logging and related services | L34: =L24 -> 966421.8 | M34: Computer, electronic and optical products | O34: =O10+O17+O24 -> 4770123.8
J35: TOTAL imported | L35: =L36 -> 1.2097229e+09
J36: Food, beverages and tobacco products | L36: =L12+L5 -> 1.2097229e+09
J37: ALL | L37: =L35+L28 -> 1.2139456e+09 | M37: =L28+L37+O28+R28 -> 1.7871915e+09 | N37: =M37/1000000 -> 1787.1915
A38: Advanced biogasoline
A39: TOTAL | C39: =SUM(C40:C47) -> 2.3058667e+08 | D39: =SUM(D40:D47) -> 0.15 | F39: =SUM(F40:F47) -> 221586.67 | H39: =SUM(H40:H47) -> 3.1124595e+08 | L39: =L40+L47 -> 67606625 | O39: =O40+O47 -> 127980600 | R39: =R40+R47 -> 115658720
A40: of which IVC 5 | B40: 1000 | C40: =B40*F40 -> 2.0158667e+08 | D40: 0.13 | E40: ='[2]Conversion factors selected IV '!$O$18 -> 1.5506667 | F40: =D40*E40*1000000 -> 201586.67 | G40: ='LCoP 2030 MEDIUM'!E5 -> 1385.4252 | H40: =F40*G40 -> 2.7928326e+08 | I40: ='LCoP 2030 MEDIUM'!H5 -> 0.22695215 | L40: =I40*H40 -> 63383936 | M40: ='LCoP 2030 MEDIUM'!F5 -> 0.40059902 | O40: =M40*H40 -> 111880600 | P40: ='LCoP 2030 MEDIUM'!G5 -> 0.37244882 | R40: =P40*H40 -> 104018720 | S40: =L40+O40+R40 -> 2.7928326e+08
H41: domestic | I41: Straw | J41: Products of agriculture, hunting and related services | K41: ='Feedstock MIX per IVC'!G13 -> 228.35941 | L41: =K41*F$40 -> 46034213 | M41: Fabricated metal products | N41: 0 | O41: =N41*O$40 -> 0 | P41: Electricity, gas, steam and air conditioning | Q41: 0.2 | R41: =Q41*R$40 -> 20803744
...

Sheet 2030 costs Sc 1
A1: Contribution of each IVC to final product in Scenario (1) 2030
A2: Assumptions:
A3: technical capacity = cmc | E3: feedstock availability: 2030 medium
A4: Market value of ALLL biofule production | C4: =C6+C196+C225+C274+C283 -> 3.7066586e+10
B5: market price [€/t] | C5: makret value of overall amount produced | D5: produced in Mtoe | E5: Conversion factor [t/toe] | F5: produced in t | G5: Cost of production [€/t] | H5: Money spent on each IVC | I5: Feedstock share of costs | J5: Eurostat sector | K5: money [€] spent on each feedtsock when producing 1t of product | L5: Absolute feedstock costs [€] | M5: CAPEX share of costs | N5: CAPEX distribution | O5: Absoluet CAPEX [€] | P5: OPEX share of costs | R5: Absolute OPEX [€] | S5: TOTAL production costs
A6: SUMME ALL advanced | C6: =C8+C44+C86+C120+C154 -> 1.0819763e+10 | D6: =D8+D44+D86+D120+D154 -> 7.3763477
A7: Advanced biodiesel
A8: TOTAL | B8: =C8/1000000 -> 3061.585 | C8: =C9+C23+C16 -> 3.061585e+09 | D8: =D9+D23+D43+D16 -> 1.8575045 | F8: =F9+F23+F16 -> 2040905.7 | H8: =H9+H23+H16 -> 2.7528869e+09 | L8: =L9+L16+L23 -> 1.8846907e+09 | O8: =O9+O16+O23+#REF! -> #REF! | R8: =R9+R16+R23+#REF! -> #REF!
A9: of which IVC 1 | B9: 1450 | C9: =B9*F9 -> 2.465e+09 | D9: ='[1]GAP analysis Sc. 1'!$P$55+'[1]GAP analysis Sc. 1'!$P$68 -> 1.5023407 | E9: ='[2]Conversion factors selected IV '!$O$4 -> 1.1315676 | F9: =D9*E9*1000000 -> 1700000 | G9: ='LCoP 2030 MEDIUM'!E2 -> 1350 | H9: =G9*F9 -> 2.295e+09 | I9: ='LCoP 2030 MEDIUM'!H2 -> 0.74074074 | L9: =I9*H9 -> 1.7e+09 | M9: ='LCoP 2030 MEDIUM'!F2 -> 0.061481481 | O9: =M9*H9 -> 1.411e+08 | P9: ='LCoP 2030 MEDIUM'!G2 -> 0.19777778 | R9: =P9*H9 -> 4.539e+08 | S9: =SUM(S10:S15) -> 0 | T9: =L9+O9+R9 -> 2.295e+09
C10: =C9/C8 -> 0.80513852 | H10: imported | I10: POME | J10: Food, beverages and tobacco products | K10: 1000 | L10: =K10*F9 -> 1.7e+09 | M10: Fabricated metal products | N10: 0.05 | O10: =N10*O$9 -> 7055000 | P10: Electricity, gas, steam and air conditioning | Q10: 0.35 | R10: =Q10*R$9 -> 1.58865e+08
M11: Electrical equipment | N11: 0.02 | O11: =N11*O$9 -> 2822000 | P11: Chemicals and chemical products | Q11: 0.25 | R11: =Q11*R$9 -> 1.13475e+08
M12: Machinery and equipment n.e.c. | N12: 0.45 | O12: =N12*O$9 -> 63495000 | P12: Legal and accounting services; services of head offices; management consultancy services | Q12: 0.2 | R12: =Q12*R$9 -> 90780000
M13: Constructions and construction works | N13: 0.15 | O13: =N13*O$9 -> 21165000 | P13: Repair and installation services of machinery and equipment | Q13: 0.15 | R13: =Q13*R$9 -> 68085000
M14: Architectural and engineering services; technical testing and analysis services | N14: 0.3 | O14: =N14*O$9 -> 42330000 | P14: Land transport services and transport services via pipelines | Q14: 0.05 | R14: =Q14*R$9 -> 22695000
M15: Computer, electronic and optical products | N15: 0.03 | O15: =N15*O$9 -> 4233000
A16: of which IVC 2 HVO | B16: 1750 | C16: =B16*F16 -> 4.9e+08 | D16: ='[1]GAP analysis Sc. 1'!$P$56+'[1]GAP analysis Sc. 1'!$P$69 -> 0.29425814 | E16: ='[2]Conversion factors selected IV '!$O$7 -> 0.95154545 | F16: =D16*E16*1000000 -> 280000 | G16: ='LCoP 2030 MEDIUM'!E3 -> 1287.6835 | H16: =G16*F16 -> 3.6055137e+08 | I16: ='LCoP 2030 MEDIUM'!H3 -> 0.47657943 | L16: =I16*H16 -> 1.7183137e+08 | M16: ='LCoP 2030 MEDIUM'!F3 -> 0.20890227 | O16: =M16*H16 -> 75320000 | P16: ='LCoP 2030 MEDIUM'!G3 -> 0.31451829 | R16: =P16*H16 -> 1.134e+08 | S16: =L16+O16+R16 -> 3.6055137e+08
C17: =C16/C8 -> 0.16004782 | H17: domestic | I17: Tall oil | J17: Products of agriculture, hunting and related services | K17: ='Feedstock MIX per IVC'!G6 -> 88.966549 | L17: =K17*$F$16 -> 24910634 | M17: Fabricated metal products | N17: 0.05 | O17: =N17*O$16 -> 3766000 | P17: Electricity, gas, steam and air conditioning | Q17: 0.35 | R17: =Q17*R$16 -> 39690000
I18: FPBO (Intermediate bioenergy carrier) | J18: Advanced biodiesel | K18: ='Feedstock MIX per IVC'!G7*0.85 -> 446.00937 | L18: =K18*$F$16 -> 1.2488262e+08 | M18: Electrical equipment | N18: 0.02 | O18: =N18*O$16 -> 1506400 | P18: Chemicals and chemical products | Q18: 0.25 | R18: =Q18*R$16 -> 28350000
I19: biocrude (Intermediate Bioenergy carrier) | J19: Chemicals and chemical products | K19: ='Feedstock MIX per IVC'!G7*0.15 -> 78.707535 | L19: =K19*$F$16 -> 22038110 | M19: Machinery and equipment n.e.c. | N19: 0.45 | O19: =N19*O$16 -> 33894000 | P19: Legal and accounting services; services of head offices; management consultancy services | Q19: 0.2 | R19: =Q19*R$16 -> 22680000
L20: =SUM(L17:L19) -> 1.7183137e+08 | M20: Constructions and construction works | N20: 0.15 | O20: =N20*O$16 -> 11298000 | P20: Repair and installation services of machinery and equipment | Q20: 0.15 | R20: =Q20*R$16 -> 17010000
M21: Architectural and engineering services; technical testing and analysis services | N21: 0.3 | O21: =N21*O$16 -> 22596000 | P21: Land transport services and transport services via pipelines | Q21: 0.05 | R21: =Q21*R$16 -> 5670000
M22: Computer, electronic and optical products | N22: 0.03 | O22: =N22*O$16 -> 2259600
A23: of which 13a (half) | B23: 1750 | C23: =B23*F23 -> 1.0658498e+08 | D23: ='[1]GAP analysis Sc. 1'!$P$57 -> 0.060905704 | E23: ='[2]Conversion factors selected IV '!$O$89 -> 1 | F23: =D23*E23*1000000 -> 60905.704 | G23: ='LCoP 2030 MEDIUM'!E20 -> 1598.1345 | H23: =G23*F23 -> 97335504 | I23: ='LCoP 2030 MEDIUM'!H20 -> 0.13211308 | L23: =I23*H23 -> 12859293 | M23: ='LCoP 2030 MEDIUM'!F20 -> 0.50371231 | O23: =M23*H23 -> 49029091 | P23: ='LCoP 2030 MEDIUM'!G20 -> 0.36417461 | R23: =P23*H23 -> 35447120 | S23: =L23+O23+R23 -> 97335504
C24: =C23/C8 -> 0.034813661 | F24: Products of agriculture, hunting and related services | G24: =L27/L21 -> #DIV/0! | H24: domestic | I24: Straw | J24: Products of agriculture, hunting and related services | K24: ='Feedstock MIX per IVC'!G89 -> 104.52294 | L24: =K24*F$23 -> 6366043.2 | M24: Fabricated metal products | N24: 0.15 | O24: =N24*O$23 -> 7354363.7 | P24: Electricity, gas, steam and air conditioning | Q24: 0.15 | R24: =Q24*R$23 -> 5317067.9
F25: Food, beverages and tobacco products | G25: =L26/L23 -> 0.013872488 | H25: domestic | I25: Prunings & damaged crops | J25: Products of agriculture, hunting and related services | K25: ='Feedstock MIX per IVC'!G90 -> 6.0040708 | L25: =K25*F$23 -> 365682.16 | M25: Electrical equipment | N25: 0.02 | O25: =N25*O$23 -> 980581.83 | P25: Chemicals and chemical products | Q25: 0.25 | R25: =Q25*R$23 -> 8861779.9
F26: Products of forestry, logging and related services | G26: =L29/L23 -> 0.22886406 | H26: domestic | I26: Agroprocessing residues - maize cobs | J26: Food, beverages and tobacco products | K26: ='Feedstock MIX per IVC'!G91 -> 2.9289602 | L26: =K26*F$23 -> 178390.38 | M26: Machinery and equipment n.e.c. | N26: 0.45 | O26: =N26*O$23 -> 22063091 | P26: Legal and accounting services; services of head offices; management consultancy services | Q26: 0.2 | R26: =Q26*R$23 -> 7089423.9
F27: Paper and paper products | G27: =L30/L23 -> 0.20022694 | H27: domestic | I27: Lignocrops abandoned degraded | J27: Products of agriculture, hunting and related services | K27: ='Feedstock MIX per IVC'!G92 -> 4.8668638 | L27: =K27*F$23 -> 296419.76 | M27: Constructions and construction works | N27: 0.1 | O27: =N27*O$23 -> 4902909.1 | P27: Repair and installation services of machinery and equipment | Q27: 0.3 | R27: =Q27*R$23 -> 10634136
F28: Sewerage services; sewage sludge; waste collection, treatment and disposal services; materials recovery services; remediation services and other waste management services | G28: =L31/L23 -> 0 | H28: domestic | I28: Lignocrops inter & cover cropping | J28: Products of agriculture, hunting and related services | K28: ='Feedstock MIX per IVC'!G93 -> 2.2157284 | L28: =K28*F$23 -> 134950.5 | M28: Architectural and engineering services; technical testing and analysis services | N28: 0.25 | O28: =N28*O$23 -> 12257273 | P28: Land transport services and transport services via pipelines | Q28: 0.1 | R28: =Q28*R$23 -> 3544712
H29: domestic | I29: Primary forestry residues | J29: Products of forestry, logging and related services | K29: ='Feedstock MIX per IVC'!G94 -> 48.32109 | L29: =K29*F$23 -> 2943030 | M29: Computer, electronic and optical products | N29: 0.03 | O29: =N29*O$23 -> 1470872.7 | Q29: =SUM(Q24:Q28) -> 1
H30: domestic | I30: Secondary forest residues | J30: Paper and paper products | K30: ='Feedstock MIX per IVC'!G95 -> 42.274808 | L30: =K30*F$23 -> 2574776.9
H31: domestic | I31: Biowastes - Post consumer wood | J31: Sewerage services; sewage sludge; waste collection, treatment and disposal services; materials recovery services; remediation services and other waste management services | K31: ='Feedstock MIX per IVC'!G96 -> 0 | L31: =K31*F$23 -> 0
I32: SUM | L32: =SUM(L34:L42) -> 1.8846907e+09 | S32: =SUM(S34:S42) -> #REF!
I33: TOTALS domestic | M33: TOTALS | O33: =SUM(O34:O39) -> #REF! | P33: TOTALS | R33: =SUM(R34:R38) -> #REF! | S33: CHECKED; ALL FINE
J34: Products of agriculture, hunting and related services | L34: =SUMIF($J$17:$J$31, J34, $L$17:$L$31) -> 32073729 | M34: Fabricated metal products | O34: =O10+O17+#REF!+O24 -> #REF! | P34: Electricity, gas, steam and air conditioning | R34: =R10+R17+R24+#REF! -> #REF! | S34: =R34/$H$8 -> #REF!
J35: Products of forestry, logging and related services | L35: =SUMIF($J$17:$J$31, J35, $L$17:$L$31) -> 2943030 | M35: Electrical equipment | O35: =O11+O18+#REF!+O25 -> #REF! | P35: Chemicals and chemical products | R35: =R11+R18+R25+#REF! -> #REF! | S35: =R35/$H$8 -> #REF! | T35: =L32+O33+R33 -> #REF!
J36: Paper and paper products | L36: =SUMIF($J$17:$J$31, J36, $L$17:$L$31) -> 2574776.9 | M36: Machinery and equipment n.e.c. | O36: =O12+O19+#REF!+O26 -> #REF! | P36: Legal and accounting services; services of head offices; management consultancy services | R36: =R12+R19+R26+#REF! -> #REF! | S36: =R36/$H$8 -> #REF!
J37: Food, beverages and tobacco products | L37: =SUMIF($J$17:$J$31, J37, $L$17:$L$31) -> 178390.38 | M37: Constructions and construction works | O37: =O13+O20+#REF!+O27 -> #REF! | P37: Repair and installation services of machinery and equipment | R37: =R13+R20+R27+#REF! -> #REF! | S37: =R37/$H$8 -> #REF!
J38: Sewerage services; sewage sludge; waste collection, treatment and disposal services; materials recovery services; remediation services and other waste management services | L38: =SUMIF($J$17:$J$31, J38, $L$17:$L$31) -> 0 | M38: Architectural and engineering services; technical testing and analysis services | O38: =O14+O21+#REF!+O28 -> #REF! | P38: Land transport services and transport services via pipelines | R38: =R14+R21+R28+#REF! -> #REF! | S38: =R38/$H$8 -> #REF!
J39: Chemicals and chemical products | L39: =SUMIF($J$17:$J$31, J39, $L$17:$L$31) -> 22038110 | M39: Computer, electronic and optical products | O39: =O15+O22+#REF!+O29 -> #REF!
J40: Advanced biodiesel | L40: =SUMIF($J$17:$J$31, J40, $L$17:$L$31) -> 1.2488262e+08
...

Sheet 2030 costs Sc 2
A1: Contribution of each IVC to final product in Scenario (2) 2030
A2: Assumptions:
A3: technical capacity = tcp | E3: feedstock availability: 2030 high
B5: Market value | C5: Makret value of overall amount produced | D5: produced in Mtoe | E5: Conversion factor [t/toe] | F5: produced in t | G5: Cost of production [€/t] | H5: Money spent on each IVC | I5: Feedstock share of costs | J5: Eurostat sector | K5: money [€] spent on each feedtsock when producing 1t of product | L5: Absolute feedstock costs [€] | M5: CAPEX share of costs | N5: CAPEX distribution | O5: Absoluet CAPEX [€] | P5: OPEX share of costs | R5: Absolute OPEX [€] | S5: TOTAL production costs
A6: Sum ALL advanced | D6: =D8+D48+D90+D123+D173 -> 18.590301
A7: Advanced biodiesel
A8: TOTAL | B8: =C8/1000000 -> 9549.6752 | C8: =C28+C9+C16 -> 9.5496752e+09 | D8: =D28+D9+D16 -> 5.6702449 | F8: =F28+F9+F16 -> 5456957.3 | H8: =H28+H9+H16 -> 1.2899645e+10 | L8: =L28+L9+L16 -> 1.6003873e+09 | O8: =O9+O16+O28 -> 6.7243056e+09 | R8: =R9+R16+R28 -> 4.5749518e+09
A9: of which IVC 2 HVO | B9: 1750 | C9: =B9*F9 -> 5.1963933e+08 | D9: ='[1]GAP analysis Sc. 2'!$N$123 -> 0.31205736 | E9: ='[2]Conversion factors selected IV '!$O$7 -> 0.95154545 | F9: =D9*E9*1000000 -> 296936.76 | G9: ='LCoP 2030 HIGH'!E3 -> 1281.9315 | H9: =G9*F9 -> 3.8065259e+08 | I9: ='LCoP 2030 HIGH'!H3 -> 0.47423088 | L9: =I9*H9 -> 1.8051721e+08 | M9: ='LCoP 2030 HIGH'!F3 -> 0.2098396 | O9: =M9*H9 -> 79875988 | P9: ='LCoP 2030 HIGH'!G3 -> 0.31592951 | R9: =P9*H9 -> 1.2025939e+08 | S9: =L9+O9+R9 -> 3.8065259e+08
C10: =C9/C8 -> 0.054414345 | F10: Products of agriculture, hunting and related services | G10: =(SUMIF($J$10:$J$12,F10,$L$10:$L$12)/$L$9) -> 0.21075509 | I10: Tall oil | J10: Products of agriculture, hunting and related services | K10: ='Feedstock MIX per IVC'!J6 -> 128.12466 | L10: =K10*F$9 -> 38044922 | M10: Fabricated metal products | N10: 0.05 | O10: =N10*O$9 -> 3993799.4 | P10: Electricity, gas, steam and air conditioning | Q10: 0.35 | R10: =Q10*R$9 -> 42090786
F11: Advanced biodiesel | G11: =(SUMIF($J$10:$J$12,F11,$L$10:$L$12)/$L$9)/2 -> 0.33542909 | I11: FPBO (Intermediate bioenergy carrier) | J11: Advanced biodiesel | K11: ='Feedstock MIX per IVC'!J7*0.85 -> 407.83583 | L11: =K11*F$9 -> 1.2110145e+08 | M11: Electrical equipment | N11: 0.02 | O11: =N11*O$9 -> 1597519.8 | P11: Chemicals and chemical products | Q11: 0.25 | R11: =Q11*R$9 -> 30064847
F12: Chemicals and chemical products | G12: =(SUMIF($J$10:$J$12,F12,$L$10:$L$12)/$L$9) -> 0.11838674 | I12: biocrude (Intermediate Bioenergy carrier) | J12: Chemicals and chemical products | K12: ='Feedstock MIX per IVC'!J7*0.15 -> 71.971029 | L12: =K12*F$9 -> 21370844 | M12: Machinery and equipment n.e.c. | N12: 0.45 | O12: =N12*O$9 -> 35944195 | P12: Legal and accounting services; services of head offices; management consultancy services | Q12: 0.2 | R12: =Q12*R$9 -> 24051877
F13: Advanced biogasoline | G13: =G11 -> 0.33542909 | M13: Constructions and construction works | N13: 0.15 | O13: =N13*O$9 -> 11981398 | P13: Repair and installation services of machinery and equipment | Q13: 0.15 | R13: =Q13*R$9 -> 18038908
G14: =SUM(G10:G13) -> 1 | M14: Architectural and engineering services; technical testing and analysis services | N14: 0.3 | O14: =N14*O$9 -> 23962796 | P14: Land transport services and transport services via pipelines | Q14: 0.05 | R14: =Q14*R$9 -> 6012969.4
I15: Sum | L15: =SUM(L10:L12) -> 1.8051721e+08 | M15: Computer, electronic and optical products | N15: 0.03 | O15: =N15*O$9 -> 2396279.6
A16: of which IVC 11a (road) | B16: 1750 | C16: =B16*F16 -> 6.8102703e+09 | D16: ='[1]GAP analysis Sc. 2'!$N$124 -> 4.08975 | E16: ='[2]Conversion factors selected IV '!$O$64 -> 0.95154545 | F16: =D16*E16*1000000 -> 3891583 | G16: ='LCoP 2030 HIGH'!E16 -> 2696.299 | H16: =G16*F16 -> 1.0492871e+10 | I16: ='LCoP 2030 HIGH'!H16 -> 0.109891 | L16: =I16*H16 -> 1.1530721e+09 | M16: ='LCoP 2030 HIGH'!F16 -> 0.5359198 | O16: =M16*H16 -> 5.6233375e+09 | P16: ='LCoP 2030 HIGH'!G16 -> 0.35418921 | R16: =P16*H16 -> 3.7164618e+09 | S16: =L16+O16+R16 -> 1.0492871e+10
C17: =C16/C8 -> 0.71314156 | F17: Products of agriculture, hunting and related services | G17: =(SUMIF($J$17:$J$26,F17,$L$17:$L$26)/$L$16) -> 0.62196372 | I17: Straw | J17: Products of agriculture, hunting and related services | K17: ='Feedstock MIX per IVC'!J63 -> 161.99072 | L17: =K17*F$16 -> 6.3040032e+08 | M17: Fabricated metal products | N17: 0 | O17: =N17*O$16 -> 0 | P17: Electricity, gas, steam and air conditioning | Q17: 0.25 | R17: =Q17*R$16 -> 9.2911545e+08
F18: Products of forestry, logging and related services | G18: =(SUMIF($J$17:$J$26,F18,$L$17:$L$26)/$L$16) -> 0.1487034 | I18: Prunings & damaged crops | J18: Products of agriculture, hunting and related services | K18: ='Feedstock MIX per IVC'!J64 -> 8.4731123 | L18: =K18*F$16 -> 32973820 | M18: Electrical equipment | N18: 0.02 | O18: =N18*O$16 -> 1.1246675e+08 | P18: Chemicals and chemical products | Q18: 0.15 | R18: =Q18*R$16 -> 5.5746927e+08
F19: Paper and paper products | G19: =(SUMIF($J$17:$J$26,F19,$L$17:$L$26)/$L$16) -> 0.18227674 | I19: Sewage sludge | J19: Sewerage services; sewage sludge; waste collection, treatment and disposal services; materials recovery services; remediation services and other waste management services | K19: ='Feedstock MIX per IVC'!J65 -> 0 | L19: =K19*F$16 -> 0 | M19: Machinery and equipment n.e.c. | N19: 0.55 | O19: =N19*O$16 -> 3.0928356e+09 | P19: Legal and accounting services; services of head offices; management consultancy services | Q19: 0.3 | R19: =Q19*R$16 -> 1.1149385e+09
F20: Food, beverages and tobacco products | G20: =(SUMIF($J$17:$J$26,F20,$L$17:$L$26)/$L$16) -> 0.014502397 | I20: Agroprocessing residues - maize cobs | J20: Food, beverages and tobacco products | K20: ='Feedstock MIX per IVC'!J66 -> 4.2970453 | L20: =K20*F$16 -> 16722309 | M20: Constructions and construction works | N20: 0.1 | O20: =N20*O$16 -> 5.6233375e+08 | P20: Repair and installation services of machinery and equipment | Q20: 0.3 | R20: =Q20*R$16 -> 1.1149385e+09
F21: Sewerage services; sewage sludge; waste collection, treatment and disposal services; materials recovery services; remediation services and other waste management services | G21: =(SUMIF($J$17:$J$26,F21,$L$17:$L$26)/$L$16) -> 0 | I21: Lignocrops abandoned degraded | J21: Products of agriculture, hunting and related services | K21: ='Feedstock MIX per IVC'!J67 -> 8.1190082 | L21: =K21*F$16 -> 31595795 | M21: Architectural and engineering services; technical testing and analysis services | N21: 0.3 | O21: =N21*O$16 -> 1.6870012e+09 | P21: Land transport services and transport services via pipelines | Q21: 0 | R21: =Q21*R$16 -> 0
F22: Advanced biodiesel | G22: =(SUMIF($J$17:$J$26,F22,$L$17:$L$26)/$L$16)/2 -> 0.016276872 | I22: Lignocrops inter & cover cropping | J22: Products of agriculture, hunting and related services | K22: ='Feedstock MIX per IVC'!J68 -> 5.7043807 | L22: =K22*F$16 -> 22199071 | M22: Computer, electronic and optical products | N22: 0.03 | O22: =N22*O$16 -> 1.6870012e+08
F23: Chemicals and chemical products | G23: =(SUMIF($J$17:$J$26,F23,$L$17:$L$26)/$L$16) -> 0 | I23: Primary forestry residues | J23: Products of forestry, logging and related services | K23: ='Feedstock MIX per IVC'!J69 -> 44.060666 | L23: =K23*F$16 -> 1.7146574e+08
F24: Advanced biogasoline | G24: =G22 -> 0.016276872 | I24: Secondary forest residues | J24: Paper and paper products | K24: ='Feedstock MIX per IVC'!J70 -> 54.008411 | L24: =K24*F$16 -> 2.1017822e+08
G25: =SUM(G17:G24) -> 1 | I25: Biowastes - Post consumer wood | J25: Sewerage services; sewage sludge; waste collection, treatment and disposal services; materials recovery services; remediation services and other waste management services | K25: ='Feedstock MIX per IVC'!J71 -> 0 | L25: =K25*F$16 -> 0
I26: Intermediate Bioenergy carriers (FPBO with lower quality ) | J26: Advanced biodiesel | K26: ='Feedstock MIX per IVC'!J72 -> 9.6456413 | L26: =K26*F$16 -> 37536814
I27: Sum | L27: =SUM(L17:L26) -> 1.1530721e+09
A28: of which 13a (half) | B28: 1750 | C28: =B28*F28 -> 2219765625 | D28: ='[1]GAP analysis Sc. 2'!$N$125 -> 1.2684375 | E28: ='[2]Conversion factors selected IV '!$O$89 -> 1 | F28: =D28*E28*1000000 -> 1268437.5 | G28: ='LCoP 2030 HIGH'!E20 -> 1597.336 | H28: =G28*F28 -> 2.0261209e+09 | I28: ='LCoP 2030 HIGH'!H20 -> 0.13167923 | L28: =I28*H28 -> 2.6679804e+08 | M28: ='LCoP 2030 HIGH'!F20 -> 0.50396411 | O28: =M28*H28 -> 1.0210922e+09 | P28: ='LCoP 2030 HIGH'!G20 -> 0.36435666 | R28: =P28*H28 -> 738230625 | S28: =L28+O28+R28 -> 2.0261209e+09
C29: =C28/C8 -> 0.2324441 | F29: Products of agriculture, hunting and related services | G29: =(SUMIF($J$29:$J$36,F29,$L$29:$L$36)/$L$28) -> 0.62730453 | I29: Straw | J29: Products of agriculture, hunting and related services | K29: ='Feedstock MIX per IVC'!J89 -> 115.98101 | L29: =K29*F$28 -> 1.4711467e+08 | M29: Fabricated metal products | N29: 0.15 | O29: =N29*O$28 -> 1.5316383e+08 | P29: Electricity, gas, steam and air conditioning | Q29: 0.15 | R29: =Q29*R$28 -> 1.1073459e+08
F30: Products of forestry, logging and related services | G30: =(SUMIF($J$29:$J$36,F30,$L$29:$L$36)/$L$28) -> 0.16087373 | I30: Prunings & damaged crops | J30: Products of agriculture, hunting and related services | K30: ='Feedstock MIX per IVC'!J90 -> 6.0665214 | L30: =K30*F$28 -> 7695003.3 | M30: Electrical equipment | N30: 0.02 | O30: =N30*O$28 -> 20421844 | P30: Chemicals and chemical products | Q30: 0.25 | R30: =Q30*R$28 -> 1.8455766e+08
F31: Paper and paper products | G31: =(SUMIF($J$29:$J$36,F31,$L$29:$L$36)/$L$28) -> 0.19719481 | I31: Agroprocessing residues - maize cobs | J31: Food, beverages and tobacco products | K31: ='Feedstock MIX per IVC'!J91 -> 3.0765693 | L31: =K31*F$28 -> 3902435.9 | M31: Machinery and equipment n.e.c. | N31: 0.45 | O31: =N31*O$28 -> 4.5949148e+08 | P31: Legal and accounting services; services of head offices; management consultancy services | Q31: 0.2 | R31: =Q31*R$28 -> 147646125
F32: Food, beverages and tobacco products | G32: =(SUMIF($J$29:$J$36,F32,$L$29:$L$36)/$L$28) -> 0.014626929 | I32: Lignocrops abandoned degraded | J32: Products of agriculture, hunting and related services | K32: ='Feedstock MIX per IVC'!J92 -> 5.8129924 | L32: =K32*F$28 -> 7373417.5 | M32: Constructions and construction works | N32: 0.1 | O32: =N32*O$28 -> 1.0210922e+08 | P32: Repair and installation services of machinery and equipment | Q32: 0.3 | R32: =Q32*R$28 -> 2.2146919e+08
F33: Sewerage services; sewage sludge; waste collection, treatment and disposal services; materials recovery services; remediation services and other waste management services | G33: =(SUMIF($J$29:$J$36,F33,$L$29:$L$36)/$L$28) -> 0 | I33: Lignocrops inter & cover cropping | J33: Products of agriculture, hunting and related services | K33: ='Feedstock MIX per IVC'!J93 -> 4.0841838 | L33: =K33*F$28 -> 5180531.9 | M33: Architectural and engineering services; technical testing and analysis services | N33: 0.25 | O33: =N33*O$28 -> 2.5527305e+08 | P33: Land transport services and transport services via pipelines | Q33: 0.1 | R33: =Q33*R$28 -> 73823062
F34: Advanced biodiesel | G34: =(SUMIF($J$29:$J$36,F34,$L$29:$L$36)/$L$28) -> 0 | I34: Primary forestry residues | J34: Products of forestry, logging and related services | K34: ='Feedstock MIX per IVC'!J94 -> 33.837534 | L34: =K34*F$28 -> 42920797 | M34: Computer, electronic and optical products | N34: 0.03 | O34: =N34*O$28 -> 30632766 | Q34: =SUM(Q29:Q33) -> 1
F35: Chemicals and chemical products | G35: =(SUMIF($J$29:$J$36,F35,$L$29:$L$36)/$L$28) -> 0 | I35: Secondary forest residues | J35: Paper and paper products | K35: ='Feedstock MIX per IVC'!J95 -> 41.477163 | L35: =K35*F$28 -> 52611189
G36: =SUM(G29:G35) -> 1 | I36: Biowastes - Post consumer wood | J36: Sewerage services; sewage sludge; waste collection, treatment and disposal services; materials recovery services; remediation services and other waste management services | K36: ='Feedstock MIX per IVC'!J96 -> 0 | L36: =K36*F$28 -> 0
I37: SUM | L37: =SUM(L29:L36) -> 2.6679804e+08
I38: TOTALS domestic | M38: TOTALS | O38: =SUM(O39:O44) -> 6.7243056e+09 | P38: TOTALS | R38: =SUM(R39:R43) -> 4.5749518e+09 | S38: =SUM(S39:S43) -> 0.35465719
J39: Products of agriculture, hunting and related services | L39: =SUMIF($J$10:$J$36,J39,$L$10:$L$36) -> 9.2257755e+08 | M39: Fabricated metal products | O39: =SUMIF($M$10:$M$36,M39,$O$10:$O$36) -> 1.5715763e+08 | P39: Electricity, gas, steam and air conditioning | R39: =SUMIF($P$10:$P$36,P39,$R$10:$R$36) -> 1.0819408e+09 | S39: =R39/$H$8 -> 0.083873691
J40: Products of forestry, logging and related services | L40: =SUMIF($J$10:$J$36,J40,$L$10:$L$36) -> 2.1438654e+08 | M40: Electrical equipment | O40: =SUMIF($M$10:$M$36,M40,$O$10:$O$36) -> 1.3448611e+08 | P40: Chemicals and chemical products | R40: =SUMIF($P$10:$P$36,P40,$R$10:$R$36) -> 7.7209177e+08 | S40: =R40/$H$8 -> 0.059853723
J41: Paper and paper products | L41: =SUMIF($J$10:$J$36,J41,$L$10:$L$36) -> 2.6278941e+08 | M41: Machinery and equipment n.e.c. | O41: =SUMIF($M$10:$M$36,M41,$O$10:$O$36) -> 3.5882713e+09 | P41: Legal and accounting services; services of head offices; management consultancy services | R41: =SUMIF($P$10:$P$36,P41,$R$10:$R$36) -> 1.2866365e+09 | S41: =R41/$H$8 -> 0.099742013
...

Sheet 2030 costs Sc 3
A1: Contribution of each IVC to final product in Scenario (3) 2030
A2: Assumptions:
A3: technical capacity = no constraints | E3: feedstock availability: 2030 high
D5: produced in Mtoe | E5: Conversion factor [t/toe] | F5: produced in t | G5: Cost of production [€/t] | H5: Money spent on each IVC | I5: Feedstock share of costs | J5: Eurostat sector | K5: money [€] spent on each feedtsock when producing 1t of product | L5: Absolute feedstock costs [€] | M5: CAPEX share of costs | N5: CAPEX distribution | O5: Absoluet CAPEX [€] | P5: OPEX share of costs | R5: Absolute OPEX [€] | S5: TOTAL production costs
A6: Sum ALL advanced | B6: Market price [€(t] | C6: Makret value of overall amount produced | D6: =D8+D48+D90+D123+D163 -> 102.37541
A7: Advanced biodiesel
A8: TOTAL | D8: =D28+D9+D16 -> 10.021837 | F8: =F28+F9+F16 -> 9715725.4 | H8: =H28+H9+H16 -> 2.1491397e+10 | L8: =L28+L9+L16 -> 2.7000504e+09 | O8: =O9+O16+O28 -> 1.1141155e+10 | R8: =R9+R16+R28 -> 7.6501915e+09
A9: of which IVC 2 HVO | B9: 1750 | C9: =B9*F9 -> 7.8465261e+08 | D9: ='[1]GAP analysis Sc. 3'!$J$27 -> 0.47120494 | E9: ='[2]Conversion factors selected IV '!$O$7 -> 0.95154545 | F9: =D9*E9*1000000 -> 448372.92 | G9: ='LCoP 2030 HIGH'!E3 -> 1281.9315 | H9: =G9*F9 -> 5.7478338e+08 | I9: ='LCoP 2030 HIGH'!H3 -> 0.47423088 | L9: =I9*H9 -> 2.7258003e+08 | M9: ='LCoP 2030 HIGH'!F3 -> 0.2098396 | O9: =M9*H9 -> 1.2061232e+08 | P9: ='LCoP 2030 HIGH'!G3 -> 0.31592951 | R9: =P9*H9 -> 1.8159103e+08 | S9: =L9+O9+R9 -> 5.7478338e+08
G10: Products of agriculture, hunting and related services | H10: =L10/L9 -> 0.21075509 | I10: Tall oil | J10: Products of agriculture, hunting and related services | K10: ='Feedstock MIX per IVC'!J6 -> 128.12466 | L10: =K10*F$9 -> 57447629 | M10: Fabricated metal products | N10: 0.05 | O10: =N10*O$9 -> 6030615.8 | P10: Electricity, gas, steam and air conditioning | Q10: 0.35 | R10: =Q10*R$9 -> 63556862
G11: Advanced biodiesel | H11: =L11/L9 -> 0.67085817 | I11: FPBO (Intermediate bioenergy carrier) | J11: Advanced biodiesel | K11: ='Feedstock MIX per IVC'!J7*0.85 -> 407.83583 | L11: =K11*F$9 -> 1.8286254e+08 | M11: Electrical equipment | N11: 0.02 | O11: =N11*O$9 -> 2412246.3 | P11: Chemicals and chemical products | Q11: 0.25 | R11: =Q11*R$9 -> 45397758
G12: Chemicals and chemical products | H12: =L12/L9 -> 0.11838674 | I12: biocrude (Intermediate Bioenergy carrier) | J12: Chemicals and chemical products | K12: ='Feedstock MIX per IVC'!J7*0.15 -> 71.971029 | L12: =K12*F$9 -> 32269860 | M12: Machinery and equipment n.e.c. | N12: 0.45 | O12: =N12*O$9 -> 54275542 | P12: Legal and accounting services; services of head offices; management consultancy services | Q12: 0.2 | R12: =Q12*R$9 -> 36318207
M13: Constructions and construction works | N13: 0.15 | O13: =N13*O$9 -> 18091847 | P13: Repair and installation services of machinery and equipment | Q13: 0.15 | R13: =Q13*R$9 -> 27238655
M14: Architectural and engineering services; technical testing and analysis services | N14: 0.3 | O14: =N14*O$9 -> 36183695 | P14: Land transport services and transport services via pipelines | Q14: 0.05 | R14: =Q14*R$9 -> 9079551.7
I15: Sum | L15: =SUM(L10:L12) -> 2.7258003e+08 | M15: Computer, electronic and optical products | N15: 0.03 | O15: =N15*O$9 -> 3618369.5
A16: of which IVC 11a (road) | B16: 1750 | C16: =B16*F16 -> 9.7352608e+09 | D16: ='[1]GAP analysis Sc. 3'!$J$28 -> 5.8462853 | E16: ='[2]Conversion factors selected IV '!$O$64 -> 0.95154545 | F16: =D16*E16*1000000 -> 5563006.2 | G16: ='LCoP 2030 HIGH'!E16 -> 2696.299 | H16: =G16*F16 -> 1.4999528e+10 | I16: ='LCoP 2030 HIGH'!H16 -> 0.109891 | L16: =I16*H16 -> 1.6483131e+09 | M16: ='LCoP 2030 HIGH'!F16 -> 0.5359198 | O16: =M16*H16 -> 8.0385439e+09 | P16: ='LCoP 2030 HIGH'!G16 -> 0.35418921 | R16: =P16*H16 -> 5.3126709e+09 | S16: =L16+O16+R16 -> 1.4999528e+10
G17: Sewerage services; sewage sludge; waste collection, treatment and disposal services; materials recovery services; remediation services and other waste management services | H17: =SUMIF($J$17:$J$26,G17,$L$17:$L$26)/$L$16 -> 0 | I17: Straw | J17: Products of agriculture, hunting and related services | K17: ='Feedstock MIX per IVC'!J63 -> 161.99072 | L17: =K17*F$16 -> 9.0115536e+08 | M17: Fabricated metal products | N17: 0 | O17: =N17*O$16 -> 0 | P17: Electricity, gas, steam and air conditioning | Q17: 0.25 | R17: =Q17*R$16 -> 1.3281677e+09
G18: Food, beverages and tobacco products | H18: =SUMIF($J$17:$J$26,G18,$L$17:$L$26)/$L$16 -> 0.014502397 | I18: Prunings & damaged crops | J18: Products of agriculture, hunting and related services | K18: ='Feedstock MIX per IVC'!J64 -> 8.4731123 | L18: =K18*F$16 -> 47135976 | M18: Electrical equipment | N18: 0.02 | O18: =N18*O$16 -> 1.6077088e+08 | P18: Chemicals and chemical products | Q18: 0.15 | R18: =Q18*R$16 -> 7.9690063e+08
G19: Products of agriculture, hunting and related services | H19: =SUMIF($J$17:$J$26,G19,$L$17:$L$26)/$L$16 -> 0.62196372 | I19: Sewage sludge | J19: Sewerage services; sewage sludge; waste collection, treatment and disposal services; materials recovery services; remediation services and other waste management services | K19: ='Feedstock MIX per IVC'!J65 -> 0 | L19: =K19*F$16 -> 0 | M19: Machinery and equipment n.e.c. | N19: 0.55 | O19: =N19*O$16 -> 4.4211992e+09 | P19: Legal and accounting services; services of head offices; management consultancy services | Q19: 0.3 | R19: =Q19*R$16 -> 1.5938013e+09
G20: Products of forestry, logging and related services | H20: =SUMIF($J$17:$J$26,G20,$L$17:$L$26)/$L$16 -> 0.1487034 | I20: Agroprocessing residues - maize cobs | J20: Food, beverages and tobacco products | K20: ='Feedstock MIX per IVC'!J66 -> 4.2970453 | L20: =K20*F$16 -> 23904490 | M20: Constructions and construction works | N20: 0.1 | O20: =N20*O$16 -> 8.0385439e+08 | P20: Repair and installation services of machinery and equipment | Q20: 0.3 | R20: =Q20*R$16 -> 1.5938013e+09
G21: Paper and paper products | H21: =SUMIF($J$17:$J$26,G21,$L$17:$L$26)/$L$16 -> 0.18227674 | I21: Lignocrops abandoned degraded | J21: Products of agriculture, hunting and related services | K21: ='Feedstock MIX per IVC'!J67 -> 8.1190082 | L21: =K21*F$16 -> 45166093 | M21: Architectural and engineering services; technical testing and analysis services | N21: 0.3 | O21: =N21*O$16 -> 2.4115632e+09 | P21: Land transport services and transport services via pipelines | Q21: 0 | R21: =Q21*R$16 -> 0
G22: Advanced biodiesel | H22: =SUMIF($J$17:$J$26,G22,$L$17:$L$26)/$L$16 -> 0.032553744 | I22: Lignocrops inter & cover cropping | J22: Products of agriculture, hunting and related services | K22: ='Feedstock MIX per IVC'!J68 -> 5.7043807 | L22: =K22*F$16 -> 31733505 | M22: Computer, electronic and optical products | N22: 0.03 | O22: =N22*O$16 -> 2.4115632e+08
H23: =SUM(H17:H22) -> 1 | I23: Primary forestry residues | J23: Products of forestry, logging and related services | K23: ='Feedstock MIX per IVC'!J69 -> 44.060666 | L23: =K23*F$16 -> 2.4510976e+08
I24: Secondary forest residues | J24: Paper and paper products | K24: ='Feedstock MIX per IVC'!J70 -> 54.008411 | L24: =K24*F$16 -> 3.0044913e+08
