Workbook

Sheet Prices per feedstock & per IVC
A1: This sheet is mostly redundant since the price data is in th "feedstock MIX price per IVC " sheet. But references and Eurostat mapping in here
A2: Prices of feedstocks
B4: Eurostat sector | C4: Share per feedstock of overall feedstock mix (2030 medium) | D4: Share per feedstock of overall feedstock mix (2030 high) | E4: Price estimate [€/t] | F4: Source | G4: Share distribution of feedstocks within IVC 2030 | H4: Share distribution of feedstocks within IVC 2050 | I4: share feedstock costs | J4: CAPEX [€/t] | K4: share CAPEX | L4: OPEX [€/t] | M4: share OPEX | N4: OVERALL costs
A5: IVC 1 | E5: 520 | I5: =E5/N5 -> 0.59770115 | J5: 83 | K5: =J5/N5 -> 0.095402299 | L5: 267 | M5: =L5/N5 -> 0.30689655 | N5: =E5+J5+L5 -> 870
A6: Oil crops abandoned, degraded, intercropping | B6: A01: Products of agriculture, hunting and related services | D6: 1 | E6: 520 €/t | F6: Study 2, p. 124 | G6: 1 | H6: 1
A7: IVC 2 - HVO | C7: =SUM(C8:C10) -> 1 | D7: =SUM(D8:D10) -> 1 | E7: =D8*E8+D10*E10 -> 87.837631 | I7: =E7/N7 -> 0.11529705 | J7: 269 | K7: =J7/N7 -> 0.35309361 | L7: 405 | M7: =L7/N7 -> 0.53160934 | N7: =E7+J7+L7 -> 761.83763
A8: Oil crops abandoned, degraded, intercropping | B8: A01: Products of agriculture, hunting and related services | C8: 0 | D8: 0 | E8: 520 | F8: Study 2, p. 124
A9: Tall Oil | C9: ='[1]Availabilities EU Austria'!$N$13/'[1]Availabilities EU Austria'!$N$10 -> 0.063011547 | D9: ='[1]Availabilities EU Austria'!$Q$13/'[1]Availabilities EU Austria'!$Q$10 -> 0.089199177 | E9: ??
A10: Intermediate Bioenergy carriers (biocrude, FPBO) | B10: C20: Chemicals and chemical products | C10: =('[1]Availabilities EU Austria'!$N$15+'[1]Availabilities EU Austria'!$N$14)/'[1]Availabilities EU Austria'!$N$10 -> 0.93698845 | D10: =('[1]Availabilities EU Austria'!$Q$14+'[1]Availabilities EU Austria'!$Q$15)/'[1]Availabilities EU Austria'!$Q$10 -> 0.91080082 | E10: 96.44 | F10: CHECK
A11: IVC 2 - HEFA | C11: =SUM(C12:C14) -> 1 | D11: =SUM(D12:D14) -> 1 | E11: =D12*E12+D14*E14 -> 137.72093 | I11: =E11/N11 -> 0.12755234 | J11: 376 | K11: =J11/N11 -> 0.34823813 | L11: 566 | M11: =L11/N11 -> 0.52420953 | N11: =E11+J11+L11 -> 1079.7209
A12: Oil crops abandoned, degraded, intercropping | B12: A01: Products of agriculture, hunting and related services | C12: ='[1]Availabilities EU Austria'!$N$21/'[1]Availabilities EU Austria'!$N$16 -> 0.072434801 | D12: ='[1]Availabilities EU Austria'!$Q$21/'[1]Availabilities EU Austria'!$Q$16 -> 0.11542722 | E12: 520 | F12: Study 2, p. 124
A13: Tall oil | C13: ='[1]Availabilities EU Austria'!$N$23/'[1]Availabilities EU Austria'!$N$16 -> 0.058447318 | D13: ='[1]Availabilities EU Austria'!$Q$23/'[1]Availabilities EU Austria'!$Q$16 -> 0.078903164 | E13: ?
A14: Intermediate Bioenergy carriers (biocrude, FPBO) | B14: C20: Chemicals and chemical products | C14: =('[1]Availabilities EU Austria'!$N$24+'[1]Availabilities EU Austria'!$N$25)/'[1]Availabilities EU Austria'!$N$16 -> 0.86911788 | D14: =('[1]Availabilities EU Austria'!$Q$24+'[1]Availabilities EU Austria'!$Q$25)/'[1]Availabilities EU Austria'!$Q$16 -> 0.80566962 | E14: 96.44
A15: IVC 5 | C15: =SUM(C16:C19) -> 1 | D15: =SUM(D16:D19) -> 1 | E15: =D16*E16+D17*E17+D18*E18+D19*E19 -> 60.376239
A16: Straw | B16: A01: Products of agriculture, hunting and related services | C16: ='[1]Availabilities EU Austria'!$N$27/'[1]Availabilities EU Austria'!$N$26 -> 0.73688393 | D16: ='[1]Availabilities EU Austria'!$Q$27/'[1]Availabilities EU Austria'!$Q$26 -> 0.74789495 | E16: 58 | F16: Study 2, p. 97
A17: Lignocrops abandoned degraded | B17: A01: Products of agriculture, hunting and related services | C17: ='[1]Availabilities EU Austria'!$N$28/'[1]Availabilities EU Austria'!$N$26 -> 0.028841348 | D17: ='[1]Availabilities EU Austria'!$Q$28/'[1]Availabilities EU Austria'!$Q$26 -> 0.031508836 | E17: 69 | F17: Study 2, p. 193
A18: Lignocrops inter & cover cropping | B18: A01: Products of agriculture, hunting and related services | C18: ='[1]Availabilities EU Austria'!$N$29/'[1]Availabilities EU Austria'!$N$26 -> 0.013130549 | D18: ='[1]Availabilities EU Austria'!$Q$29/'[1]Availabilities EU Austria'!$Q$26 -> 0.022137974 | E18: 69 | F18: Study 2, p. 193
A19: Secondary forest residues | B19: C17 Paper and paper products (en) | C19: ='[1]Availabilities EU Austria'!$N$30/'[1]Availabilities EU Austria'!$N$26 -> 0.22114418 | D19: ='[1]Availabilities EU Austria'!$Q$30/'[1]Availabilities EU Austria'!$Q$26 -> 0.19845824 | E19: 67
A20: IVC 6 | E20: =D21*E21 -> 96.44
A21: Intermediate Bioenergy carrier (ethanol, methanol) | B21: C20: Chemicals and chemical products | C21: 1 | D21: 1 | E21: 96.44
A22: IVC 7 | C22: =SUM(C23:C31) -> 1 | D22: =SUM(D23:D31) -> 1 | E22: =D23*E23+D24*E24+D25*E25+D26*E26+D27*E27+D28*E28+D29*E29+D30*E30+D31*E31 -> 30.965299
A23: Prunings & damaged crops (olive stones excluded) | B23: A01: Products of agriculture, hunting and related services | C23: ='[1]Availabilities EU Austria'!$N$41/'[1]Availabilities EU Austria'!$N$40 -> 0.030601718 | D23: ='[1]Availabilities EU Austria'!$Q$41/'[1]Availabilities EU Austria'!$Q$40 -> 0.03010511 | E23: 44 | F23: Study 2, p. 111
A24: Lignocrops abandoned degraded | B24: A01: Products of agriculture, hunting and related services | C24: ='[1]Availabilities EU Austria'!$N$42/'[1]Availabilities EU Austria'!$N$40 -> 0.018454385 | D24: ='[1]Availabilities EU Austria'!$Q$42/'[1]Availabilities EU Austria'!$Q$40 -> 0.021462821 | E24: 69 | F24: Study 2, p. 193 | G24: =0.21/2 -> 0.105
A25: Lignocrops inter & cover cropping | B25: A01: Products of agriculture, hunting and related services | C25: ='[1]Availabilities EU Austria'!$N$43/'[1]Availabilities EU Austria'!$N$40 -> 0.0084016949 | D25: ='[1]Availabilities EU Austria'!$Q$43/'[1]Availabilities EU Austria'!$Q$40 -> 0.015079687 | E25: 69 | F25: Study 2, p. 193 | G25: =0.21/2 -> 0.105
A26: Agroprocessing residues | B26: CPA_C10-12 (Food, beverages and tobacco products) | C26: ='[1]Availabilities EU Austria'!$N$44/'[1]Availabilities EU Austria'!$N$40 -> 0.023575445 | D26: ='[1]Availabilities EU Austria'!$Q$44/'[1]Availabilities EU Austria'!$Q$40 -> 0.024015373 | E26: 44 | F26: Study 2, p. 111 | G26: 0.24
A27: Straw | B27: A01: Products of agriculture, hunting and related services (en); A01.1: non-perennial crops | C27: ='[1]Availabilities EU Austria'!$N$45/'[1]Availabilities EU Austria'!$N$40 -> 0.47150152 | D27: ='[1]Availabilities EU Austria'!$Q$45/'[1]Availabilities EU Austria'!$Q$40 -> 0.50944236 | E27: 58
A28: Manure | B28: A01: Products of agriculture, hunting and related services; A01.4: Live animals and animal products | C28: ='[1]Availabilities EU Austria'!$N$46/'[1]Availabilities EU Austria'!$N$40 -> 0.347493 | D28: ='[1]Availabilities EU Austria'!$Q$46/'[1]Availabilities EU Austria'!$Q$40 -> 0.3159246 | E28: 0 | G28: 0.32
A29: Sewage sludge | B29: Sewerage services; sewage sludge; waste collection, treatment and disposal services; materials recovery services; remediation services and other waste management services | C29: ='[1]Availabilities EU Austria'!$N$47/'[1]Availabilities EU Austria'!$N$40 -> 0.031761184 | D29: ='[1]Availabilities EU Austria'!$Q$47/'[1]Availabilities EU Austria'!$Q$40 -> 0.024204717 | E29: 0
A30: Biowastes (post consumer woods excluded) | B30: Sewerage services; sewage sludge; waste collection, treatment and disposal services; materials recovery services; remediation services and other waste management services | C30: ='[1]Availabilities EU Austria'!$N$48/'[1]Availabilities EU Austria'!$N$40 -> 0.065902037 | D30: ='[1]Availabilities EU Austria'!$Q$48/'[1]Availabilities EU Austria'!$Q$40 -> 0.05819089 | E30: =-(55+70)/2 -> -62.5 | F30: Study 2, annex 4, page 40 | H30: wird hier das Minuszeichen richtig in die Formel übernommen?
A31: Intermediate Bioenergy carrier (crude glycerine) | B31: C20: Chemicals and chemical products | C31: ='[1]Availabilities EU Austria'!$N$49/'[1]Availabilities EU Austria'!$N$40 -> 0.0023090105 | D31: ='[1]Availabilities EU Austria'!$Q$49/'[1]Availabilities EU Austria'!$Q$40 -> 0.0015744344 | E31: 96.44 | F31: CETO 2026, p. 29
A32: IVC 8a | C32: =SUM(C33:C42) -> 1 | D32: =SUM(D33:D42) -> 1 | E32: =D33*E33+D34*E34+D35*E35+D36*E36+D37*E37+D38*E38+D39*E39+D40*E40+D41*E41+D42*E42 -> 57.287316
A33: Straw | B33: A01: Products of agriculture, hunting and related services (en); A01.1: non-perennial crops | C33: ='[1]Availabilities EU Austria'!$N$51/'[1]Availabilities EU Austria'!$N$50 -> 0.5178381 | D33: ='[1]Availabilities EU Austria'!$Q$51/'[1]Availabilities EU Austria'!$Q$50 -> 0.56804069 | E33: 58
A34: Prunings & damaged crops | B34: A01: Products of agriculture, hunting and related services | C34: ='[1]Availabilities EU Austria'!$N$52/'[1]Availabilities EU Austria'!$N$50 -> 0.033609087 | D34: ='[1]Availabilities EU Austria'!$Q$52/'[1]Availabilities EU Austria'!$Q$50 -> 0.033570732 | E34: 44
A35: Sewage sludge | B35: E: WATER SUPPLY; SEWERAGE, WASTE MANAGEMENT AND REMEDIATION SERVICES (en); E37: Sewage services, sewage sludge | C35: ='[1]Availabilities EU Austria'!$N$53/'[1]Availabilities EU Austria'!$N$50 -> 0.034882499 | D35: ='[1]Availabilities EU Austria'!$Q$53/'[1]Availabilities EU Austria'!$Q$50 -> 0.026988851 | E35: 0 | F35: CHECK
A36: Agroprocessing residues - maize cobs | B36: CPA_C10-12 (Food, beverages and tobacco products) | C36: ='[1]Availabilities EU Austria'!$N$54/'[1]Availabilities EU Austria'!$N$50 -> 0.013662908 | D36: ='[1]Availabilities EU Austria'!$Q$54/'[1]Availabilities EU Austria'!$Q$50 -> 0.014187521 | E36: 44
A37: Lignocrops abandoned degraded | B37: A01: Products of agriculture, hunting and related services | C37: ='[1]Availabilities EU Austria'!$N$55/'[1]Availabilities EU Austria'!$N$50 -> 0.020267981 | D37: ='[1]Availabilities EU Austria'!$Q$55/'[1]Availabilities EU Austria'!$Q$50 -> 0.02393157 | E37: 69
A38: Lignocrops inter & cover cropping | B38: A01: Products of agriculture, hunting and related services | C38: ='[1]Availabilities EU Austria'!$N$56/'[1]Availabilities EU Austria'!$N$50 -> 0.0092273673 | D38: ='[1]Availabilities EU Austria'!$Q$56/'[1]Availabilities EU Austria'!$Q$50 -> 0.01681422 | E38: 69
A39: Primary forestry residues | B39: A02: Products of forestry, logging and related services (en) | C39: ='[1]Availabilities EU Austria'!$N$57/'[1]Availabilities EU Austria'!$N$50 -> 0.14802813 | D39: ='[1]Availabilities EU Austria'!$Q$57/'[1]Availabilities EU Austria'!$Q$50 -> 0.10247464 | E39: 69 | F39: CHECK
A40: Secondary forest residues | B40: C MANUFACTURED PRODUCTS, C17: Paper and paper products (en) | C40: ='[1]Availabilities EU Austria'!$N$58/'[1]Availabilities EU Austria'!$N$50 -> 0.15540695 | D40: ='[1]Availabilities EU Austria'!$Q$58/'[1]Availabilities EU Austria'!$Q$50 -> 0.15073288 | E40: 69 | F40: CHECK
A41: Biowastes - Post consumer wood | B41: E WATER SUPPLY; SEWERAGE, WASTE MANAGEMENT AND REMEDIATION SERVICES (en) | C41: ='[1]Availabilities EU Austria'!$N$59/'[1]Availabilities EU Austria'!$N$50 -> 0.046552014 | D41: ='[1]Availabilities EU Austria'!$Q$59/'[1]Availabilities EU Austria'!$Q$50 -> 0.042968416 | E41: 0 | F41: CHECK
...

Sheet LCoP CONVENTIONAL
B1: TOTAL absolute costs [€/ t product] | C1: Feedstock share | E1: Absolute feedstock costs [€/t product] | F1: CAPEX share | H1: Absolute CAPEX | I1: OPEX share | K1: Absolute OPEX
A2: Conventional biodiesel
A3: transesterification of food/feed crops | B3: 800 | C3: 0.75 | D3: money [€] spent on each feedtsock when producing 1t of product | E3: =C3*B3 -> 600 | F3: 0.065 | G3: =SUM(G4:G8) -> 1 | H3: =F3*B3 -> 52 | I3: 0.185 | J3: =SUM(J4:J9) -> 1 | K3: =I3*B3 -> 148
B4: primarily EU | C4: Rapeseed oil | D4: ='Feedtstocks only CONVENTIONAL'!I4 -> 354.464 | E4: 0.76 | F4: Machinery and equipment | G4: 0.45 | H4: =G4*$H$3 -> 23.4 | I4: Chemical and chemical products | J4: 0.3 | K4: =J4*$K$3 -> 44.4
B5: imported | C5: Soybean oil | D5: ='Feedtstocks only CONVENTIONAL'!I5 -> 74.624 | E5: 0.16 | F5: Architectural and engineering services | G5: 0.3 | H5: =G5*$H$3 -> 15.6 | I5: Electricity, gas, steam & AC | J5: 0.2 | K5: =J5*$K$3 -> 29.6
B6: primarily EU | C6: Sunflower oil | D6: ='Feedtstocks only CONVENTIONAL'!I6 -> 18.656 | E6: 0.04 | F6: Constructions and construction works | G6: 0.15 | H6: =G6*$H$3 -> 7.8 | I6: Legal and accounting services; services of head offices; management consultancy services | J6: 0.25 | K6: =J6*$K$3 -> 37
B7: imported | C7: Palm oil | D7: ='Feedtstocks only CONVENTIONAL'!I7 -> 18.333333 | E7: 0.04 | F7: Fabricated metal products | G7: 0.07 | H7: =G7*$H$3 -> 3.64 | I7: Repair and installation services | J7: 0.15 | K7: =J7*$K$3 -> 22.2
F8: Computer, electronic and optical products | G8: 0.03 | H8: =G8*$H$3 -> 1.56 | I8: Land transport services and transport services via pipelines | J8: 0.1 | K8: =J8*$K$3 -> 14.8
I9: Waste management services | J9: 0 | K9: =J9*$K$3 -> 0
A10: transesterification of cover crops from marginal lands | B10: =E10+H10+K10 -> 1253 | C10: =E10/B10 -> 0.72067039 | E10: 903 | F10: =H10/B10 -> 0.066241022 | G10: =SUM(G11:G15) -> 1 | H10: 83 | I10: =K10/B10 -> 0.21308859 | J10: =SUM(J11:J16) -> 1 | K10: 267
F11: Machinery and equipment | G11: 0.48 | H11: =G11*$H$10 -> 39.84 | I11: Chemical and chemical products | J11: 0.25 | K11: =J11*$K$10 -> 66.75
F12: Architectural and engineering services | G12: 0.3 | H12: =G12*$H$10 -> 24.9 | I12: Electricity, gas, steam & AC | J12: 0.15 | K12: =J12*$K$10 -> 40.05
F13: Constructions and construction works | G13: 0.12 | H13: =G13*$H$10 -> 9.96 | I13: Legal and accounting services; services of head offices; management consultancy services | J13: 0.2 | K13: =J13*$K$10 -> 53.4
F14: Fabricated metal products | G14: 0.07 | H14: =G14*$H$10 -> 5.81 | I14: Repair and installation services | J14: 0.15 | K14: =J14*$K$10 -> 40.05
F15: Computer, electronic and optical products | G15: 0.03 | H15: =G15*$H$10 -> 2.49 | I15: Land transport services and transport services via pipelines | J15: 0.25 | K15: =J15*$K$10 -> 66.75
I16: Waste management services | J16: 0 | K16: =J16*$K$10 -> 0
A17: transesterification of UCO and AF | B17: 1253 | C17: =E17/$B$17 -> 0.72067039 | E17: 903 | F17: =$H$17/$B$17 -> 0.066241022 | G17: =SUM(G18:G22) -> 1 | H17: 83 | I17: =K17/B17 -> 0.21308859 | J17: =SUM(J18:J23) -> 1 | K17: 267
C18: UCO imported | D18: =0.6618*0.6 -> 0.39708 | E18: =D18*$E$17 -> 358.56324 | F18: Machinery and equipment | G18: 0.5 | H18: =G18*$H$17 -> 41.5 | I18: Chemical and chemical products | J18: 0.25 | K18: =J18*K$17 -> 66.75
C19: UCO domestic | D19: =0.6618*0.4 -> 0.26472 | E19: =D19*$E$17 -> 239.04216 | F19: Architectural and engineering services | G19: 0.3 | H19: =G19*$H$17 -> 24.9 | I19: Electricity, gas, steam & AC | J19: 0.15 | K19: =J19*K$17 -> 40.05
C20: Animal Fat | D20: 0.3382 | E20: =D20*$E$17 -> 305.3946 | F20: Constructions and construction works | G20: 0.1 | H20: =G20*$H$17 -> 8.3 | I20: Legal and accounting services; services of head offices; management consultancy services | J20: 0.2 | K20: =J20*K$17 -> 53.4
F21: Fabricated metal products | G21: 0.07 | H21: =G21*$H$17 -> 5.81 | I21: Repair and installation services | J21: 0.2 | K21: =J21*K$17 -> 53.4
F22: Computer, electronic and optical products | G22: 0.03 | H22: =G22*$H$17 -> 2.49 | I22: Land transport services and transport services via pipelines | J22: 0.1 | K22: =J22*K$17 -> 26.7
I23: Waste management services | J23: 0.1 | K23: =J23*K$17 -> 26.7
A24: hydrotreatment of food/feed crops | B24: =E24+H24+K24 -> 900 | C24: =E24/B24 -> 0.66666667 | E24: 600 | F24: =H24/B24 -> 0.11111111 | G24: =SUM(G25:G29) -> 1 | H24: 100 | I24: =K24/B24 -> 0.22222222 | J24: =SUM(J25:J30) -> 1 | K24: 200
F25: Machinery and equipment | G25: 0.55 | H25: =G25*$H$24 -> 55 | I25: Chemical and chemical products | J25: 0.4 | K25: =J25*$K$24 -> 80
F26: Architectural and engineering services | G26: 0.25 | H26: =G26*$H$24 -> 25 | I26: Electricity, gas, steam & AC | J26: 0.2 | K26: =J26*$K$24 -> 40
F27: Constructions and construction works | G27: 0.1 | H27: =G27*$H$24 -> 10 | I27: Legal and accounting services; services of head offices; management consultancy services | J27: 0.2 | K27: =J27*$K$24 -> 40
F28: Fabricated metal products | G28: 0.07 | H28: =G28*$H$24 -> 7 | I28: Repair and installation services | J28: 0.15 | K28: =J28*$K$24 -> 30
F29: Computer, electronic and optical products | G29: 0.03 | H29: =G29*$H$24 -> 3 | I29: Land transport services and transport services via pipelines | J29: 0.05 | K29: =J29*$K$24 -> 10
I30: Waste management services | J30: 0 | K30: =J30*$K$24 -> 0
A31: hydrotreatment of cover crops from marginal lands (non-aviation part) | B31: =E31+H31+K31 -> 1203 | C31: =E31/B31 -> 0.75062344 | E31: 903 | F31: =H31/$B$31 -> 0.08312552 | G31: =SUM(G32:G36) -> 1 | H31: 100 | I31: =K31/$B$31 -> 0.16625104 | J31: =SUM(J32:J37) -> 1 | K31: 200
F32: Machinery and equipment | G32: 0.58 | H32: =G32*$H$31 -> 58 | I32: Chemical and chemical products | J32: 0.35 | K32: =J32*$K$31 -> 70
F33: Architectural and engineering services | G33: 0.25 | H33: =G33*$H$31 -> 25 | I33: Electricity, gas, steam & AC | J33: 0.15 | K33: =J33*$K$31 -> 30
F34: Constructions and construction works | G34: 0.08 | H34: =G34*$H$31 -> 8 | I34: Legal and accounting services; services of head offices; management consultancy services | J34: 0.18 | K34: =J34*$K$31 -> 36
F35: Fabricated metal products | G35: 0.06 | H35: =G35*$H$31 -> 6 | I35: Repair and installation services | J35: 0.15 | K35: =J35*$K$31 -> 30
F36: Computer, electronic and optical products | G36: 0.03 | H36: =G36*$H$31 -> 3 | I36: Land transport services and transport services via pipelines | J36: 0.17 | K36: =J36*$K$31 -> 34
I37: Waste management services | J37: 0 | K37: =J37*$K$31 -> 0
A38: HVO (road) hydrotreatment of UCO and AF | B38: =E38+H38+K38 -> 2016 | C38: =E38/$B$38 -> 0.6656746 | E38: 1342 | F38: =H38/$B$38 -> 0.13343254 | G38: =SUM(G39:G43) -> 1 | H38: 269 | I38: =K38/$B$38 -> 0.20089286 | J38: =SUM(J39:J44) -> 1 | K38: 405
B39: 60% imported | C39: UCO | F39: Machinery and equipment | G39: 0.6 | H39: =G39*$H$38 -> 161.4 | I39: Chemical and chemical products | J39: 0.15 | K39: =J39*K$38 -> 60.75
B40: domestic | C40: Animal fat | F40: Architectural and engineering services | G40: 0.25 | H40: =G40*$H$38 -> 67.25 | I40: Electricity, gas, steam & AC | J40: 0.4 | K40: =J40*K$38 -> 162
...

Sheet 2023 costs
A1: 2023 | B1: marrket price | C1: market value asbolute [€/t] | D1: in Mtoe | E1: Conversion factor [t/toe] | F1: in t | G1: Cost of production [€/t] | H1: Cost spent per IVC | I1: Feedstock share of costs | J1: Eurostat sector | K1: money [€] spent on each feedtsock when producing 1t of product | L1: Absolute feedstock costs [€] | M1: CAPEX share of costs | N1: CAPEX distribution | O1: Absoluet CAPEX [€] | P1: OPEX share of costs | R1: Absolute OPEX [€] | S1: ENTIRE production costs
A2: Advanced biodiesel
A3: TOTAL | C3: =SUM(C4:C18) -> 2.1386098e+09 | D3: =D4+D11+D18 -> 1.3 | F3: =SUM(F4:F18) -> 1443203.4 | H3: =SUM(H4:H18) -> 1.894285e+09 | L3: =L4+L11+L18 -> 1.4277665e+09 | O3: =O4+O11+O18 -> 1.5900413e+08 | R3: =R4+R11+R18 -> 3.0751437e+08 | S3: =L3+R3 -> 1.7352809e+09
A4: of which IVC 1 | B4: 1450 | C4: =B4*F4 -> 1.8704812e+09 | D4: 1.14 | E4: ='[1]Conversion factors selected IV '!$O$4 -> 1.1315676 | F4: =D4*E4*1000000 -> 1289987 | G4: ='LCoP 2030 MEDIUM'!E2 -> 1283.25 | H4: =F4*G4 -> 1.6553759e+09 | I4: ='LCoP 2030 MEDIUM'!H2 -> 0.77927138 | L4: =I4*H4 -> 1.289987e+09 | M4: ='LCoP 2030 MEDIUM'!F2 -> 0.064679525 | O4: =M4*H4 -> 1.0706892e+08 | P4: ='LCoP 2030 MEDIUM'!G2 -> 0.15604909 | R4: =P4*H4 -> 2.583199e+08 | S4: =L4+O4+R4 -> 1.6553759e+09
H5: imported | I5: POME | J5: Food, beverages and tobacco products | K5: 850 | L5: =K5*F4 -> 1.096489e+09 | M5: Fabricated metal products | N5: 0.05 | O5: =N5*O$4 -> 5353446.2 | P5: Electricity, gas, steam and air conditioning | Q5: 0.35 | R5: =Q5*R$4 -> 90411966
M6: Electrical equipment | N6: 0.02 | O6: =N6*O$4 -> 2141378.5 | P6: Chemicals and chemical products | Q6: 0.25 | R6: =Q6*R$4 -> 64579976
M7: Machinery and equipment n.e.c. | N7: 0.45 | O7: =N7*O$4 -> 48181015 | P7: Legal and accounting services; services of head offices; management consultancy services | Q7: 0.2 | R7: =Q7*R$4 -> 51663980
M8: Constructions and construction works | N8: 0.15 | O8: =N8*O$4 -> 16060338 | P8: Repair and installation services of machinery and equipment | Q8: 0.15 | R8: =Q8*R$4 -> 38747985
M9: Architectural and engineering services; technical testing and analysis services | N9: 0.3 | O9: =N9*O$4 -> 32120677 | P9: Land transport services and transport services via pipelines | Q9: 0.05 | R9: =Q9*R$4 -> 12915995
M10: Computer, electronic and optical products | N10: 0.03 | O10: =N10*O$4 -> 3212067.7 | Q10: =SUM(Q5:Q9) -> 1 | R10: =SUM(R5:R9) -> 2.583199e+08
A11: of which IVC 2 | B11: 1750 | C11: =B11*F11 -> 2.3312864e+08 | D11: 0.14 | E11: ='[1]Conversion factors selected IV '!$O$7 -> 0.95154545 | F11: =D11*E11*1000000 -> 133216.36 | G11: ='LCoP 2030 MEDIUM'!E23 -> 1572.75 | H11: =F11*G11 -> 2.0951604e+08 | I11: ='LCoP 2030 MEDIUM'!H23 -> 0.63582896 | L11: =I11*H11 -> 1.3321636e+08 | M11: ='LCoP 2030 MEDIUM'!F23 -> 0.17103799 | N11: =SUM(N12:N17) -> 1 | O11: =M11*H11 -> 35835202 | P11: ='LCoP 2030 MEDIUM'!G23 -> 0.19313305 | R11: =P11*H11 -> 40464470 | S11: =L11+O11+R11 -> 2.0951604e+08
H12: imported | I12: POME | J12: Food, beverages and tobacco products | K12: 850 | L12: =K12*F11 -> 1.1323391e+08 | M12: Fabricated metal products | N12: 0.05 | O12: =N12*O$11 -> 1791760.1 | P12: Electricity, gas, steam and air conditioning | Q12: 0.35 | R12: =Q12*R$11 -> 14162565
M13: Electrical equipment | N13: 0.02 | O13: =N13*O$11 -> 716704.04 | P13: Chemicals and chemical products | Q13: 0.25 | R13: =Q13*R$11 -> 10116118
M14: Machinery and equipment n.e.c. | N14: 0.45 | O14: =N14*O$11 -> 16125841 | P14: Legal and accounting services; services of head offices; management consultancy services | Q14: 0.2 | R14: =Q14*R$11 -> 8092894.1
M15: Constructions and construction works | N15: 0.15 | O15: =N15*O$11 -> 5375280.3 | P15: Repair and installation services of machinery and equipment | Q15: 0.15 | R15: =Q15*R$11 -> 6069670.6
M16: Architectural and engineering services; technical testing and analysis services | N16: 0.3 | O16: =N16*O$11 -> 10750561 | P16: Land transport services and transport services via pipelines | Q16: 0.05 | R16: =Q16*R$11 -> 2023223.5
M17: Computer, electronic and optical products | N17: 0.03 | O17: =N17*O$11 -> 1075056.1 | Q17: =SUM(Q12:Q16) -> 1 | R17: =SUM(R12:R16) -> 40464470
A18: of which IVC 13a | B18: 1750 | C18: =B18*F18 -> 35000000 | D18: 0.02 | E18: ='[1]Conversion factors selected IV '!$O$98 -> 1 | F18: =D18*E18*1000000 -> 20000 | G18: ='LCoP 2030 MEDIUM'!E19 -> 1469.6575 | H18: =F18*G18 -> 29393151 | I18: ='LCoP 2030 MEDIUM'!H19 -> 0.15524537 | L18: =SUM(L19:L26) -> 4563150.7 | M18: ='LCoP 2030 MEDIUM'!F19 -> 0.54774666 | O18: =M18*H18 -> 16100000 | P18: ='LCoP 2030 MEDIUM'!G19 -> 0.29700797 | R18: =P18*H18 -> 8730000 | S18: =L18+O18+R18 -> 29393151
A19: I am assuming the feedstock split to be as in 2030 medium | G19: of which | H19: domestic | I19: Straw | J19: Products of agriculture, hunting and related services | K19: ='Feedstock MIX per IVC'!G84 -> 117.13778 | L19: =K19*F$18 -> 2342755.5 | M19: Fabricated metal products | N19: 0.15 | O19: =N19*O$18 -> 2415000 | P19: Electricity, gas, steam and air conditioning | Q19: 0.15 | R19: =Q19*R$18 -> 1309500
H20: domestic | I20: Prunings & damaged crops | J20: Products of agriculture, hunting and related services | K20: ='Feedstock MIX per IVC'!G85 -> 6.0040708 | L20: =K20*F$18 -> 120081.42 | M20: Electrical equipment | N20: 0.02 | O20: =N20*O$18 -> 322000 | P20: Chemicals and chemical products | Q20: 0.25 | R20: =Q20*R$18 -> 2182500
H21: domestic | I21: Agroprocessing residues - maize cobs | J21: Food, beverages and tobacco products | K21: ='Feedstock MIX per IVC'!G86 -> 2.9289602 | L21: =K21*F$18 -> 58579.204 | M21: Machinery and equipment n.e.c. | N21: 0.45 | O21: =N21*O$18 -> 7245000 | P21: Legal and accounting services; services of head offices; management consultancy services | Q21: 0.2 | R21: =Q21*R$18 -> 1746000
H22: domestic | I22: Lignocrops abandoned degraded | J22: Products of agriculture, hunting and related services | K22: ='Feedstock MIX per IVC'!G87 -> 4.8668638 | L22: =K22*F$18 -> 97337.275 | M22: Constructions and construction works | N22: 0.1 | O22: =N22*O$18 -> 1610000 | P22: Repair and installation services of machinery and equipment | Q22: 0.3 | R22: =Q22*R$18 -> 2619000
H23: domestic | I23: Lignocrops inter & cover cropping | J23: Products of agriculture, hunting and related services | K23: ='Feedstock MIX per IVC'!G88 -> 2.2157284 | L23: =K23*F$18 -> 44314.568 | M23: Architectural and engineering services; technical testing and analysis services | N23: 0.25 | O23: =N23*O$18 -> 4025000 | P23: Land transport services and transport services via pipelines | Q23: 0.1 | R23: =Q23*R$18 -> 873000
H24: domestic | I24: Primary forestry residues | J24: Products of forestry, logging and related services | K24: ='Feedstock MIX per IVC'!G89 -> 48.32109 | L24: =K24*F$18 -> 966421.8 | M24: Computer, electronic and optical products | N24: 0.03 | O24: =N24*O$18 -> 483000 | Q24: =SUM(Q19:Q23) -> 1 | R24: =SUM(R19:R23) -> 8730000
H25: domestic | I25: Secondary forest residues | J25: Paper and paper products | K25: ='Feedstock MIX per IVC'!G90 -> 41.012873 | L25: =K25*F$18 -> 820257.46
H26: domestic | I26: Biowastes - Post consumer wood | J26: Sewerage services; sewage sludge; waste collection, treatment and disposal services; materials recovery services; remediation services and other waste management services | K26: ='Feedstock MIX per IVC'!G91 -> 5.6701708 | L26: =K26*F$18 -> 113403.42 | M26: =K26*F$18 -> 113403.42
J28: TOTALS domestic | L28: =SUM(L29:L34) -> 4563150.7 | M28: TOTALS | O28: =SUM(O29:O34) -> 1.5900413e+08 | R28: =SUM(R29:R33) -> 3.0751437e+08 | S28: =S4+S11+S18 -> 1.894285e+09
J29: Products of agriculture, hunting and related services | L29: =L19+L20+L22+L23 -> 2604488.8 | M29: Fabricated metal products | O29: =O5+O12+O19 -> 9560206.3 | P29: Electricity, gas, steam and air conditioning | R29: =R5+R12+R19 -> 1.0588403e+08
J30: Paper and paper products | L30: =L25 -> 820257.46 | M30: Electrical equipment | O30: =O6+O13+O20 -> 3180082.5 | P30: Chemicals and chemical products | R30: =R6+R13+R20 -> 76878593
G31: or does that rather come from a biofuels sector directly? | J31: Chemicals and chemical products | L31: =L13 -> 0 | M31: Machinery and equipment n.e.c. | O31: =O7+O14+O21 -> 71551856 | P31: Legal and accounting services; services of head offices; management consultancy services | R31: =R7+R14+R21 -> 61502875
J32: Food, beverages and tobacco products | L32: =L21 -> 58579.204 | M32: Constructions and construction works | O32: =O8+O15+O22 -> 23045619 | P32: Repair and installation services of machinery and equipment | R32: =R8+R15+R22 -> 47436656
J33: Sewerage services; sewage sludge; waste collection, treatment and disposal services; materials recovery services; remediation services and other waste management services | L33: =L26 -> 113403.42 | M33: Architectural and engineering services; technical testing and analysis services | O33: =O9+O16+O23 -> 46896238 | P33: Land transport services and transport services via pipelines | R33: =R9+R16+R23 -> 15812219
J34: Products of forestry, logging and related services | L34: =L24 -> 966421.8 | M34: Computer, electronic and optical products | O34: =O10+O17+O24 -> 4770123.8
J35: TOTAL imported | L35: =L36 -> 1.2097229e+09
J36: Food, beverages and tobacco products | L36: =L12+L5 -> 1.2097229e+09
J37: ALL | L37: =L35+L28 -> 1.214286e+09 | M37: =L28+L37+O28+R28 -> 1.6853677e+09 | N37: =M37/1000000 -> 1685.3677
A38: Advanced biogasoline
A39: TOTAL | C39: =SUM(C40:C47) -> 2.3658667e+08 | D39: =SUM(D40:D47) -> 0.15 | F39: =SUM(F40:F47) -> 221586.67 | H39: =SUM(H40:H47) -> 2.8780279e+08 | L39: =L40+L47 -> 73078152 | O39: =O40+O47 -> 127980600 | R39: =R40+R47 -> 86744040
A40: of which IVC 5 | B40: 1000 | C40: =B40*F40 -> 2.0158667e+08 | D40: 0.13 | E40: ='[1]Conversion factors selected IV '!$O$18 -> 1.5506667 | F40: =D40*E40*1000000 -> 201586.67 | G40: ='LCoP 2030 MEDIUM'!E5 -> 1281.8786 | H40: =F40*G40 -> 2.5840964e+08 | I40: ='LCoP 2030 MEDIUM'!H5 -> 0.26514104 | L40: =I40*H40 -> 68515002 | M40: ='LCoP 2030 MEDIUM'!F5 -> 0.4329583 | O40: =M40*H40 -> 111880600 | P40: ='LCoP 2030 MEDIUM'!G5 -> 0.30190065 | R40: =P40*H40 -> 78014040 | S40: =L40+O40+R40 -> 2.5840964e+08
H41: domestic | I41: Straw | J41: Products of agriculture, hunting and related services | K41: ='Feedstock MIX per IVC'!G13 -> 255.92003 | L41: =K41*F$40 -> 51590066 | M41: Fabricated metal products | N41: 0 | O41: =N41*O$40 -> 0 | P41: Electricity, gas, steam and air conditioning | Q41: 0.2 | R41: =Q41*R$40 -> 15602808
...

Sheet 2030 costs Sc 1
A1: Contribution of each IVC to final product in Scenario (1) 2030
A2: Assumptions:
A3: technical capacity = cmc | E3: feedstock availability: 2030 medium
A4: Market value of ALLL biofule production | C4: =C6+C196+C225+C274+C283 -> 3.5019596e+10
B5: market price [€/t] | C5: makret value of overall amount produced | D5: produced in Mtoe | E5: Conversion factor [t/toe] | F5: produced in t | G5: Cost of production [€/t] | H5: Money spent on each IVC | I5: Feedstock share of costs | J5: Eurostat sector | K5: money [€] spent on each feedtsock when producing 1t of product | L5: Absolute feedstock costs [€] | M5: CAPEX share of costs | N5: CAPEX distribution | O5: Absoluet CAPEX [€] | P5: OPEX share of costs | R5: Absolute OPEX [€] | S5: TOTAL production costs
A6: SUMME ALL advanced | C6: =C8+C44+C86+C120+C154 -> 8.6532415e+09 | D6: =D8+D44+D86+D120+D154 -> 5.494849
A7: Advanced biodiesel
A8: TOTAL | B8: =C8/1000000 -> 3061.585 | C8: =C9+C23+C16 -> 3.061585e+09 | D8: =D9+D16+D23 -> 1.8575045 | F8: =F9+F23+F16 -> 2040905.7 | H8: =H9+H23+H16 -> 2.7114055e+09 | L8: =L9+L16+L23 -> 1.9938961e+09 | O8: =O9+O16+O23 -> 2.6544909e+08 | R8: =R9+R16+R23 -> 4.5206034e+08
A9: of which IVC 1 | B9: 1450 | C9: =B9*F9 -> 2.465e+09 | D9: ='[2]GAP analysis Sc. 1'!$C$36+'[2]GAP analysis Sc. 1'!$C$50 -> 1.5023407 | E9: ='[1]Conversion factors selected IV '!$O$4 -> 1.1315676 | F9: =D9*E9*1000000 -> 1700000 | G9: ='LCoP 2030 MEDIUM'!E2 -> 1283.25 | H9: =G9*F9 -> 2.181525e+09 | I9: ='LCoP 2030 MEDIUM'!H2 -> 0.77927138 | L9: =I9*H9 -> 1.7e+09 | M9: ='LCoP 2030 MEDIUM'!F2 -> 0.064679525 | O9: =M9*H9 -> 1.411e+08 | P9: ='LCoP 2030 MEDIUM'!G2 -> 0.15604909 | R9: =P9*H9 -> 3.40425e+08 | S9: =SUM(S10:S15) -> 0 | T9: =L9+O9+R9 -> 2.181525e+09
C10: =C9/C8 -> 0.80513852 | H10: imported | I10: POME | J10: Food, beverages and tobacco products | K10: ='Feedstock MIX per IVC'!G4 -> 1000 | L10: =K10*F9 -> 1.7e+09 | M10: Fabricated metal products | N10: 0.05 | O10: =N10*O$9 -> 7055000 | P10: Electricity, gas, steam and air conditioning | Q10: 0.35 | R10: =Q10*R$9 -> 1.1914875e+08
M11: Electrical equipment | N11: 0.02 | O11: =N11*O$9 -> 2822000 | P11: Chemicals and chemical products | Q11: 0.25 | R11: =Q11*R$9 -> 85106250
M12: Machinery and equipment n.e.c. | N12: 0.45 | O12: =N12*O$9 -> 63495000 | P12: Legal and accounting services; services of head offices; management consultancy services | Q12: 0.2 | R12: =Q12*R$9 -> 68085000
M13: Constructions and construction works | N13: 0.15 | O13: =N13*O$9 -> 21165000 | P13: Repair and installation services of machinery and equipment | Q13: 0.15 | R13: =Q13*R$9 -> 51063750
M14: Architectural and engineering services; technical testing and analysis services | N14: 0.3 | O14: =N14*O$9 -> 42330000 | P14: Land transport services and transport services via pipelines | Q14: 0.05 | R14: =Q14*R$9 -> 17021250
M15: Computer, electronic and optical products | N15: 0.03 | O15: =N15*O$9 -> 4233000
A16: of which IVC 2 HVO | B16: 1750 | C16: =B16*F16 -> 4.9e+08 | D16: ='[2]GAP analysis Sc. 1'!$C$37+'[2]GAP analysis Sc. 1'!$C$51 -> 0.29425814 | E16: ='[1]Conversion factors selected IV '!$O$7 -> 0.95154545 | F16: =D16*E16*1000000 -> 280000 | G16: ='LCoP 2030 MEDIUM'!E23 -> 1572.75 | H16: =G16*F16 -> 4.4037e+08 | I16: ='LCoP 2030 MEDIUM'!H23 -> 0.63582896 | L16: =I16*H16 -> 2.8e+08 | M16: ='LCoP 2030 MEDIUM'!F23 -> 0.17103799 | O16: =M16*H16 -> 75320000 | P16: ='LCoP 2030 MEDIUM'!G23 -> 0.19313305 | R16: =P16*H16 -> 85050000 | S16: =L16+O16+R16 -> 4.4037e+08
C17: =C16/C8 -> 0.16004782 | H17: imported | I17: POME | J17: Food, beverages and tobacco products | K17: 1000 | L17: =K17*F16 -> 2.8e+08 | M17: Fabricated metal products | N17: 0.05 | O17: =N17*O$16 -> 3766000 | P17: Electricity, gas, steam and air conditioning | Q17: 0.35 | R17: =Q17*R$16 -> 29767500
M18: Electrical equipment | N18: 0.02 | O18: =N18*O$16 -> 1506400 | P18: Chemicals and chemical products | Q18: 0.25 | R18: =Q18*R$16 -> 21262500
M19: Machinery and equipment n.e.c. | N19: 0.45 | O19: =N19*O$16 -> 33894000 | P19: Legal and accounting services; services of head offices; management consultancy services | Q19: 0.2 | R19: =Q19*R$16 -> 17010000
M20: Constructions and construction works | N20: 0.15 | O20: =N20*O$16 -> 11298000 | P20: Repair and installation services of machinery and equipment | Q20: 0.15 | R20: =Q20*R$16 -> 12757500
M21: Architectural and engineering services; technical testing and analysis services | N21: 0.3 | O21: =N21*O$16 -> 22596000 | P21: Land transport services and transport services via pipelines | Q21: 0.05 | R21: =Q21*R$16 -> 4252500
M22: Computer, electronic and optical products | N22: 0.03 | O22: =N22*O$16 -> 2259600
A23: of which 13a (half) | B23: 1750 | C23: =B23*F23 -> 1.0658498e+08 | D23: ='[2]GAP analysis Sc. 1'!$C$38 -> 0.060905704 | E23: ='[1]Conversion factors selected IV '!$O$89 -> 1 | F23: =D23*E23*1000000 -> 60905.704 | G23: ='LCoP 2030 MEDIUM'!E19 -> 1469.6575 | H23: =G23*F23 -> 89510526 | I23: ='LCoP 2030 MEDIUM'!H19 -> 0.15524537 | L23: =I23*H23 -> 13896095 | M23: ='LCoP 2030 MEDIUM'!F19 -> 0.54774666 | O23: =M23*H23 -> 49029091 | P23: ='LCoP 2030 MEDIUM'!G19 -> 0.29700797 | R23: =P23*H23 -> 26585340 | S23: =L23+O23+R23 -> 89510526
C24: =C23/C8 -> 0.034813661 | F24: Products of agriculture, hunting and related services | G24: =SUMIF($J$24:$J$31,F24,$L$24:$L$31)/$L$23 -> 0.57076546 | H24: domestic | I24: Straw | J24: Products of agriculture, hunting and related services | K24: ='Feedstock MIX per IVC'!G84 -> 117.13778 | L24: =K24*F$23 -> 7134358.7 | M24: Fabricated metal products | N24: 0.15 | O24: =N24*O$23 -> 7354363.7 | P24: Electricity, gas, steam and air conditioning | Q24: 0.15 | R24: =Q24*R$23 -> 3987800.9
F25: Food, beverages and tobacco products | G25: =SUMIF($J$24:$J$31,F25,$L$24:$L$31)/$L$23 -> 0.012837447 | H25: domestic | I25: Prunings & damaged crops | J25: Products of agriculture, hunting and related services | K25: ='Feedstock MIX per IVC'!G85 -> 6.0040708 | L25: =K25*F$23 -> 365682.16 | M25: Electrical equipment | N25: 0.02 | O25: =N25*O$23 -> 980581.83 | P25: Chemicals and chemical products | Q25: 0.25 | R25: =Q25*R$23 -> 6646334.9
F26: Products of forestry, logging and related services | G26: =SUMIF($J$24:$J$31,F26,$L$24:$L$31)/$L$23 -> 0.21178827 | H26: domestic | I26: Agroprocessing residues - maize cobs | J26: Food, beverages and tobacco products | K26: ='Feedstock MIX per IVC'!G86 -> 2.9289602 | L26: =K26*F$23 -> 178390.38 | M26: Machinery and equipment n.e.c. | N26: 0.45 | O26: =N26*O$23 -> 22063091 | P26: Legal and accounting services; services of head offices; management consultancy services | Q26: 0.2 | R26: =Q26*R$23 -> 5317067.9
F27: Paper and paper products | G27: =SUMIF($J$24:$J$31,F27,$L$24:$L$31)/$L$23 -> 0.17975682 | H27: domestic | I27: Lignocrops abandoned degraded | J27: Products of agriculture, hunting and related services | K27: ='Feedstock MIX per IVC'!G87 -> 4.8668638 | L27: =K27*F$23 -> 296419.76 | M27: Constructions and construction works | N27: 0.1 | O27: =N27*O$23 -> 4902909.1 | P27: Repair and installation services of machinery and equipment | Q27: 0.3 | R27: =Q27*R$23 -> 7975601.9
F28: Sewerage services; sewage sludge; waste collection, treatment and disposal services; materials recovery services; remediation services and other waste management services | G28: =SUMIF($J$24:$J$31,F28,$L$24:$L$31)/$L$23 -> 0.024851999 | H28: domestic | I28: Lignocrops inter & cover cropping | J28: Products of agriculture, hunting and related services | K28: ='Feedstock MIX per IVC'!G88 -> 2.2157284 | L28: =K28*F$23 -> 134950.5 | M28: Architectural and engineering services; technical testing and analysis services | N28: 0.25 | O28: =N28*O$23 -> 12257273 | P28: Land transport services and transport services via pipelines | Q28: 0.1 | R28: =Q28*R$23 -> 2658534
G29: =SUM(G24:G28) -> 1 | H29: domestic | I29: Primary forestry residues | J29: Products of forestry, logging and related services | K29: ='Feedstock MIX per IVC'!G89 -> 48.32109 | L29: =K29*F$23 -> 2943030 | M29: Computer, electronic and optical products | N29: 0.03 | O29: =N29*O$23 -> 1470872.7 | Q29: =SUM(Q24:Q28) -> 1
H30: domestic | I30: Secondary forest residues | J30: Paper and paper products | K30: ='Feedstock MIX per IVC'!G90 -> 41.012873 | L30: =K30*F$23 -> 2497917.9
H31: domestic | I31: Biowastes - Post consumer wood | J31: Sewerage services; sewage sludge; waste collection, treatment and disposal services; materials recovery services; remediation services and other waste management services | K31: ='Feedstock MIX per IVC'!G91 -> 5.6701708 | L31: =K31*F$23 -> 345345.74
I32: SUM | L32: =SUM(L34:L42) -> 1.9938961e+09 | S32: =SUM(S34:S42) -> 0.16672546
I33: TOTALS domestic | M33: TOTALS | O33: =SUM(O34:O39) -> 2.6544909e+08 | P33: TOTALS | R33: =SUM(R34:R38) -> 4.5206034e+08 | S33: CHECKED; ALL FINE
J34: Products of agriculture, hunting and related services | L34: =SUMIF($J$17:$J$31, J34, $L$17:$L$31) -> 7931411.2 | M34: Fabricated metal products | O34: =SUMIF($M$10:$M$29,M34,$O$10:$O$29) -> 18175364 | P34: Electricity, gas, steam and air conditioning | R34: =SUMIF($P$10:$P$29,P34,$R$10:$R$29) -> 1.5290405e+08 | S34: =R34/$H$8 -> 0.056392911
J35: Products of forestry, logging and related services | L35: =SUMIF($J$17:$J$31, J35, $L$17:$L$31) -> 2943030 | M35: Electrical equipment | O35: =SUMIF($M$10:$M$29,M35,$O$10:$O$29) -> 5308981.8 | P35: Chemicals and chemical products | R35: =SUMIF($P$10:$P$29,P35,$R$10:$R$29) -> 1.1301508e+08 | S35: =R35/$H$8 -> 0.041681366 | T35: =L32+O33+R33 -> 2.7114055e+09
J36: Paper and paper products | L36: =SUMIF($J$17:$J$31, J36, $L$17:$L$31) -> 2497917.9 | M36: Machinery and equipment n.e.c. | O36: =SUMIF($M$10:$M$29,M36,$O$10:$O$29) -> 1.1945209e+08 | P36: Legal and accounting services; services of head offices; management consultancy services | R36: =SUMIF($P$10:$P$29,P36,$R$10:$R$29) -> 90412068 | S36: =R36/$H$8 -> 0.033345092
J37: Food, beverages and tobacco products | L37: =SUMIF($J$17:$J$31, J37, $L$17:$L$31) -> 2.8017839e+08 | M37: Constructions and construction works | O37: =SUMIF($M$10:$M$29,M37,$O$10:$O$29) -> 37365909 | P37: Repair and installation services of machinery and equipment | R37: =SUMIF($P$10:$P$29,P37,$R$10:$R$29) -> 71796852 | S37: =R37/$H$8 -> 0.02647957
J38: Sewerage services; sewage sludge; waste collection, treatment and disposal services; materials recovery services; remediation services and other waste management services | L38: =SUMIF($J$17:$J$31, J38, $L$17:$L$31) -> 345345.74 | M38: Architectural and engineering services; technical testing and analysis services | O38: =SUMIF($M$10:$M$29,M38,$O$10:$O$29) -> 77183273 | P38: Land transport services and transport services via pipelines | R38: =SUMIF($P$10:$P$29,P38,$R$10:$R$29) -> 23932284 | S38: =R38/$H$8 -> 0.0088265233
J39: Chemicals and chemical products | L39: =SUMIF($J$17:$J$31, J39, $L$17:$L$31) -> 0 | M39: Computer, electronic and optical products | O39: =SUMIF($M$10:$M$29,M39,$O$10:$O$29) -> 7963472.7
J40: Advanced biodiesel | L40: =SUMIF($J$17:$J$31, J40, $L$17:$L$31) -> 0
...

Sheet Tabelle1
B1: Exiobase mapping
A2: Feedstock
A3: IVC 1 FAME
A4: Imported POME
A5: IVC 2 HVO
A6: Tall oil
A7: FPBO, biocrude
A8: IVC 2 HEFA | G8: Eindeutige Kategorien
A9: Oil crops abandoned | D9: Eindeutige Kategorien | E9: Eurostat sector | G9: Advanced biogasoline | H9: CPA_C20
A10: Tall oil | D10: {=_xlfn._xlws.SORT(_xlfn.UNIQUE(_xlfn._xlws.FILTER(A2:A119,(A2:A119<>"")*(UPPER(LEFT(TRIM(A2:A119),3))<>"IVC"))))} -> Agroprocessing residues | E10: Food, beverages and tobacco products | G10: {=_xlfn._xlws.SORT(_xlfn.UNIQUE(_xlfn._xlws.FILTER(E10:E35,E10:E35<>"")))} -> Advanced biodiesel | H10: CPA_C20
A11: FPBO, biocrude | D11: Agroprocessing residues - maize cobs | E11: Food, beverages and tobacco products | G11: Advanced biogas | H11: CPA_C20_Advanced_biogas
A12: IVC 5 Advanced Ethanol | D12: Biowastes - Post consumer wood | E12: Sewerage services; sewage sludge; waste collection, treatment and disposal services; materials recovery services; remediation services and other waste management services | G12: Advanced bio-HFO | H12: CPA_C20_advanced_bio_HFO
A13: Straw | D13: Biowastes (post consumer woods excluded) | E13: Sewerage services; sewage sludge; waste collection, treatment and disposal services; materials recovery services; remediation services and other waste management services | G13: Chemicals and chemical products | H13: CPA_C20_others
A14: Lignocrops abandoned degraded | D14: e-biofuel feedstocks (biogenic CO2 and hydrogen from electrolysis) | E14: Chemicals and chemical products | G14: Food, beverages and tobacco products | H14: CPA_C10-12
A15: Lignocrops inter & cover cropping | D15: Feedstock | G15: Paper and paper products | H15: CPA_C17
A16: Secondary forest residues | D16: FPBO, biocrude | E16: Chemicals and chemical products | G16: Products of agriculture, hunting and related services | H16: CPA_A01
A17: IVC 6 | D17: HEFA (with imported POME ) | E17: Advanced biodiesel | G17: Products of forestry, logging and related services | H17: CPA_A02
A18: Intermediate Bioenergy carrier (ethanol, methanol) | D18: Imported POME | E18: Food, beverages and tobacco products | G18: Sewerage services; sewage sludge; waste collection, treatment and disposal services; materials recovery services; remediation services and other waste management services | H18: CPA_E37-39
A19: IVC 7 (MCR + MSW) | D19: Intermediate Bioenergy carrier (biomethane) | E19: Advanced biogas
A20: Prunings & damaged crops (olive stones excluded) | D20: Intermediate Bioenergy carrier (crude glycerine) | E20: Chemicals and chemical products
A21: Lignocrops abandoned degraded | D21: Intermediate Bioenergy carrier (ethanol, methanol) | E21: Advanced bio-HFO
A22: Lignocrops inter & cover cropping | D22: Intermediate Bioenergy carrier (FPBO with lower quality) | E22: Advanced biodiesel
A23: Agroprocessing residues | D23: Intermediate Bioenergy carriers (FPBO with lower quality ) | E23: Advanced biodiesel
A24: Straw | D24: Intermediate Bioenergy carriers (Syngas) | E24: Advanced biogas
A25: Manure | D25: Lignocrops abandoned degraded | E25: Products of agriculture, hunting and related services
A26: Sewage sludge | D26: Lignocrops inter & cover cropping | E26: Products of agriculture, hunting and related services
A27: Biowastes (post consumer woods excluded) | D27: Manure | E27: Products of agriculture, hunting and related services
A28: Intermediate Bioenergy carrier (crude glycerine) | D28: Oil crops abandoned | E28: Products of agriculture, hunting and related services
A29: IVC 8a | D29: Primary forestry residues | E29: Products of forestry, logging and related services
A30: Straw | D30: Prunings & damaged crops | E30: Products of agriculture, hunting and related services
... A35: Lignocrops inter & cover cropping | D35: Tall oil | E35: Products of agriculture, hunting and related services
A36: Primary forestry residues
A37: Secondary forest residues
A38: Biowastes - Post consumer wood
A39: Intermediate Bioenergy carrier (FPBO with lower quality) | B39: Adv biodiesel, adv biogasoline
A40: IVC 8b
A41: Intermediate Bioenergy carrier (biomethane)
A42: IVC 8c
A43: e-biofuel feedstocks (biogenic CO2 and hydrogen from electrolysis)
A44: IVC 9a
...

Sheet 2030 costs Sc 2
A1: Contribution of each IVC to final product in Scenario (2) 2030
A2: Assumptions:
A3: technical capacity = tcp | E3: feedstock availability: 2030 high
C4: =C6+C201+C226 -> 5.5490742e+10
B5: Market value | C5: Makret value of overall amount produced | D5: produced in Mtoe | E5: Conversion factor [t/toe] | F5: produced in t | G5: Cost of production [€/t] | H5: Money spent on each IVC | I5: Feedstock share of costs | J5: Eurostat sector | K5: money [€] spent on each feedtsock when producing 1t of product | L5: Absolute feedstock costs [€] | M5: CAPEX share of costs | N5: CAPEX distribution | O5: Absoluet CAPEX [€] | P5: OPEX share of costs | R5: Absolute OPEX [€] | S5: TOTAL production costs
A6: Sum ALL advanced | C6: =C8+C48+C90+C123+C162 -> 3.7743028e+10 | D6: =D8+D48+D90+D123+D162 -> 24.505634
A7: Advanced biodiesel
A8: TOTAL | B8: =C8/1000000 -> 10212.747 | C8: =C28+C9+C16 -> 1.0212747e+10 | D8: =D28+D9+D16 -> 6.0684375 | F8: =F28+F9+F16 -> 5835855.7 | H8: =H28+H9+H16 -> 1.3293409e+10 | L8: =L28+L9+L16 -> 1.8473113e+09 | O8: =O9+O16+O28 -> 7.6210115e+09 | R8: =R9+R16+R28 -> 3.8250862e+09
A9: of which IVC 2 HVO | B9: 1750 | C9: =B9*F9 -> 0 | D9: ='[2]GAP analysis Sc. 2'!$C$38 -> 0 | E9: ='[1]Conversion factors selected IV '!$O$7 -> 0.95154545 | F9: =D9*E9*1000000 -> 0 | G9: ='LCoP 2030 HIGH'!E3 -> 2245.1729 | H9: =G9*F9 -> 0 | I9: ='LCoP 2030 HIGH'!H3 -> 0.74489715 | L9: =I9*H9 -> 0 | M9: ='LCoP 2030 HIGH'!F3 -> 0.1198126 | O9: =M9*H9 -> 0 | P9: ='LCoP 2030 HIGH'!G3 -> 0.13529025 | R9: =P9*H9 -> 0 | S9: =L9+O9+R9 -> 0
C10: =C9/C8 -> 0 | F10: Products of agriculture, hunting and related services | G10: =(SUMIF($J$10:$J$12,F10,$L$10:$L$12)/$L$9) -> #DIV/0! | I10: Tall oil | J10: Products of agriculture, hunting and related services | K10: ='Feedstock MIX per IVC'!J6 -> 179.86731 | L10: =K10*F$9 -> 0 | M10: Fabricated metal products | N10: 0.05 | O10: =N10*O$9 -> 0 | P10: Electricity, gas, steam and air conditioning | Q10: 0.35 | R10: =Q10*R$9 -> 0
F11: Advanced biodiesel | G11: =(SUMIF($J$10:$J$12,F11,$L$10:$L$12)/$L$9)/2 -> #DIV/0! | I11: FPBO (Intermediate bioenergy carrier) | J11: Advanced biodiesel | K11: ='Feedstock MIX per IVC'!J7*0.85 -> 1268.6722 | L11: =K11*F$9 -> 0 | M11: Electrical equipment | N11: 0.02 | O11: =N11*O$9 -> 0 | P11: Chemicals and chemical products | Q11: 0.25 | R11: =Q11*R$9 -> 0
F12: Chemicals and chemical products | G12: =(SUMIF($J$10:$J$12,F12,$L$10:$L$12)/$L$9) -> #DIV/0! | I12: biocrude (Intermediate Bioenergy carrier) | J12: Chemicals and chemical products | K12: ='Feedstock MIX per IVC'!J7*0.15 -> 223.88333 | L12: =K12*F$9 -> 0 | M12: Machinery and equipment n.e.c. | N12: 0.45 | O12: =N12*O$9 -> 0 | P12: Legal and accounting services; services of head offices; management consultancy services | Q12: 0.2 | R12: =Q12*R$9 -> 0
F13: Advanced biogasoline | G13: =G11 -> #DIV/0! | M13: Constructions and construction works | N13: 0.15 | O13: =N13*O$9 -> 0 | P13: Repair and installation services of machinery and equipment | Q13: 0.15 | R13: =Q13*R$9 -> 0
G14: =SUM(G10:G13) -> #DIV/0! | M14: Architectural and engineering services; technical testing and analysis services | N14: 0.3 | O14: =N14*O$9 -> 0 | P14: Land transport services and transport services via pipelines | Q14: 0.05 | R14: =Q14*R$9 -> 0
I15: Sum | L15: =SUM(L10:L12) -> 0 | M15: Computer, electronic and optical products | N15: 0.03 | O15: =N15*O$9 -> 0
A16: of which IVC 11a (road) | B16: 1750 | C16: =B16*F16 -> 7.9929818e+09 | D16: ='[2]GAP analysis Sc. 2'!$C$39 -> 4.8 | E16: ='[1]Conversion factors selected IV '!$O$64 -> 0.95154545 | F16: =D16*E16*1000000 -> 4567418.2 | G16: ='LCoP 2030 HIGH'!E15 -> 2502.2771 | H16: =G16*F16 -> 1.1428946e+10 | I16: ='LCoP 2030 HIGH'!H15 -> 0.13628669 | L16: =I16*H16 -> 1.5576132e+09 | M16: ='LCoP 2030 HIGH'!F15 -> 0.57747402 | O16: =M16*H16 -> 6.5999193e+09 | P16: ='LCoP 2030 HIGH'!G15 -> 0.28623929 | R16: =P16*H16 -> 3.2714133e+09 | S16: =L16+O16+R16 -> 1.1428946e+10
C17: =C16/C8 -> 0.78264756 | F17: Products of agriculture, hunting and related services | G17: =(SUMIF($J$17:$J$26,F17,$L$17:$L$26)/$L$16) -> 0.59771745 | I17: Straw | J17: Products of agriculture, hunting and related services | K17: ='Feedstock MIX per IVC'!J58 -> 181.54132 | L17: =K17*F$16 -> 8.2917513e+08 | M17: Fabricated metal products | N17: 0 | O17: =N17*O$16 -> 0 | P17: Electricity, gas, steam and air conditioning | Q17: 0.25 | R17: =Q17*R$16 -> 8.1785332e+08
F18: Products of forestry, logging and related services | G18: =(SUMIF($J$17:$J$26,F18,$L$17:$L$26)/$L$16) -> 0.12919991 | I18: Prunings & damaged crops | J18: Products of agriculture, hunting and related services | K18: ='Feedstock MIX per IVC'!J59 -> 8.4731123 | L18: =K18*F$16 -> 38700247 | M18: Electrical equipment | N18: 0.02 | O18: =N18*O$16 -> 1.3199839e+08 | P18: Chemicals and chemical products | Q18: 0.15 | R18: =Q18*R$16 -> 4.9071199e+08
F19: Paper and paper products | G19: =(SUMIF($J$17:$J$26,F19,$L$17:$L$26)/$L$16) -> 0.14918901 | I19: Sewage sludge | J19: Sewerage services; sewage sludge; waste collection, treatment and disposal services; materials recovery services; remediation services and other waste management services | K19: ='Feedstock MIX per IVC'!J60 -> 0 | L19: =K19*F$16 -> 0 | M19: Machinery and equipment n.e.c. | N19: 0.55 | O19: =N19*O$16 -> 3.6299556e+09 | P19: Legal and accounting services; services of head offices; management consultancy services | Q19: 0.3 | R19: =Q19*R$16 -> 9.8142398e+08
F20: Food, beverages and tobacco products | G20: =(SUMIF($J$17:$J$26,F20,$L$17:$L$26)/$L$16) -> 0.012600306 | I20: Agroprocessing residues - maize cobs | J20: Food, beverages and tobacco products | K20: ='Feedstock MIX per IVC'!J61 -> 4.2970453 | L20: =K20*F$16 -> 19626403 | M20: Constructions and construction works | N20: 0.1 | O20: =N20*O$16 -> 6.5999193e+08 | P20: Repair and installation services of machinery and equipment | Q20: 0.3 | R20: =Q20*R$16 -> 9.8142398e+08
F21: Sewerage services; sewage sludge; waste collection, treatment and disposal services; materials recovery services; remediation services and other waste management services | G21: =(SUMIF($J$17:$J$26,F21,$L$17:$L$26)/$L$16) -> 0.023308789 | I21: Lignocrops abandoned degraded | J21: Products of agriculture, hunting and related services | K21: ='Feedstock MIX per IVC'!J62 -> 8.1190082 | L21: =K21*F$16 -> 37082906 | M21: Architectural and engineering services; technical testing and analysis services | N21: 0.3 | O21: =N21*O$16 -> 1.9799758e+09 | P21: Land transport services and transport services via pipelines | Q21: 0 | R21: =Q21*R$16 -> 0
F22: Advanced biodiesel | G22: =(SUMIF($J$17:$J$26,F22,$L$17:$L$26)/$L$16)/2 -> 0.043992266 | I22: Lignocrops inter & cover cropping | J22: Products of agriculture, hunting and related services | K22: ='Feedstock MIX per IVC'!J63 -> 5.7043807 | L22: =K22*F$16 -> 26054292 | M22: Computer, electronic and optical products | N22: 0.03 | O22: =N22*O$16 -> 1.9799758e+08
F23: Chemicals and chemical products | G23: =(SUMIF($J$17:$J$26,F23,$L$17:$L$26)/$L$16) -> 0 | I23: Primary forestry residues | J23: Products of forestry, logging and related services | K23: ='Feedstock MIX per IVC'!J64 -> 44.060666 | L23: =K23*F$16 -> 2.0124349e+08
F24: Advanced biogasoline | G24: =G22 -> 0.043992266 | I24: Secondary forest residues | J24: Paper and paper products | K24: ='Feedstock MIX per IVC'!J65 -> 50.877489 | L24: =K24*F$16 -> 2.3237877e+08
G25: =SUM(G17:G24) -> 1 | I25: Biowastes - Post consumer wood | J25: Sewerage services; sewage sludge; waste collection, treatment and disposal services; materials recovery services; remediation services and other waste management services | K25: ='Feedstock MIX per IVC'!J66 -> 7.9489277 | L25: =K25*F$16 -> 36306077
I26: Intermediate Bioenergy carriers (FPBO with lower quality ) | J26: Advanced biodiesel | K26: ='Feedstock MIX per IVC'!J67 -> 30.005106 | L26: =K26*F$16 -> 1.3704586e+08
I27: Sum | L27: =SUM(L17:L26) -> 1.5576132e+09
A28: of which 13a (half) | B28: 1750 | C28: =B28*F28 -> 2219765625 | D28: ='[2]GAP analysis Sc. 2'!$C$40 -> 1.2684375 | E28: ='[1]Conversion factors selected IV '!$O$89 -> 1 | F28: =D28*E28*1000000 -> 1268437.5 | G28: ='LCoP 2030 HIGH'!E19 -> 1469.8897 | H28: =G28*F28 -> 1.8644632e+09 | I28: ='LCoP 2030 HIGH'!H19 -> 0.15537881 | L28: =I28*H28 -> 2.8969808e+08 | M28: ='LCoP 2030 HIGH'!F19 -> 0.54766013 | O28: =M28*H28 -> 1.0210922e+09 | P28: ='LCoP 2030 HIGH'!G19 -> 0.29696105 | R28: =P28*H28 -> 5.5367297e+08 | S28: =L28+O28+R28 -> 1.8644632e+09
C29: =C28/C8 -> 0.21735244 | F29: Products of agriculture, hunting and related services | G29: =(SUMIF($J$29:$J$36,F29,$L$29:$L$36)/$L$28) -> 0.63900608 | I29: Straw | J29: Products of agriculture, hunting and related services | K29: ='Feedstock MIX per IVC'!J84 -> 129.97872 | L29: =K29*F$28 -> 1.6486989e+08 | M29: Fabricated metal products | N29: 0.15 | O29: =N29*O$28 -> 1.5316383e+08 | P29: Electricity, gas, steam and air conditioning | Q29: 0.15 | R29: =Q29*R$28 -> 83050945
F30: Products of forestry, logging and related services | G30: =(SUMIF($J$29:$J$36,F30,$L$29:$L$36)/$L$28) -> 0.14815699 | I30: Prunings & damaged crops | J30: Products of agriculture, hunting and related services | K30: ='Feedstock MIX per IVC'!J85 -> 6.0665214 | L30: =K30*F$28 -> 7695003.3 | M30: Electrical equipment | N30: 0.02 | O30: =N30*O$28 -> 20421844 | P30: Chemicals and chemical products | Q30: 0.25 | R30: =Q30*R$28 -> 1.3841824e+08
F31: Paper and paper products | G31: =(SUMIF($J$29:$J$36,F31,$L$29:$L$36)/$L$28) -> 0.17618586 | I31: Agroprocessing residues - maize cobs | J31: Food, beverages and tobacco products | K31: ='Feedstock MIX per IVC'!J86 -> 3.0765693 | L31: =K31*F$28 -> 3902435.9 | M31: Machinery and equipment n.e.c. | N31: 0.45 | O31: =N31*O$28 -> 4.5949148e+08 | P31: Legal and accounting services; services of head offices; management consultancy services | Q31: 0.2 | R31: =Q31*R$28 -> 1.1073459e+08
F32: Food, beverages and tobacco products | G32: =(SUMIF($J$29:$J$36,F32,$L$29:$L$36)/$L$28) -> 0.0134707 | I32: Lignocrops abandoned degraded | J32: Products of agriculture, hunting and related services | K32: ='Feedstock MIX per IVC'!J87 -> 5.8129924 | L32: =K32*F$28 -> 7373417.5 | M32: Constructions and construction works | N32: 0.1 | O32: =N32*O$28 -> 1.0210922e+08 | P32: Repair and installation services of machinery and equipment | Q32: 0.3 | R32: =Q32*R$28 -> 1.6610189e+08
F33: Sewerage services; sewage sludge; waste collection, treatment and disposal services; materials recovery services; remediation services and other waste management services | G33: =(SUMIF($J$29:$J$36,F33,$L$29:$L$36)/$L$28) -> 0.023180367 | I33: Lignocrops inter & cover cropping | J33: Products of agriculture, hunting and related services | K33: ='Feedstock MIX per IVC'!J88 -> 4.0841838 | L33: =K33*F$28 -> 5180531.9 | M33: Architectural and engineering services; technical testing and analysis services | N33: 0.25 | O33: =N33*O$28 -> 2.5527305e+08 | P33: Land transport services and transport services via pipelines | Q33: 0.1 | R33: =Q33*R$28 -> 55367297
F34: Advanced biodiesel | G34: =(SUMIF($J$29:$J$36,F34,$L$29:$L$36)/$L$28) -> 0 | I34: Primary forestry residues | J34: Products of forestry, logging and related services | K34: ='Feedstock MIX per IVC'!J89 -> 33.837534 | L34: =K34*F$28 -> 42920797 | M34: Computer, electronic and optical products | N34: 0.03 | O34: =N34*O$28 -> 30632766 | Q34: =SUM(Q29:Q33) -> 1
F35: Chemicals and chemical products | G35: =(SUMIF($J$29:$J$36,F35,$L$29:$L$36)/$L$28) -> 0 | I35: Secondary forest residues | J35: Paper and paper products | K35: ='Feedstock MIX per IVC'!J90 -> 40.239039 | L35: =K35*F$28 -> 51040706
G36: =SUM(G29:G35) -> 1 | I36: Biowastes - Post consumer wood | J36: Sewerage services; sewage sludge; waste collection, treatment and disposal services; materials recovery services; remediation services and other waste management services | K36: ='Feedstock MIX per IVC'!J91 -> 5.2941575 | L36: =K36*F$28 -> 6715307.9
I37: SUM | L37: =SUM(L29:L36) -> 2.8969808e+08
I38: TOTALS domestic | M38: TOTALS | O38: =SUM(O39:O44) -> 7.6210115e+09 | P38: TOTALS | R38: =SUM(R39:R43) -> 3.8250862e+09 | S38: =SUM(S39:S43) -> 0.28774307
J39: Products of agriculture, hunting and related services | L39: =SUMIF($J$10:$J$36,J39,$L$10:$L$36) -> 1.1161314e+09 | M39: Fabricated metal products | O39: =SUMIF($M$10:$M$36,M39,$O$10:$O$36) -> 1.5316383e+08 | P39: Electricity, gas, steam and air conditioning | R39: =SUMIF($P$10:$P$36,P39,$R$10:$R$36) -> 9.0090426e+08 | S39: =R39/$H$8 -> 0.067770748
J40: Products of forestry, logging and related services | L40: =SUMIF($J$10:$J$36,J40,$L$10:$L$36) -> 2.4416429e+08 | M40: Electrical equipment | O40: =SUMIF($M$10:$M$36,M40,$O$10:$O$36) -> 1.5242023e+08 | P40: Chemicals and chemical products | R40: =SUMIF($P$10:$P$36,P40,$R$10:$R$36) -> 6.2913023e+08 | S40: =R40/$H$8 -> 0.047326478
...

Sheet 2030 costs Sc 3
A1: Contribution of each IVC to final product in Scenario (3) 2030
A2: Assumptions:
A3: technical capacity = no constraints | E3: feedstock availability: 2030 high
C4: =C6+C201+C227 -> 2.8570881e+11
A5: Sum ALL advanced | B5: Market price [€(t] | C5: Makret value of overall amount produced | D5: produced in Mtoe | E5: Conversion factor [t/toe] | F5: produced in t | G5: Cost of production [€/t] | H5: Money spent on each IVC | I5: Feedstock share of costs | J5: Eurostat sector | K5: money [€] spent on each feedtsock when producing 1t of product | L5: Absolute feedstock costs [€] | M5: CAPEX share of costs | N5: CAPEX distribution | O5: Absoluet CAPEX [€] | P5: OPEX share of costs | R5: Absolute OPEX [€] | S5: TOTAL production costs
C6: =C8+C48+C90+C123+C163 -> 2.4431698e+11 | D6: =D8+D48+D90+D123+D163 -> 167.03273
A7: Advanced biodiesel
A8: TOTAL | C8: =C28+C9+C16 -> 2.8899847e+10 | D8: =D28+D9+D16 -> 16.977868 | F8: =F28+F9+F16 -> 16514198 | H8: =H28+H9+H16 -> 3.355918e+10 | L8: =L28+L9+L16 -> 5.3942548e+09 | O8: =O9+O16+O28 -> 1.8594166e+10 | R8: =R9+R16+R28 -> 9.5707588e+09
A9: of which IVC 2 HVO | B9: 1750 | C9: =B9*F9 -> 7.8465261e+08 | D9: ='[3]Scenario 3 2030'!$O$9 -> 0.47120494 | E9: ='[1]Conversion factors selected IV '!$O$7 -> 0.95154545 | F9: =D9*E9*1000000 -> 448372.92 | G9: ='LCoP 2030 HIGH'!E3 -> 2245.1729 | H9: =G9*F9 -> 1.0066747e+09 | I9: ='LCoP 2030 HIGH'!H3 -> 0.74489715 | L9: =I9*H9 -> 7.4986913e+08 | M9: ='LCoP 2030 HIGH'!F3 -> 0.1198126 | O9: =M9*H9 -> 1.2061232e+08 | P9: ='LCoP 2030 HIGH'!G3 -> 0.13529025 | R9: =P9*H9 -> 1.3619328e+08 | S9: =L9+O9+R9 -> 1.0066747e+09
C10: =C9/$C$8 -> 0.027150753 | G10: Products of agriculture, hunting and related services | H10: =L10/L9 -> 0.10754894 | I10: Tall oil | J10: Products of agriculture, hunting and related services | K10: ='Feedstock MIX per IVC'!J6 -> 179.86731 | L10: =K10*F$9 -> 80647633 | M10: Fabricated metal products | N10: 0.05 | O10: =N10*O$9 -> 6030615.8 | P10: Electricity, gas, steam and air conditioning | Q10: 0.35 | R10: =Q10*R$9 -> 47667646
G11: Advanced biodiesel | H11: =L11/L9 -> 0.7585834 | I11: FPBO (Intermediate bioenergy carrier) | J11: Advanced biodiesel | K11: ='Feedstock MIX per IVC'!J7*0.85 -> 1268.6722 | L11: =K11*F$9 -> 5.6883827e+08 | M11: Electrical equipment | N11: 0.02 | O11: =N11*O$9 -> 2412246.3 | P11: Chemicals and chemical products | Q11: 0.25 | R11: =Q11*R$9 -> 34048319
G12: Chemicals and chemical products | H12: =L12/L9 -> 0.13386766 | I12: biocrude (Intermediate Bioenergy carrier) | J12: Chemicals and chemical products | K12: ='Feedstock MIX per IVC'!J7*0.15 -> 223.88333 | L12: =K12*F$9 -> 1.0038322e+08 | M12: Machinery and equipment n.e.c. | N12: 0.45 | O12: =N12*O$9 -> 54275542 | P12: Legal and accounting services; services of head offices; management consultancy services | Q12: 0.2 | R12: =Q12*R$9 -> 27238655
